[2025-03-01T01:58:30.837+0000] {local_task_job_runner.py:123} INFO - ::group::Pre task execution logs
[2025-03-01T01:58:30.853+0000] {taskinstance.py:2614} INFO - Dependencies all met for dep_context=non-requeueable deps ti=<TaskInstance: dag_postgres_1.insert_orders scheduled__2025-03-01T01:40:00+00:00 [queued]>
[2025-03-01T01:58:30.861+0000] {taskinstance.py:2614} INFO - Dependencies all met for dep_context=requeueable deps ti=<TaskInstance: dag_postgres_1.insert_orders scheduled__2025-03-01T01:40:00+00:00 [queued]>
[2025-03-01T01:58:30.862+0000] {taskinstance.py:2867} INFO - Starting attempt 1 of 2
[2025-03-01T01:58:30.884+0000] {taskinstance.py:2890} INFO - Executing <Task(PythonOperator): insert_orders> on 2025-03-01 01:40:00+00:00
[2025-03-01T01:58:30.896+0000] {logging_mixin.py:190} WARNING - /home/***/.local/lib/python3.12/site-packages/***/task/task_runner/standard_task_runner.py:70 DeprecationWarning: This process (pid=51988) is multi-threaded, use of fork() may lead to deadlocks in the child.
[2025-03-01T01:58:30.895+0000] {standard_task_runner.py:104} INFO - Running: ['***', 'tasks', 'run', 'dag_postgres_1', 'insert_orders', 'scheduled__2025-03-01T01:40:00+00:00', '--job-id', '57', '--raw', '--subdir', 'DAGS_FOLDER/dag_generate_table_info.py', '--cfg-path', '/tmp/tmp58eqdl4o']
[2025-03-01T01:58:30.897+0000] {standard_task_runner.py:72} INFO - Started process 51992 to run task
[2025-03-01T01:58:30.897+0000] {standard_task_runner.py:105} INFO - Job 57: Subtask insert_orders
[2025-03-01T01:58:30.946+0000] {task_command.py:467} INFO - Running <TaskInstance: dag_postgres_1.insert_orders scheduled__2025-03-01T01:40:00+00:00 [running]> on host e6b43e607126
[2025-03-01T01:58:31.029+0000] {taskinstance.py:3134} INFO - Exporting env vars: AIRFLOW_CTX_DAG_EMAIL='kucikm23@gmail.com' AIRFLOW_CTX_DAG_OWNER='***' AIRFLOW_CTX_DAG_ID='dag_postgres_1' AIRFLOW_CTX_TASK_ID='insert_orders' AIRFLOW_CTX_EXECUTION_DATE='2025-03-01T01:40:00+00:00' AIRFLOW_CTX_TRY_NUMBER='1' AIRFLOW_CTX_DAG_RUN_ID='scheduled__2025-03-01T01:40:00+00:00'
[2025-03-01T01:58:31.031+0000] {logging_mixin.py:190} INFO - Task instance is in running state
[2025-03-01T01:58:31.032+0000] {logging_mixin.py:190} INFO -  Previous state of the Task instance: queued
[2025-03-01T01:58:31.032+0000] {logging_mixin.py:190} INFO - Current task name:insert_orders state:running start_date:2025-03-01 01:58:30.854039+00:00
[2025-03-01T01:58:31.032+0000] {logging_mixin.py:190} INFO - Dag name:dag_postgres_1 and current dag run status:running
[2025-03-01T01:58:31.033+0000] {taskinstance.py:732} INFO - ::endgroup::
[2025-03-01T01:58:31.042+0000] {taskinstance.py:3313} ERROR - Task failed with exception
Traceback (most recent call last):
  File "/home/airflow/.local/lib/python3.12/site-packages/airflow/models/taskinstance.py", line 768, in _execute_task
    result = _execute_callable(context=context, **execute_callable_kwargs)
             ^^^^^^^^^^^^^^^^^^^^^^^^^^^^^^^^^^^^^^^^^^^^^^^^^^^^^^^^^^^^^
  File "/home/airflow/.local/lib/python3.12/site-packages/airflow/models/taskinstance.py", line 734, in _execute_callable
    return ExecutionCallableRunner(
           ^^^^^^^^^^^^^^^^^^^^^^^^
  File "/home/airflow/.local/lib/python3.12/site-packages/airflow/utils/operator_helpers.py", line 252, in run
    return self.func(*args, **kwargs)
           ^^^^^^^^^^^^^^^^^^^^^^^^^^
  File "/home/airflow/.local/lib/python3.12/site-packages/airflow/models/baseoperator.py", line 424, in wrapper
    return func(self, *args, **kwargs)
           ^^^^^^^^^^^^^^^^^^^^^^^^^^^
  File "/home/airflow/.local/lib/python3.12/site-packages/airflow/operators/python.py", line 238, in execute
    return_value = self.execute_callable()
                   ^^^^^^^^^^^^^^^^^^^^^^^
  File "/home/airflow/.local/lib/python3.12/site-packages/airflow/operators/python.py", line 256, in execute_callable
    return runner.run(*self.op_args, **self.op_kwargs)
           ^^^^^^^^^^^^^^^^^^^^^^^^^^^^^^^^^^^^^^^^^^^
  File "/home/airflow/.local/lib/python3.12/site-packages/airflow/utils/operator_helpers.py", line 252, in run
    return self.func(*args, **kwargs)
           ^^^^^^^^^^^^^^^^^^^^^^^^^^
  File "/opt/airflow/dags/dag_generate_table_info.py", line 41, in generate_table_info
    two_weeks_ago = current_date - timedelta(weeks=3)
                    ^^^^^^^^^^^^
NameError: name 'current_date' is not defined
[2025-03-01T01:58:31.061+0000] {logging_mixin.py:190} INFO - Task instance in failure state
[2025-03-01T01:58:31.061+0000] {logging_mixin.py:190} INFO - Task start:2025-03-01 01:58:30.854039+00:00 end:2025-03-01 01:58:31.060548+00:00 duration:0.206509
[2025-03-01T01:58:31.062+0000] {logging_mixin.py:190} INFO - Task:<Task(PythonOperator): insert_orders> dag:<DAG: dag_postgres_1> dagrun:<DagRun dag_postgres_1 @ 2025-03-01 01:40:00+00:00: scheduled__2025-03-01T01:40:00+00:00, state:running, queued_at: 2025-03-01 01:58:29.688825+00:00. externally triggered: False>
[2025-03-01T01:58:31.062+0000] {logging_mixin.py:190} INFO - Failure caused by name 'current_date' is not defined
[2025-03-01T01:58:31.062+0000] {taskinstance.py:1226} INFO - Marking task as UP_FOR_RETRY. dag_id=dag_postgres_1, task_id=insert_orders, run_id=scheduled__2025-03-01T01:40:00+00:00, execution_date=20250301T014000, start_date=20250301T015830, end_date=20250301T015831
[2025-03-01T01:58:31.093+0000] {taskinstance.py:341} INFO - ::group::Post task execution logs
[2025-03-01T01:58:31.093+0000] {standard_task_runner.py:124} ERROR - Failed to execute job 57 for task insert_orders (name 'current_date' is not defined; 51992)
Traceback (most recent call last):
  File "/home/airflow/.local/lib/python3.12/site-packages/airflow/task/task_runner/standard_task_runner.py", line 117, in _start_by_fork
    ret = args.func(args, dag=self.dag)
          ^^^^^^^^^^^^^^^^^^^^^^^^^^^^^
  File "/home/airflow/.local/lib/python3.12/site-packages/airflow/cli/cli_config.py", line 49, in command
    return func(*args, **kwargs)
           ^^^^^^^^^^^^^^^^^^^^^
  File "/home/airflow/.local/lib/python3.12/site-packages/airflow/utils/cli.py", line 116, in wrapper
    return f(*args, **kwargs)
           ^^^^^^^^^^^^^^^^^^
  File "/home/airflow/.local/lib/python3.12/site-packages/airflow/cli/commands/task_command.py", line 483, in task_run
    task_return_code = _run_task_by_selected_method(args, _dag, ti)
                       ^^^^^^^^^^^^^^^^^^^^^^^^^^^^^^^^^^^^^^^^^^^^
  File "/home/airflow/.local/lib/python3.12/site-packages/airflow/cli/commands/task_command.py", line 256, in _run_task_by_selected_method
    return _run_raw_task(args, ti)
           ^^^^^^^^^^^^^^^^^^^^^^^
  File "/home/airflow/.local/lib/python3.12/site-packages/airflow/cli/commands/task_command.py", line 341, in _run_raw_task
    return ti._run_raw_task(
           ^^^^^^^^^^^^^^^^^
  File "/home/airflow/.local/lib/python3.12/site-packages/airflow/utils/session.py", line 97, in wrapper
    return func(*args, session=session, **kwargs)
           ^^^^^^^^^^^^^^^^^^^^^^^^^^^^^^^^^^^^^^
  File "/home/airflow/.local/lib/python3.12/site-packages/airflow/models/taskinstance.py", line 3006, in _run_raw_task
    return _run_raw_task(
           ^^^^^^^^^^^^^^
  File "/home/airflow/.local/lib/python3.12/site-packages/airflow/models/taskinstance.py", line 274, in _run_raw_task
    TaskInstance._execute_task_with_callbacks(
  File "/home/airflow/.local/lib/python3.12/site-packages/airflow/models/taskinstance.py", line 3161, in _execute_task_with_callbacks
    result = self._execute_task(context, task_orig)
             ^^^^^^^^^^^^^^^^^^^^^^^^^^^^^^^^^^^^^^
  File "/home/airflow/.local/lib/python3.12/site-packages/airflow/models/taskinstance.py", line 3185, in _execute_task
    return _execute_task(self, context, task_orig)
           ^^^^^^^^^^^^^^^^^^^^^^^^^^^^^^^^^^^^^^^
  File "/home/airflow/.local/lib/python3.12/site-packages/airflow/models/taskinstance.py", line 768, in _execute_task
    result = _execute_callable(context=context, **execute_callable_kwargs)
             ^^^^^^^^^^^^^^^^^^^^^^^^^^^^^^^^^^^^^^^^^^^^^^^^^^^^^^^^^^^^^
  File "/home/airflow/.local/lib/python3.12/site-packages/airflow/models/taskinstance.py", line 734, in _execute_callable
    return ExecutionCallableRunner(
           ^^^^^^^^^^^^^^^^^^^^^^^^
  File "/home/airflow/.local/lib/python3.12/site-packages/airflow/utils/operator_helpers.py", line 252, in run
    return self.func(*args, **kwargs)
           ^^^^^^^^^^^^^^^^^^^^^^^^^^
  File "/home/airflow/.local/lib/python3.12/site-packages/airflow/models/baseoperator.py", line 424, in wrapper
    return func(self, *args, **kwargs)
           ^^^^^^^^^^^^^^^^^^^^^^^^^^^
  File "/home/airflow/.local/lib/python3.12/site-packages/airflow/operators/python.py", line 238, in execute
    return_value = self.execute_callable()
                   ^^^^^^^^^^^^^^^^^^^^^^^
  File "/home/airflow/.local/lib/python3.12/site-packages/airflow/operators/python.py", line 256, in execute_callable
    return runner.run(*self.op_args, **self.op_kwargs)
           ^^^^^^^^^^^^^^^^^^^^^^^^^^^^^^^^^^^^^^^^^^^
  File "/home/airflow/.local/lib/python3.12/site-packages/airflow/utils/operator_helpers.py", line 252, in run
    return self.func(*args, **kwargs)
           ^^^^^^^^^^^^^^^^^^^^^^^^^^
  File "/opt/airflow/dags/dag_generate_table_info.py", line 41, in generate_table_info
    two_weeks_ago = current_date - timedelta(weeks=3)
                    ^^^^^^^^^^^^
NameError: name 'current_date' is not defined
[2025-03-01T01:58:31.152+0000] {local_task_job_runner.py:266} INFO - Task exited with return code 1
[2025-03-01T01:58:31.161+0000] {local_task_job_runner.py:245} INFO - ::endgroup::
[2025-03-01T01:59:12.251+0000] {local_task_job_runner.py:123} INFO - ::group::Pre task execution logs
[2025-03-01T01:59:12.266+0000] {taskinstance.py:2614} INFO - Dependencies all met for dep_context=non-requeueable deps ti=<TaskInstance: dag_postgres_1.insert_orders scheduled__2025-03-01T01:40:00+00:00 [queued]>
[2025-03-01T01:59:12.274+0000] {taskinstance.py:2614} INFO - Dependencies all met for dep_context=requeueable deps ti=<TaskInstance: dag_postgres_1.insert_orders scheduled__2025-03-01T01:40:00+00:00 [queued]>
[2025-03-01T01:59:12.274+0000] {taskinstance.py:2867} INFO - Starting attempt 1 of 2
[2025-03-01T01:59:12.290+0000] {taskinstance.py:2890} INFO - Executing <Task(PythonOperator): insert_orders> on 2025-03-01 01:40:00+00:00
[2025-03-01T01:59:12.302+0000] {logging_mixin.py:190} WARNING - /home/***/.local/lib/python3.12/site-packages/***/task/task_runner/standard_task_runner.py:70 DeprecationWarning: This process (pid=52524) is multi-threaded, use of fork() may lead to deadlocks in the child.
[2025-03-01T01:59:12.302+0000] {standard_task_runner.py:104} INFO - Running: ['***', 'tasks', 'run', 'dag_postgres_1', 'insert_orders', 'scheduled__2025-03-01T01:40:00+00:00', '--job-id', '60', '--raw', '--subdir', 'DAGS_FOLDER/dag_generate_table_info.py', '--cfg-path', '/tmp/tmp7wyys5z9']
[2025-03-01T01:59:12.303+0000] {standard_task_runner.py:72} INFO - Started process 52540 to run task
[2025-03-01T01:59:12.304+0000] {standard_task_runner.py:105} INFO - Job 60: Subtask insert_orders
[2025-03-01T01:59:12.358+0000] {task_command.py:467} INFO - Running <TaskInstance: dag_postgres_1.insert_orders scheduled__2025-03-01T01:40:00+00:00 [running]> on host e6b43e607126
[2025-03-01T01:59:12.443+0000] {taskinstance.py:3134} INFO - Exporting env vars: AIRFLOW_CTX_DAG_EMAIL='kucikm23@gmail.com' AIRFLOW_CTX_DAG_OWNER='***' AIRFLOW_CTX_DAG_ID='dag_postgres_1' AIRFLOW_CTX_TASK_ID='insert_orders' AIRFLOW_CTX_EXECUTION_DATE='2025-03-01T01:40:00+00:00' AIRFLOW_CTX_TRY_NUMBER='1' AIRFLOW_CTX_DAG_RUN_ID='scheduled__2025-03-01T01:40:00+00:00'
[2025-03-01T01:59:12.444+0000] {logging_mixin.py:190} INFO - Task instance is in running state
[2025-03-01T01:59:12.445+0000] {logging_mixin.py:190} INFO -  Previous state of the Task instance: queued
[2025-03-01T01:59:12.445+0000] {logging_mixin.py:190} INFO - Current task name:insert_orders state:running start_date:2025-03-01 01:59:12.267166+00:00
[2025-03-01T01:59:12.446+0000] {logging_mixin.py:190} INFO - Dag name:dag_postgres_1 and current dag run status:running
[2025-03-01T01:59:12.446+0000] {taskinstance.py:732} INFO - ::endgroup::
[2025-03-01T01:59:12.455+0000] {taskinstance.py:3313} ERROR - Task failed with exception
Traceback (most recent call last):
  File "/home/airflow/.local/lib/python3.12/site-packages/airflow/models/taskinstance.py", line 768, in _execute_task
    result = _execute_callable(context=context, **execute_callable_kwargs)
             ^^^^^^^^^^^^^^^^^^^^^^^^^^^^^^^^^^^^^^^^^^^^^^^^^^^^^^^^^^^^^
  File "/home/airflow/.local/lib/python3.12/site-packages/airflow/models/taskinstance.py", line 734, in _execute_callable
    return ExecutionCallableRunner(
           ^^^^^^^^^^^^^^^^^^^^^^^^
  File "/home/airflow/.local/lib/python3.12/site-packages/airflow/utils/operator_helpers.py", line 252, in run
    return self.func(*args, **kwargs)
           ^^^^^^^^^^^^^^^^^^^^^^^^^^
  File "/home/airflow/.local/lib/python3.12/site-packages/airflow/models/baseoperator.py", line 424, in wrapper
    return func(self, *args, **kwargs)
           ^^^^^^^^^^^^^^^^^^^^^^^^^^^
  File "/home/airflow/.local/lib/python3.12/site-packages/airflow/operators/python.py", line 238, in execute
    return_value = self.execute_callable()
                   ^^^^^^^^^^^^^^^^^^^^^^^
  File "/home/airflow/.local/lib/python3.12/site-packages/airflow/operators/python.py", line 256, in execute_callable
    return runner.run(*self.op_args, **self.op_kwargs)
           ^^^^^^^^^^^^^^^^^^^^^^^^^^^^^^^^^^^^^^^^^^^
  File "/home/airflow/.local/lib/python3.12/site-packages/airflow/utils/operator_helpers.py", line 252, in run
    return self.func(*args, **kwargs)
           ^^^^^^^^^^^^^^^^^^^^^^^^^^
  File "/opt/airflow/dags/dag_generate_table_info.py", line 42, in generate_table_info
    two_weeks_ago = current_date - timedelta(weeks=3)
                    ^^^^^^^^^^^^
NameError: name 'current_date' is not defined
[2025-03-01T01:59:12.473+0000] {logging_mixin.py:190} INFO - Task instance in failure state
[2025-03-01T01:59:12.474+0000] {logging_mixin.py:190} INFO - Task start:2025-03-01 01:59:12.267166+00:00 end:2025-03-01 01:59:12.473082+00:00 duration:0.205916
[2025-03-01T01:59:12.474+0000] {logging_mixin.py:190} INFO - Task:<Task(PythonOperator): insert_orders> dag:<DAG: dag_postgres_1> dagrun:<DagRun dag_postgres_1 @ 2025-03-01 01:40:00+00:00: scheduled__2025-03-01T01:40:00+00:00, state:running, queued_at: 2025-03-01 01:59:11.056301+00:00. externally triggered: False>
[2025-03-01T01:59:12.474+0000] {logging_mixin.py:190} INFO - Failure caused by name 'current_date' is not defined
[2025-03-01T01:59:12.475+0000] {taskinstance.py:1226} INFO - Marking task as UP_FOR_RETRY. dag_id=dag_postgres_1, task_id=insert_orders, run_id=scheduled__2025-03-01T01:40:00+00:00, execution_date=20250301T014000, start_date=20250301T015912, end_date=20250301T015912
[2025-03-01T01:59:12.507+0000] {taskinstance.py:341} INFO - ::group::Post task execution logs
[2025-03-01T01:59:12.508+0000] {standard_task_runner.py:124} ERROR - Failed to execute job 60 for task insert_orders (name 'current_date' is not defined; 52540)
Traceback (most recent call last):
  File "/home/airflow/.local/lib/python3.12/site-packages/airflow/task/task_runner/standard_task_runner.py", line 117, in _start_by_fork
    ret = args.func(args, dag=self.dag)
          ^^^^^^^^^^^^^^^^^^^^^^^^^^^^^
  File "/home/airflow/.local/lib/python3.12/site-packages/airflow/cli/cli_config.py", line 49, in command
    return func(*args, **kwargs)
           ^^^^^^^^^^^^^^^^^^^^^
  File "/home/airflow/.local/lib/python3.12/site-packages/airflow/utils/cli.py", line 116, in wrapper
    return f(*args, **kwargs)
           ^^^^^^^^^^^^^^^^^^
  File "/home/airflow/.local/lib/python3.12/site-packages/airflow/cli/commands/task_command.py", line 483, in task_run
    task_return_code = _run_task_by_selected_method(args, _dag, ti)
                       ^^^^^^^^^^^^^^^^^^^^^^^^^^^^^^^^^^^^^^^^^^^^
  File "/home/airflow/.local/lib/python3.12/site-packages/airflow/cli/commands/task_command.py", line 256, in _run_task_by_selected_method
    return _run_raw_task(args, ti)
           ^^^^^^^^^^^^^^^^^^^^^^^
  File "/home/airflow/.local/lib/python3.12/site-packages/airflow/cli/commands/task_command.py", line 341, in _run_raw_task
    return ti._run_raw_task(
           ^^^^^^^^^^^^^^^^^
  File "/home/airflow/.local/lib/python3.12/site-packages/airflow/utils/session.py", line 97, in wrapper
    return func(*args, session=session, **kwargs)
           ^^^^^^^^^^^^^^^^^^^^^^^^^^^^^^^^^^^^^^
  File "/home/airflow/.local/lib/python3.12/site-packages/airflow/models/taskinstance.py", line 3006, in _run_raw_task
    return _run_raw_task(
           ^^^^^^^^^^^^^^
  File "/home/airflow/.local/lib/python3.12/site-packages/airflow/models/taskinstance.py", line 274, in _run_raw_task
    TaskInstance._execute_task_with_callbacks(
  File "/home/airflow/.local/lib/python3.12/site-packages/airflow/models/taskinstance.py", line 3161, in _execute_task_with_callbacks
    result = self._execute_task(context, task_orig)
             ^^^^^^^^^^^^^^^^^^^^^^^^^^^^^^^^^^^^^^
  File "/home/airflow/.local/lib/python3.12/site-packages/airflow/models/taskinstance.py", line 3185, in _execute_task
    return _execute_task(self, context, task_orig)
           ^^^^^^^^^^^^^^^^^^^^^^^^^^^^^^^^^^^^^^^
  File "/home/airflow/.local/lib/python3.12/site-packages/airflow/models/taskinstance.py", line 768, in _execute_task
    result = _execute_callable(context=context, **execute_callable_kwargs)
             ^^^^^^^^^^^^^^^^^^^^^^^^^^^^^^^^^^^^^^^^^^^^^^^^^^^^^^^^^^^^^
  File "/home/airflow/.local/lib/python3.12/site-packages/airflow/models/taskinstance.py", line 734, in _execute_callable
    return ExecutionCallableRunner(
           ^^^^^^^^^^^^^^^^^^^^^^^^
  File "/home/airflow/.local/lib/python3.12/site-packages/airflow/utils/operator_helpers.py", line 252, in run
    return self.func(*args, **kwargs)
           ^^^^^^^^^^^^^^^^^^^^^^^^^^
  File "/home/airflow/.local/lib/python3.12/site-packages/airflow/models/baseoperator.py", line 424, in wrapper
    return func(self, *args, **kwargs)
           ^^^^^^^^^^^^^^^^^^^^^^^^^^^
  File "/home/airflow/.local/lib/python3.12/site-packages/airflow/operators/python.py", line 238, in execute
    return_value = self.execute_callable()
                   ^^^^^^^^^^^^^^^^^^^^^^^
  File "/home/airflow/.local/lib/python3.12/site-packages/airflow/operators/python.py", line 256, in execute_callable
    return runner.run(*self.op_args, **self.op_kwargs)
           ^^^^^^^^^^^^^^^^^^^^^^^^^^^^^^^^^^^^^^^^^^^
  File "/home/airflow/.local/lib/python3.12/site-packages/airflow/utils/operator_helpers.py", line 252, in run
    return self.func(*args, **kwargs)
           ^^^^^^^^^^^^^^^^^^^^^^^^^^
  File "/opt/airflow/dags/dag_generate_table_info.py", line 42, in generate_table_info
    two_weeks_ago = current_date - timedelta(weeks=3)
                    ^^^^^^^^^^^^
NameError: name 'current_date' is not defined
[2025-03-01T01:59:12.559+0000] {local_task_job_runner.py:266} INFO - Task exited with return code 1
[2025-03-01T01:59:12.583+0000] {taskinstance.py:3901} INFO - 0 downstream tasks scheduled from follow-on schedule check
[2025-03-01T01:59:12.588+0000] {local_task_job_runner.py:245} INFO - ::endgroup::
