[2025-03-01T01:30:50.278+0000] {local_task_job_runner.py:123} INFO - ::group::Pre task execution logs
[2025-03-01T01:30:50.297+0000] {taskinstance.py:2614} INFO - Dependencies all met for dep_context=non-requeueable deps ti=<TaskInstance: dag_postgres_1.generate_and_insert_orders manual__2025-03-01T01:30:44.355820+00:00 [queued]>
[2025-03-01T01:30:50.305+0000] {taskinstance.py:2614} INFO - Dependencies all met for dep_context=requeueable deps ti=<TaskInstance: dag_postgres_1.generate_and_insert_orders manual__2025-03-01T01:30:44.355820+00:00 [queued]>
[2025-03-01T01:30:50.306+0000] {taskinstance.py:2867} INFO - Starting attempt 1 of 2
[2025-03-01T01:30:50.318+0000] {taskinstance.py:2890} INFO - Executing <Task(PythonOperator): generate_and_insert_orders> on 2025-03-01 01:30:44.355820+00:00
[2025-03-01T01:30:50.328+0000] {standard_task_runner.py:104} INFO - Running: ['***', 'tasks', 'run', 'dag_postgres_1', 'generate_and_insert_orders', 'manual__2025-03-01T01:30:44.355820+00:00', '--job-id', '37', '--raw', '--subdir', 'DAGS_FOLDER/dag_generate_table_info.py', '--cfg-path', '/tmp/tmp7jxkeogy']
[2025-03-01T01:30:50.330+0000] {standard_task_runner.py:105} INFO - Job 37: Subtask generate_and_insert_orders
[2025-03-01T01:30:50.331+0000] {logging_mixin.py:190} WARNING - /home/***/.local/lib/python3.12/site-packages/***/task/task_runner/standard_task_runner.py:70 DeprecationWarning: This process (pid=36079) is multi-threaded, use of fork() may lead to deadlocks in the child.
[2025-03-01T01:30:50.332+0000] {standard_task_runner.py:72} INFO - Started process 36080 to run task
[2025-03-01T01:30:50.372+0000] {task_command.py:467} INFO - Running <TaskInstance: dag_postgres_1.generate_and_insert_orders manual__2025-03-01T01:30:44.355820+00:00 [running]> on host e6b43e607126
[2025-03-01T01:30:50.448+0000] {taskinstance.py:3134} INFO - Exporting env vars: AIRFLOW_CTX_DAG_EMAIL='kucikm23@gmail.com' AIRFLOW_CTX_DAG_OWNER='***' AIRFLOW_CTX_DAG_ID='dag_postgres_1' AIRFLOW_CTX_TASK_ID='generate_and_insert_orders' AIRFLOW_CTX_EXECUTION_DATE='2025-03-01T01:30:44.355820+00:00' AIRFLOW_CTX_TRY_NUMBER='1' AIRFLOW_CTX_DAG_RUN_ID='manual__2025-03-01T01:30:44.355820+00:00'
[2025-03-01T01:30:50.450+0000] {logging_mixin.py:190} INFO - Task instance is in running state
[2025-03-01T01:30:50.450+0000] {logging_mixin.py:190} INFO -  Previous state of the Task instance: queued
[2025-03-01T01:30:50.450+0000] {logging_mixin.py:190} INFO - Current task name:generate_and_insert_orders state:running start_date:2025-03-01 01:30:50.298177+00:00
[2025-03-01T01:30:50.451+0000] {logging_mixin.py:190} INFO - Dag name:dag_postgres_1 and current dag run status:running
[2025-03-01T01:30:50.451+0000] {taskinstance.py:732} INFO - ::endgroup::
[2025-03-01T01:30:50.459+0000] {taskinstance.py:3313} ERROR - Task failed with exception
Traceback (most recent call last):
  File "/home/airflow/.local/lib/python3.12/site-packages/airflow/models/taskinstance.py", line 768, in _execute_task
    result = _execute_callable(context=context, **execute_callable_kwargs)
             ^^^^^^^^^^^^^^^^^^^^^^^^^^^^^^^^^^^^^^^^^^^^^^^^^^^^^^^^^^^^^
  File "/home/airflow/.local/lib/python3.12/site-packages/airflow/models/taskinstance.py", line 734, in _execute_callable
    return ExecutionCallableRunner(
           ^^^^^^^^^^^^^^^^^^^^^^^^
  File "/home/airflow/.local/lib/python3.12/site-packages/airflow/utils/operator_helpers.py", line 252, in run
    return self.func(*args, **kwargs)
           ^^^^^^^^^^^^^^^^^^^^^^^^^^
  File "/home/airflow/.local/lib/python3.12/site-packages/airflow/models/baseoperator.py", line 424, in wrapper
    return func(self, *args, **kwargs)
           ^^^^^^^^^^^^^^^^^^^^^^^^^^^
  File "/home/airflow/.local/lib/python3.12/site-packages/airflow/operators/python.py", line 238, in execute
    return_value = self.execute_callable()
                   ^^^^^^^^^^^^^^^^^^^^^^^
  File "/home/airflow/.local/lib/python3.12/site-packages/airflow/operators/python.py", line 256, in execute_callable
    return runner.run(*self.op_args, **self.op_kwargs)
           ^^^^^^^^^^^^^^^^^^^^^^^^^^^^^^^^^^^^^^^^^^^
  File "/home/airflow/.local/lib/python3.12/site-packages/airflow/utils/operator_helpers.py", line 252, in run
    return self.func(*args, **kwargs)
           ^^^^^^^^^^^^^^^^^^^^^^^^^^
  File "/opt/airflow/dags/dag_generate_table_info.py", line 57, in generate_and_insert_orders
    currency = random.choice(currencies)
               ^^^^^^^^^^^^^^^^^^^^^^^^^
  File "/usr/local/lib/python3.12/random.py", line 346, in choice
    if not len(seq):
           ^^^^^^^^
TypeError: object of type 'NoneType' has no len()
[2025-03-01T01:30:50.472+0000] {logging_mixin.py:190} INFO - Task instance in failure state
[2025-03-01T01:30:50.473+0000] {logging_mixin.py:190} INFO - Task start:2025-03-01 01:30:50.298177+00:00 end:2025-03-01 01:30:50.472439+00:00 duration:0.174262
[2025-03-01T01:30:50.473+0000] {logging_mixin.py:190} INFO - Task:<Task(PythonOperator): generate_and_insert_orders> dag:<DAG: dag_postgres_1> dagrun:<DagRun dag_postgres_1 @ 2025-03-01 01:30:44.355820+00:00: manual__2025-03-01T01:30:44.355820+00:00, state:running, queued_at: 2025-03-01 01:30:44.364312+00:00. externally triggered: True>
[2025-03-01T01:30:50.474+0000] {logging_mixin.py:190} INFO - Failure caused by object of type 'NoneType' has no len()
[2025-03-01T01:30:50.474+0000] {taskinstance.py:1226} INFO - Marking task as UP_FOR_RETRY. dag_id=dag_postgres_1, task_id=generate_and_insert_orders, run_id=manual__2025-03-01T01:30:44.355820+00:00, execution_date=20250301T013044, start_date=20250301T013050, end_date=20250301T013050
[2025-03-01T01:30:50.502+0000] {taskinstance.py:341} INFO - ::group::Post task execution logs
[2025-03-01T01:30:50.503+0000] {standard_task_runner.py:124} ERROR - Failed to execute job 37 for task generate_and_insert_orders (object of type 'NoneType' has no len(); 36080)
Traceback (most recent call last):
  File "/home/airflow/.local/lib/python3.12/site-packages/airflow/task/task_runner/standard_task_runner.py", line 117, in _start_by_fork
    ret = args.func(args, dag=self.dag)
          ^^^^^^^^^^^^^^^^^^^^^^^^^^^^^
  File "/home/airflow/.local/lib/python3.12/site-packages/airflow/cli/cli_config.py", line 49, in command
    return func(*args, **kwargs)
           ^^^^^^^^^^^^^^^^^^^^^
  File "/home/airflow/.local/lib/python3.12/site-packages/airflow/utils/cli.py", line 116, in wrapper
    return f(*args, **kwargs)
           ^^^^^^^^^^^^^^^^^^
  File "/home/airflow/.local/lib/python3.12/site-packages/airflow/cli/commands/task_command.py", line 483, in task_run
    task_return_code = _run_task_by_selected_method(args, _dag, ti)
                       ^^^^^^^^^^^^^^^^^^^^^^^^^^^^^^^^^^^^^^^^^^^^
  File "/home/airflow/.local/lib/python3.12/site-packages/airflow/cli/commands/task_command.py", line 256, in _run_task_by_selected_method
    return _run_raw_task(args, ti)
           ^^^^^^^^^^^^^^^^^^^^^^^
  File "/home/airflow/.local/lib/python3.12/site-packages/airflow/cli/commands/task_command.py", line 341, in _run_raw_task
    return ti._run_raw_task(
           ^^^^^^^^^^^^^^^^^
  File "/home/airflow/.local/lib/python3.12/site-packages/airflow/utils/session.py", line 97, in wrapper
    return func(*args, session=session, **kwargs)
           ^^^^^^^^^^^^^^^^^^^^^^^^^^^^^^^^^^^^^^
  File "/home/airflow/.local/lib/python3.12/site-packages/airflow/models/taskinstance.py", line 3006, in _run_raw_task
    return _run_raw_task(
           ^^^^^^^^^^^^^^
  File "/home/airflow/.local/lib/python3.12/site-packages/airflow/models/taskinstance.py", line 274, in _run_raw_task
    TaskInstance._execute_task_with_callbacks(
  File "/home/airflow/.local/lib/python3.12/site-packages/airflow/models/taskinstance.py", line 3161, in _execute_task_with_callbacks
    result = self._execute_task(context, task_orig)
             ^^^^^^^^^^^^^^^^^^^^^^^^^^^^^^^^^^^^^^
  File "/home/airflow/.local/lib/python3.12/site-packages/airflow/models/taskinstance.py", line 3185, in _execute_task
    return _execute_task(self, context, task_orig)
           ^^^^^^^^^^^^^^^^^^^^^^^^^^^^^^^^^^^^^^^
  File "/home/airflow/.local/lib/python3.12/site-packages/airflow/models/taskinstance.py", line 768, in _execute_task
    result = _execute_callable(context=context, **execute_callable_kwargs)
             ^^^^^^^^^^^^^^^^^^^^^^^^^^^^^^^^^^^^^^^^^^^^^^^^^^^^^^^^^^^^^
  File "/home/airflow/.local/lib/python3.12/site-packages/airflow/models/taskinstance.py", line 734, in _execute_callable
    return ExecutionCallableRunner(
           ^^^^^^^^^^^^^^^^^^^^^^^^
  File "/home/airflow/.local/lib/python3.12/site-packages/airflow/utils/operator_helpers.py", line 252, in run
    return self.func(*args, **kwargs)
           ^^^^^^^^^^^^^^^^^^^^^^^^^^
  File "/home/airflow/.local/lib/python3.12/site-packages/airflow/models/baseoperator.py", line 424, in wrapper
    return func(self, *args, **kwargs)
           ^^^^^^^^^^^^^^^^^^^^^^^^^^^
  File "/home/airflow/.local/lib/python3.12/site-packages/airflow/operators/python.py", line 238, in execute
    return_value = self.execute_callable()
                   ^^^^^^^^^^^^^^^^^^^^^^^
  File "/home/airflow/.local/lib/python3.12/site-packages/airflow/operators/python.py", line 256, in execute_callable
    return runner.run(*self.op_args, **self.op_kwargs)
           ^^^^^^^^^^^^^^^^^^^^^^^^^^^^^^^^^^^^^^^^^^^
  File "/home/airflow/.local/lib/python3.12/site-packages/airflow/utils/operator_helpers.py", line 252, in run
    return self.func(*args, **kwargs)
           ^^^^^^^^^^^^^^^^^^^^^^^^^^
  File "/opt/airflow/dags/dag_generate_table_info.py", line 57, in generate_and_insert_orders
    currency = random.choice(currencies)
               ^^^^^^^^^^^^^^^^^^^^^^^^^
  File "/usr/local/lib/python3.12/random.py", line 346, in choice
    if not len(seq):
           ^^^^^^^^
TypeError: object of type 'NoneType' has no len()
[2025-03-01T01:30:50.546+0000] {local_task_job_runner.py:266} INFO - Task exited with return code 1
[2025-03-01T01:30:50.567+0000] {taskinstance.py:3901} INFO - 0 downstream tasks scheduled from follow-on schedule check
[2025-03-01T01:30:50.570+0000] {local_task_job_runner.py:245} INFO - ::endgroup::
