[2025-03-01T02:00:05.564+0000] {local_task_job_runner.py:123} INFO - ::group::Pre task execution logs
[2025-03-01T02:00:05.582+0000] {taskinstance.py:2614} INFO - Dependencies all met for dep_context=non-requeueable deps ti=<TaskInstance: dag_postgres_1.generate_orders_data scheduled__2025-03-01T01:50:00+00:00 [queued]>
[2025-03-01T02:00:05.590+0000] {taskinstance.py:2614} INFO - Dependencies all met for dep_context=requeueable deps ti=<TaskInstance: dag_postgres_1.generate_orders_data scheduled__2025-03-01T01:50:00+00:00 [queued]>
[2025-03-01T02:00:05.591+0000] {taskinstance.py:2867} INFO - Starting attempt 1 of 2
[2025-03-01T02:00:05.604+0000] {taskinstance.py:2890} INFO - Executing <Task(PythonOperator): generate_orders_data> on 2025-03-01 01:50:00+00:00
[2025-03-01T02:00:05.614+0000] {logging_mixin.py:190} WARNING - /home/***/.local/lib/python3.12/site-packages/***/task/task_runner/standard_task_runner.py:70 DeprecationWarning: This process (pid=52928) is multi-threaded, use of fork() may lead to deadlocks in the child.
[2025-03-01T02:00:05.614+0000] {standard_task_runner.py:104} INFO - Running: ['***', 'tasks', 'run', 'dag_postgres_1', 'generate_orders_data', 'scheduled__2025-03-01T01:50:00+00:00', '--job-id', '67', '--raw', '--subdir', 'DAGS_FOLDER/dag_generate_table_info.py', '--cfg-path', '/tmp/tmpzhhm22m3']
[2025-03-01T02:00:05.615+0000] {standard_task_runner.py:72} INFO - Started process 52931 to run task
[2025-03-01T02:00:05.615+0000] {standard_task_runner.py:105} INFO - Job 67: Subtask generate_orders_data
[2025-03-01T02:00:05.657+0000] {task_command.py:467} INFO - Running <TaskInstance: dag_postgres_1.generate_orders_data scheduled__2025-03-01T01:50:00+00:00 [running]> on host e6b43e607126
[2025-03-01T02:00:05.736+0000] {taskinstance.py:3134} INFO - Exporting env vars: AIRFLOW_CTX_DAG_EMAIL='kucikm23@gmail.com' AIRFLOW_CTX_DAG_OWNER='***' AIRFLOW_CTX_DAG_ID='dag_postgres_1' AIRFLOW_CTX_TASK_ID='generate_orders_data' AIRFLOW_CTX_EXECUTION_DATE='2025-03-01T01:50:00+00:00' AIRFLOW_CTX_TRY_NUMBER='1' AIRFLOW_CTX_DAG_RUN_ID='scheduled__2025-03-01T01:50:00+00:00'
[2025-03-01T02:00:05.737+0000] {logging_mixin.py:190} INFO - Task instance is in running state
[2025-03-01T02:00:05.737+0000] {logging_mixin.py:190} INFO -  Previous state of the Task instance: queued
[2025-03-01T02:00:05.738+0000] {logging_mixin.py:190} INFO - Current task name:generate_orders_data state:running start_date:2025-03-01 02:00:05.583367+00:00
[2025-03-01T02:00:05.738+0000] {logging_mixin.py:190} INFO - Dag name:dag_postgres_1 and current dag run status:running
[2025-03-01T02:00:05.738+0000] {taskinstance.py:732} INFO - ::endgroup::
[2025-03-01T02:00:05.747+0000] {taskinstance.py:3313} ERROR - Task failed with exception
Traceback (most recent call last):
  File "/home/airflow/.local/lib/python3.12/site-packages/airflow/models/taskinstance.py", line 768, in _execute_task
    result = _execute_callable(context=context, **execute_callable_kwargs)
             ^^^^^^^^^^^^^^^^^^^^^^^^^^^^^^^^^^^^^^^^^^^^^^^^^^^^^^^^^^^^^
  File "/home/airflow/.local/lib/python3.12/site-packages/airflow/models/taskinstance.py", line 734, in _execute_callable
    return ExecutionCallableRunner(
           ^^^^^^^^^^^^^^^^^^^^^^^^
  File "/home/airflow/.local/lib/python3.12/site-packages/airflow/utils/operator_helpers.py", line 252, in run
    return self.func(*args, **kwargs)
           ^^^^^^^^^^^^^^^^^^^^^^^^^^
  File "/home/airflow/.local/lib/python3.12/site-packages/airflow/models/baseoperator.py", line 424, in wrapper
    return func(self, *args, **kwargs)
           ^^^^^^^^^^^^^^^^^^^^^^^^^^^
  File "/home/airflow/.local/lib/python3.12/site-packages/airflow/operators/python.py", line 238, in execute
    return_value = self.execute_callable()
                   ^^^^^^^^^^^^^^^^^^^^^^^
  File "/home/airflow/.local/lib/python3.12/site-packages/airflow/operators/python.py", line 256, in execute_callable
    return runner.run(*self.op_args, **self.op_kwargs)
           ^^^^^^^^^^^^^^^^^^^^^^^^^^^^^^^^^^^^^^^^^^^
  File "/home/airflow/.local/lib/python3.12/site-packages/airflow/utils/operator_helpers.py", line 252, in run
    return self.func(*args, **kwargs)
           ^^^^^^^^^^^^^^^^^^^^^^^^^^
  File "/opt/airflow/dags/dag_generate_table_info.py", line 42, in generate_table_info
    two_weeks_ago = current_date - timedelta(weeks=3)
                    ^^^^^^^^^^^^
NameError: name 'current_date' is not defined
[2025-03-01T02:00:05.764+0000] {logging_mixin.py:190} INFO - Task instance in failure state
[2025-03-01T02:00:05.765+0000] {logging_mixin.py:190} INFO - Task start:2025-03-01 02:00:05.583367+00:00 end:2025-03-01 02:00:05.764328+00:00 duration:0.180961
[2025-03-01T02:00:05.765+0000] {logging_mixin.py:190} INFO - Task:<Task(PythonOperator): generate_orders_data> dag:<DAG: dag_postgres_1> dagrun:<DagRun dag_postgres_1 @ 2025-03-01 01:50:00+00:00: scheduled__2025-03-01T01:50:00+00:00, state:running, queued_at: 2025-03-01 02:00:00.529895+00:00. externally triggered: False>
[2025-03-01T02:00:05.766+0000] {logging_mixin.py:190} INFO - Failure caused by name 'current_date' is not defined
[2025-03-01T02:00:05.766+0000] {taskinstance.py:1226} INFO - Marking task as UP_FOR_RETRY. dag_id=dag_postgres_1, task_id=generate_orders_data, run_id=scheduled__2025-03-01T01:50:00+00:00, execution_date=20250301T015000, start_date=20250301T020005, end_date=20250301T020005
[2025-03-01T02:00:05.795+0000] {taskinstance.py:341} INFO - ::group::Post task execution logs
[2025-03-01T02:00:05.795+0000] {standard_task_runner.py:124} ERROR - Failed to execute job 67 for task generate_orders_data (name 'current_date' is not defined; 52931)
Traceback (most recent call last):
  File "/home/airflow/.local/lib/python3.12/site-packages/airflow/task/task_runner/standard_task_runner.py", line 117, in _start_by_fork
    ret = args.func(args, dag=self.dag)
          ^^^^^^^^^^^^^^^^^^^^^^^^^^^^^
  File "/home/airflow/.local/lib/python3.12/site-packages/airflow/cli/cli_config.py", line 49, in command
    return func(*args, **kwargs)
           ^^^^^^^^^^^^^^^^^^^^^
  File "/home/airflow/.local/lib/python3.12/site-packages/airflow/utils/cli.py", line 116, in wrapper
    return f(*args, **kwargs)
           ^^^^^^^^^^^^^^^^^^
  File "/home/airflow/.local/lib/python3.12/site-packages/airflow/cli/commands/task_command.py", line 483, in task_run
    task_return_code = _run_task_by_selected_method(args, _dag, ti)
                       ^^^^^^^^^^^^^^^^^^^^^^^^^^^^^^^^^^^^^^^^^^^^
  File "/home/airflow/.local/lib/python3.12/site-packages/airflow/cli/commands/task_command.py", line 256, in _run_task_by_selected_method
    return _run_raw_task(args, ti)
           ^^^^^^^^^^^^^^^^^^^^^^^
  File "/home/airflow/.local/lib/python3.12/site-packages/airflow/cli/commands/task_command.py", line 341, in _run_raw_task
    return ti._run_raw_task(
           ^^^^^^^^^^^^^^^^^
  File "/home/airflow/.local/lib/python3.12/site-packages/airflow/utils/session.py", line 97, in wrapper
    return func(*args, session=session, **kwargs)
           ^^^^^^^^^^^^^^^^^^^^^^^^^^^^^^^^^^^^^^
  File "/home/airflow/.local/lib/python3.12/site-packages/airflow/models/taskinstance.py", line 3006, in _run_raw_task
    return _run_raw_task(
           ^^^^^^^^^^^^^^
  File "/home/airflow/.local/lib/python3.12/site-packages/airflow/models/taskinstance.py", line 274, in _run_raw_task
    TaskInstance._execute_task_with_callbacks(
  File "/home/airflow/.local/lib/python3.12/site-packages/airflow/models/taskinstance.py", line 3161, in _execute_task_with_callbacks
    result = self._execute_task(context, task_orig)
             ^^^^^^^^^^^^^^^^^^^^^^^^^^^^^^^^^^^^^^
  File "/home/airflow/.local/lib/python3.12/site-packages/airflow/models/taskinstance.py", line 3185, in _execute_task
    return _execute_task(self, context, task_orig)
           ^^^^^^^^^^^^^^^^^^^^^^^^^^^^^^^^^^^^^^^
  File "/home/airflow/.local/lib/python3.12/site-packages/airflow/models/taskinstance.py", line 768, in _execute_task
    result = _execute_callable(context=context, **execute_callable_kwargs)
             ^^^^^^^^^^^^^^^^^^^^^^^^^^^^^^^^^^^^^^^^^^^^^^^^^^^^^^^^^^^^^
  File "/home/airflow/.local/lib/python3.12/site-packages/airflow/models/taskinstance.py", line 734, in _execute_callable
    return ExecutionCallableRunner(
           ^^^^^^^^^^^^^^^^^^^^^^^^
  File "/home/airflow/.local/lib/python3.12/site-packages/airflow/utils/operator_helpers.py", line 252, in run
    return self.func(*args, **kwargs)
           ^^^^^^^^^^^^^^^^^^^^^^^^^^
  File "/home/airflow/.local/lib/python3.12/site-packages/airflow/models/baseoperator.py", line 424, in wrapper
    return func(self, *args, **kwargs)
           ^^^^^^^^^^^^^^^^^^^^^^^^^^^
  File "/home/airflow/.local/lib/python3.12/site-packages/airflow/operators/python.py", line 238, in execute
    return_value = self.execute_callable()
                   ^^^^^^^^^^^^^^^^^^^^^^^
  File "/home/airflow/.local/lib/python3.12/site-packages/airflow/operators/python.py", line 256, in execute_callable
    return runner.run(*self.op_args, **self.op_kwargs)
           ^^^^^^^^^^^^^^^^^^^^^^^^^^^^^^^^^^^^^^^^^^^
  File "/home/airflow/.local/lib/python3.12/site-packages/airflow/utils/operator_helpers.py", line 252, in run
    return self.func(*args, **kwargs)
           ^^^^^^^^^^^^^^^^^^^^^^^^^^
  File "/opt/airflow/dags/dag_generate_table_info.py", line 42, in generate_table_info
    two_weeks_ago = current_date - timedelta(weeks=3)
                    ^^^^^^^^^^^^
NameError: name 'current_date' is not defined
[2025-03-01T02:00:05.830+0000] {local_task_job_runner.py:266} INFO - Task exited with return code 1
[2025-03-01T02:00:05.851+0000] {taskinstance.py:3901} INFO - 0 downstream tasks scheduled from follow-on schedule check
[2025-03-01T02:00:05.855+0000] {local_task_job_runner.py:245} INFO - ::endgroup::
[2025-03-01T02:03:46.876+0000] {local_task_job_runner.py:123} INFO - ::group::Pre task execution logs
[2025-03-01T02:03:46.897+0000] {taskinstance.py:2614} INFO - Dependencies all met for dep_context=non-requeueable deps ti=<TaskInstance: dag_postgres_1.generate_orders_data scheduled__2025-03-01T01:50:00+00:00 [queued]>
[2025-03-01T02:03:46.906+0000] {taskinstance.py:2614} INFO - Dependencies all met for dep_context=requeueable deps ti=<TaskInstance: dag_postgres_1.generate_orders_data scheduled__2025-03-01T01:50:00+00:00 [queued]>
[2025-03-01T02:03:46.907+0000] {taskinstance.py:2867} INFO - Starting attempt 1 of 2
[2025-03-01T02:03:46.922+0000] {taskinstance.py:2890} INFO - Executing <Task(PythonOperator): generate_orders_data> on 2025-03-01 01:50:00+00:00
[2025-03-01T02:03:46.933+0000] {logging_mixin.py:190} WARNING - /home/***/.local/lib/python3.12/site-packages/***/task/task_runner/standard_task_runner.py:70 DeprecationWarning: This process (pid=55071) is multi-threaded, use of fork() may lead to deadlocks in the child.
[2025-03-01T02:03:46.932+0000] {standard_task_runner.py:104} INFO - Running: ['***', 'tasks', 'run', 'dag_postgres_1', 'generate_orders_data', 'scheduled__2025-03-01T01:50:00+00:00', '--job-id', '75', '--raw', '--subdir', 'DAGS_FOLDER/dag_generate_table_info.py', '--cfg-path', '/tmp/tmp3rdlc4dk']
[2025-03-01T02:03:46.934+0000] {standard_task_runner.py:72} INFO - Started process 55082 to run task
[2025-03-01T02:03:46.934+0000] {standard_task_runner.py:105} INFO - Job 75: Subtask generate_orders_data
[2025-03-01T02:03:46.980+0000] {task_command.py:467} INFO - Running <TaskInstance: dag_postgres_1.generate_orders_data scheduled__2025-03-01T01:50:00+00:00 [running]> on host e6b43e607126
[2025-03-01T02:03:47.071+0000] {taskinstance.py:3134} INFO - Exporting env vars: AIRFLOW_CTX_DAG_EMAIL='kucikm23@gmail.com' AIRFLOW_CTX_DAG_OWNER='***' AIRFLOW_CTX_DAG_ID='dag_postgres_1' AIRFLOW_CTX_TASK_ID='generate_orders_data' AIRFLOW_CTX_EXECUTION_DATE='2025-03-01T01:50:00+00:00' AIRFLOW_CTX_TRY_NUMBER='1' AIRFLOW_CTX_DAG_RUN_ID='scheduled__2025-03-01T01:50:00+00:00'
[2025-03-01T02:03:47.073+0000] {logging_mixin.py:190} INFO - Task instance is in running state
[2025-03-01T02:03:47.073+0000] {logging_mixin.py:190} INFO -  Previous state of the Task instance: queued
[2025-03-01T02:03:47.074+0000] {logging_mixin.py:190} INFO - Current task name:generate_orders_data state:running start_date:2025-03-01 02:03:46.898158+00:00
[2025-03-01T02:03:47.074+0000] {logging_mixin.py:190} INFO - Dag name:dag_postgres_1 and current dag run status:running
[2025-03-01T02:03:47.074+0000] {taskinstance.py:732} INFO - ::endgroup::
[2025-03-01T02:03:47.084+0000] {taskinstance.py:3313} ERROR - Task failed with exception
Traceback (most recent call last):
  File "/home/airflow/.local/lib/python3.12/site-packages/airflow/models/taskinstance.py", line 768, in _execute_task
    result = _execute_callable(context=context, **execute_callable_kwargs)
             ^^^^^^^^^^^^^^^^^^^^^^^^^^^^^^^^^^^^^^^^^^^^^^^^^^^^^^^^^^^^^
  File "/home/airflow/.local/lib/python3.12/site-packages/airflow/models/taskinstance.py", line 734, in _execute_callable
    return ExecutionCallableRunner(
           ^^^^^^^^^^^^^^^^^^^^^^^^
  File "/home/airflow/.local/lib/python3.12/site-packages/airflow/utils/operator_helpers.py", line 252, in run
    return self.func(*args, **kwargs)
           ^^^^^^^^^^^^^^^^^^^^^^^^^^
  File "/home/airflow/.local/lib/python3.12/site-packages/airflow/models/baseoperator.py", line 424, in wrapper
    return func(self, *args, **kwargs)
           ^^^^^^^^^^^^^^^^^^^^^^^^^^^
  File "/home/airflow/.local/lib/python3.12/site-packages/airflow/operators/python.py", line 238, in execute
    return_value = self.execute_callable()
                   ^^^^^^^^^^^^^^^^^^^^^^^
  File "/home/airflow/.local/lib/python3.12/site-packages/airflow/operators/python.py", line 256, in execute_callable
    return runner.run(*self.op_args, **self.op_kwargs)
           ^^^^^^^^^^^^^^^^^^^^^^^^^^^^^^^^^^^^^^^^^^^
  File "/home/airflow/.local/lib/python3.12/site-packages/airflow/utils/operator_helpers.py", line 252, in run
    return self.func(*args, **kwargs)
           ^^^^^^^^^^^^^^^^^^^^^^^^^^
  File "/opt/airflow/dags/dag_generate_table_info.py", line 42, in generate_table_info
    two_weeks_ago = current_date - timedelta(weeks=3)
                    ^^^^^^^^^^^^
NameError: name 'current_date' is not defined
[2025-03-01T02:03:47.102+0000] {logging_mixin.py:190} INFO - Task instance in failure state
[2025-03-01T02:03:47.102+0000] {logging_mixin.py:190} INFO - Task start:2025-03-01 02:03:46.898158+00:00 end:2025-03-01 02:03:47.101562+00:00 duration:0.203404
[2025-03-01T02:03:47.103+0000] {logging_mixin.py:190} INFO - Task:<Task(PythonOperator): generate_orders_data> dag:<DAG: dag_postgres_1> dagrun:<DagRun dag_postgres_1 @ 2025-03-01 01:50:00+00:00: scheduled__2025-03-01T01:50:00+00:00, state:running, queued_at: 2025-03-01 02:03:40.548117+00:00. externally triggered: False>
[2025-03-01T02:03:47.103+0000] {logging_mixin.py:190} INFO - Failure caused by name 'current_date' is not defined
[2025-03-01T02:03:47.103+0000] {taskinstance.py:1226} INFO - Marking task as UP_FOR_RETRY. dag_id=dag_postgres_1, task_id=generate_orders_data, run_id=scheduled__2025-03-01T01:50:00+00:00, execution_date=20250301T015000, start_date=20250301T020346, end_date=20250301T020347
[2025-03-01T02:03:47.139+0000] {taskinstance.py:341} INFO - ::group::Post task execution logs
[2025-03-01T02:03:47.140+0000] {standard_task_runner.py:124} ERROR - Failed to execute job 75 for task generate_orders_data (name 'current_date' is not defined; 55082)
Traceback (most recent call last):
  File "/home/airflow/.local/lib/python3.12/site-packages/airflow/task/task_runner/standard_task_runner.py", line 117, in _start_by_fork
    ret = args.func(args, dag=self.dag)
          ^^^^^^^^^^^^^^^^^^^^^^^^^^^^^
  File "/home/airflow/.local/lib/python3.12/site-packages/airflow/cli/cli_config.py", line 49, in command
    return func(*args, **kwargs)
           ^^^^^^^^^^^^^^^^^^^^^
  File "/home/airflow/.local/lib/python3.12/site-packages/airflow/utils/cli.py", line 116, in wrapper
    return f(*args, **kwargs)
           ^^^^^^^^^^^^^^^^^^
  File "/home/airflow/.local/lib/python3.12/site-packages/airflow/cli/commands/task_command.py", line 483, in task_run
    task_return_code = _run_task_by_selected_method(args, _dag, ti)
                       ^^^^^^^^^^^^^^^^^^^^^^^^^^^^^^^^^^^^^^^^^^^^
  File "/home/airflow/.local/lib/python3.12/site-packages/airflow/cli/commands/task_command.py", line 256, in _run_task_by_selected_method
    return _run_raw_task(args, ti)
           ^^^^^^^^^^^^^^^^^^^^^^^
  File "/home/airflow/.local/lib/python3.12/site-packages/airflow/cli/commands/task_command.py", line 341, in _run_raw_task
    return ti._run_raw_task(
           ^^^^^^^^^^^^^^^^^
  File "/home/airflow/.local/lib/python3.12/site-packages/airflow/utils/session.py", line 97, in wrapper
    return func(*args, session=session, **kwargs)
           ^^^^^^^^^^^^^^^^^^^^^^^^^^^^^^^^^^^^^^
  File "/home/airflow/.local/lib/python3.12/site-packages/airflow/models/taskinstance.py", line 3006, in _run_raw_task
    return _run_raw_task(
           ^^^^^^^^^^^^^^
  File "/home/airflow/.local/lib/python3.12/site-packages/airflow/models/taskinstance.py", line 274, in _run_raw_task
    TaskInstance._execute_task_with_callbacks(
  File "/home/airflow/.local/lib/python3.12/site-packages/airflow/models/taskinstance.py", line 3161, in _execute_task_with_callbacks
    result = self._execute_task(context, task_orig)
             ^^^^^^^^^^^^^^^^^^^^^^^^^^^^^^^^^^^^^^
  File "/home/airflow/.local/lib/python3.12/site-packages/airflow/models/taskinstance.py", line 3185, in _execute_task
    return _execute_task(self, context, task_orig)
           ^^^^^^^^^^^^^^^^^^^^^^^^^^^^^^^^^^^^^^^
  File "/home/airflow/.local/lib/python3.12/site-packages/airflow/models/taskinstance.py", line 768, in _execute_task
    result = _execute_callable(context=context, **execute_callable_kwargs)
             ^^^^^^^^^^^^^^^^^^^^^^^^^^^^^^^^^^^^^^^^^^^^^^^^^^^^^^^^^^^^^
  File "/home/airflow/.local/lib/python3.12/site-packages/airflow/models/taskinstance.py", line 734, in _execute_callable
    return ExecutionCallableRunner(
           ^^^^^^^^^^^^^^^^^^^^^^^^
  File "/home/airflow/.local/lib/python3.12/site-packages/airflow/utils/operator_helpers.py", line 252, in run
    return self.func(*args, **kwargs)
           ^^^^^^^^^^^^^^^^^^^^^^^^^^
  File "/home/airflow/.local/lib/python3.12/site-packages/airflow/models/baseoperator.py", line 424, in wrapper
    return func(self, *args, **kwargs)
           ^^^^^^^^^^^^^^^^^^^^^^^^^^^
  File "/home/airflow/.local/lib/python3.12/site-packages/airflow/operators/python.py", line 238, in execute
    return_value = self.execute_callable()
                   ^^^^^^^^^^^^^^^^^^^^^^^
  File "/home/airflow/.local/lib/python3.12/site-packages/airflow/operators/python.py", line 256, in execute_callable
    return runner.run(*self.op_args, **self.op_kwargs)
           ^^^^^^^^^^^^^^^^^^^^^^^^^^^^^^^^^^^^^^^^^^^
  File "/home/airflow/.local/lib/python3.12/site-packages/airflow/utils/operator_helpers.py", line 252, in run
    return self.func(*args, **kwargs)
           ^^^^^^^^^^^^^^^^^^^^^^^^^^
  File "/opt/airflow/dags/dag_generate_table_info.py", line 42, in generate_table_info
    two_weeks_ago = current_date - timedelta(weeks=3)
                    ^^^^^^^^^^^^
NameError: name 'current_date' is not defined
[2025-03-01T02:03:47.188+0000] {local_task_job_runner.py:266} INFO - Task exited with return code 1
[2025-03-01T02:03:47.211+0000] {taskinstance.py:3901} INFO - 0 downstream tasks scheduled from follow-on schedule check
[2025-03-01T02:03:47.216+0000] {local_task_job_runner.py:245} INFO - ::endgroup::
[2025-03-01T02:04:15.699+0000] {local_task_job_runner.py:123} INFO - ::group::Pre task execution logs
[2025-03-01T02:04:15.716+0000] {taskinstance.py:2614} INFO - Dependencies all met for dep_context=non-requeueable deps ti=<TaskInstance: dag_postgres_1.generate_orders_data scheduled__2025-03-01T01:50:00+00:00 [queued]>
[2025-03-01T02:04:15.723+0000] {taskinstance.py:2614} INFO - Dependencies all met for dep_context=requeueable deps ti=<TaskInstance: dag_postgres_1.generate_orders_data scheduled__2025-03-01T01:50:00+00:00 [queued]>
[2025-03-01T02:04:15.724+0000] {taskinstance.py:2867} INFO - Starting attempt 1 of 2
[2025-03-01T02:04:15.739+0000] {taskinstance.py:2890} INFO - Executing <Task(PythonOperator): generate_orders_data> on 2025-03-01 01:50:00+00:00
[2025-03-01T02:04:15.749+0000] {logging_mixin.py:190} WARNING - /home/***/.local/lib/python3.12/site-packages/***/task/task_runner/standard_task_runner.py:70 DeprecationWarning: This process (pid=55379) is multi-threaded, use of fork() may lead to deadlocks in the child.
[2025-03-01T02:04:15.749+0000] {standard_task_runner.py:104} INFO - Running: ['***', 'tasks', 'run', 'dag_postgres_1', 'generate_orders_data', 'scheduled__2025-03-01T01:50:00+00:00', '--job-id', '79', '--raw', '--subdir', 'DAGS_FOLDER/dag_generate_table_info.py', '--cfg-path', '/tmp/tmprvpos9z1']
[2025-03-01T02:04:15.750+0000] {standard_task_runner.py:72} INFO - Started process 55380 to run task
[2025-03-01T02:04:15.750+0000] {standard_task_runner.py:105} INFO - Job 79: Subtask generate_orders_data
[2025-03-01T02:04:15.790+0000] {task_command.py:467} INFO - Running <TaskInstance: dag_postgres_1.generate_orders_data scheduled__2025-03-01T01:50:00+00:00 [running]> on host e6b43e607126
[2025-03-01T02:04:15.865+0000] {taskinstance.py:3134} INFO - Exporting env vars: AIRFLOW_CTX_DAG_EMAIL='kucikm23@gmail.com' AIRFLOW_CTX_DAG_OWNER='***' AIRFLOW_CTX_DAG_ID='dag_postgres_1' AIRFLOW_CTX_TASK_ID='generate_orders_data' AIRFLOW_CTX_EXECUTION_DATE='2025-03-01T01:50:00+00:00' AIRFLOW_CTX_TRY_NUMBER='1' AIRFLOW_CTX_DAG_RUN_ID='scheduled__2025-03-01T01:50:00+00:00'
[2025-03-01T02:04:15.866+0000] {logging_mixin.py:190} INFO - Task instance is in running state
[2025-03-01T02:04:15.866+0000] {logging_mixin.py:190} INFO -  Previous state of the Task instance: queued
[2025-03-01T02:04:15.867+0000] {logging_mixin.py:190} INFO - Current task name:generate_orders_data state:running start_date:2025-03-01 02:04:15.717215+00:00
[2025-03-01T02:04:15.867+0000] {logging_mixin.py:190} INFO - Dag name:dag_postgres_1 and current dag run status:running
[2025-03-01T02:04:15.867+0000] {taskinstance.py:732} INFO - ::endgroup::
[2025-03-01T02:04:15.875+0000] {taskinstance.py:3313} ERROR - Task failed with exception
Traceback (most recent call last):
  File "/home/airflow/.local/lib/python3.12/site-packages/airflow/models/taskinstance.py", line 768, in _execute_task
    result = _execute_callable(context=context, **execute_callable_kwargs)
             ^^^^^^^^^^^^^^^^^^^^^^^^^^^^^^^^^^^^^^^^^^^^^^^^^^^^^^^^^^^^^
  File "/home/airflow/.local/lib/python3.12/site-packages/airflow/models/taskinstance.py", line 734, in _execute_callable
    return ExecutionCallableRunner(
           ^^^^^^^^^^^^^^^^^^^^^^^^
  File "/home/airflow/.local/lib/python3.12/site-packages/airflow/utils/operator_helpers.py", line 252, in run
    return self.func(*args, **kwargs)
           ^^^^^^^^^^^^^^^^^^^^^^^^^^
  File "/home/airflow/.local/lib/python3.12/site-packages/airflow/models/baseoperator.py", line 424, in wrapper
    return func(self, *args, **kwargs)
           ^^^^^^^^^^^^^^^^^^^^^^^^^^^
  File "/home/airflow/.local/lib/python3.12/site-packages/airflow/operators/python.py", line 238, in execute
    return_value = self.execute_callable()
                   ^^^^^^^^^^^^^^^^^^^^^^^
  File "/home/airflow/.local/lib/python3.12/site-packages/airflow/operators/python.py", line 256, in execute_callable
    return runner.run(*self.op_args, **self.op_kwargs)
           ^^^^^^^^^^^^^^^^^^^^^^^^^^^^^^^^^^^^^^^^^^^
  File "/home/airflow/.local/lib/python3.12/site-packages/airflow/utils/operator_helpers.py", line 252, in run
    return self.func(*args, **kwargs)
           ^^^^^^^^^^^^^^^^^^^^^^^^^^
  File "/opt/airflow/dags/dag_generate_table_info.py", line 42, in generate_table_info
    two_weeks_ago = current_date - timedelta(weeks=3)
                    ^^^^^^^^^^^^
NameError: name 'current_date' is not defined
[2025-03-01T02:04:15.892+0000] {logging_mixin.py:190} INFO - Task instance in failure state
[2025-03-01T02:04:15.892+0000] {logging_mixin.py:190} INFO - Task start:2025-03-01 02:04:15.717215+00:00 end:2025-03-01 02:04:15.891920+00:00 duration:0.174705
[2025-03-01T02:04:15.893+0000] {logging_mixin.py:190} INFO - Task:<Task(PythonOperator): generate_orders_data> dag:<DAG: dag_postgres_1> dagrun:<DagRun dag_postgres_1 @ 2025-03-01 01:50:00+00:00: scheduled__2025-03-01T01:50:00+00:00, state:running, queued_at: 2025-03-01 02:04:11.017280+00:00. externally triggered: False>
[2025-03-01T02:04:15.893+0000] {logging_mixin.py:190} INFO - Failure caused by name 'current_date' is not defined
[2025-03-01T02:04:15.893+0000] {taskinstance.py:1226} INFO - Marking task as UP_FOR_RETRY. dag_id=dag_postgres_1, task_id=generate_orders_data, run_id=scheduled__2025-03-01T01:50:00+00:00, execution_date=20250301T015000, start_date=20250301T020415, end_date=20250301T020415
[2025-03-01T02:04:15.925+0000] {taskinstance.py:341} INFO - ::group::Post task execution logs
[2025-03-01T02:04:15.925+0000] {standard_task_runner.py:124} ERROR - Failed to execute job 79 for task generate_orders_data (name 'current_date' is not defined; 55380)
Traceback (most recent call last):
  File "/home/airflow/.local/lib/python3.12/site-packages/airflow/task/task_runner/standard_task_runner.py", line 117, in _start_by_fork
    ret = args.func(args, dag=self.dag)
          ^^^^^^^^^^^^^^^^^^^^^^^^^^^^^
  File "/home/airflow/.local/lib/python3.12/site-packages/airflow/cli/cli_config.py", line 49, in command
    return func(*args, **kwargs)
           ^^^^^^^^^^^^^^^^^^^^^
  File "/home/airflow/.local/lib/python3.12/site-packages/airflow/utils/cli.py", line 116, in wrapper
    return f(*args, **kwargs)
           ^^^^^^^^^^^^^^^^^^
  File "/home/airflow/.local/lib/python3.12/site-packages/airflow/cli/commands/task_command.py", line 483, in task_run
    task_return_code = _run_task_by_selected_method(args, _dag, ti)
                       ^^^^^^^^^^^^^^^^^^^^^^^^^^^^^^^^^^^^^^^^^^^^
  File "/home/airflow/.local/lib/python3.12/site-packages/airflow/cli/commands/task_command.py", line 256, in _run_task_by_selected_method
    return _run_raw_task(args, ti)
           ^^^^^^^^^^^^^^^^^^^^^^^
  File "/home/airflow/.local/lib/python3.12/site-packages/airflow/cli/commands/task_command.py", line 341, in _run_raw_task
    return ti._run_raw_task(
           ^^^^^^^^^^^^^^^^^
  File "/home/airflow/.local/lib/python3.12/site-packages/airflow/utils/session.py", line 97, in wrapper
    return func(*args, session=session, **kwargs)
           ^^^^^^^^^^^^^^^^^^^^^^^^^^^^^^^^^^^^^^
  File "/home/airflow/.local/lib/python3.12/site-packages/airflow/models/taskinstance.py", line 3006, in _run_raw_task
    return _run_raw_task(
           ^^^^^^^^^^^^^^
  File "/home/airflow/.local/lib/python3.12/site-packages/airflow/models/taskinstance.py", line 274, in _run_raw_task
    TaskInstance._execute_task_with_callbacks(
  File "/home/airflow/.local/lib/python3.12/site-packages/airflow/models/taskinstance.py", line 3161, in _execute_task_with_callbacks
    result = self._execute_task(context, task_orig)
             ^^^^^^^^^^^^^^^^^^^^^^^^^^^^^^^^^^^^^^
  File "/home/airflow/.local/lib/python3.12/site-packages/airflow/models/taskinstance.py", line 3185, in _execute_task
    return _execute_task(self, context, task_orig)
           ^^^^^^^^^^^^^^^^^^^^^^^^^^^^^^^^^^^^^^^
  File "/home/airflow/.local/lib/python3.12/site-packages/airflow/models/taskinstance.py", line 768, in _execute_task
    result = _execute_callable(context=context, **execute_callable_kwargs)
             ^^^^^^^^^^^^^^^^^^^^^^^^^^^^^^^^^^^^^^^^^^^^^^^^^^^^^^^^^^^^^
  File "/home/airflow/.local/lib/python3.12/site-packages/airflow/models/taskinstance.py", line 734, in _execute_callable
    return ExecutionCallableRunner(
           ^^^^^^^^^^^^^^^^^^^^^^^^
  File "/home/airflow/.local/lib/python3.12/site-packages/airflow/utils/operator_helpers.py", line 252, in run
    return self.func(*args, **kwargs)
           ^^^^^^^^^^^^^^^^^^^^^^^^^^
  File "/home/airflow/.local/lib/python3.12/site-packages/airflow/models/baseoperator.py", line 424, in wrapper
    return func(self, *args, **kwargs)
           ^^^^^^^^^^^^^^^^^^^^^^^^^^^
  File "/home/airflow/.local/lib/python3.12/site-packages/airflow/operators/python.py", line 238, in execute
    return_value = self.execute_callable()
                   ^^^^^^^^^^^^^^^^^^^^^^^
  File "/home/airflow/.local/lib/python3.12/site-packages/airflow/operators/python.py", line 256, in execute_callable
    return runner.run(*self.op_args, **self.op_kwargs)
           ^^^^^^^^^^^^^^^^^^^^^^^^^^^^^^^^^^^^^^^^^^^
  File "/home/airflow/.local/lib/python3.12/site-packages/airflow/utils/operator_helpers.py", line 252, in run
    return self.func(*args, **kwargs)
           ^^^^^^^^^^^^^^^^^^^^^^^^^^
  File "/opt/airflow/dags/dag_generate_table_info.py", line 42, in generate_table_info
    two_weeks_ago = current_date - timedelta(weeks=3)
                    ^^^^^^^^^^^^
NameError: name 'current_date' is not defined
[2025-03-01T02:04:15.964+0000] {local_task_job_runner.py:266} INFO - Task exited with return code 1
[2025-03-01T02:04:15.984+0000] {taskinstance.py:3901} INFO - 0 downstream tasks scheduled from follow-on schedule check
[2025-03-01T02:04:15.990+0000] {local_task_job_runner.py:245} INFO - ::endgroup::
[2025-03-01T02:07:19.190+0000] {local_task_job_runner.py:123} INFO - ::group::Pre task execution logs
[2025-03-01T02:07:19.214+0000] {taskinstance.py:2614} INFO - Dependencies all met for dep_context=non-requeueable deps ti=<TaskInstance: dag_postgres_1.generate_orders_data scheduled__2025-03-01T01:50:00+00:00 [queued]>
[2025-03-01T02:07:19.226+0000] {taskinstance.py:2614} INFO - Dependencies all met for dep_context=requeueable deps ti=<TaskInstance: dag_postgres_1.generate_orders_data scheduled__2025-03-01T01:50:00+00:00 [queued]>
[2025-03-01T02:07:19.226+0000] {taskinstance.py:2867} INFO - Starting attempt 1 of 2
[2025-03-01T02:07:19.244+0000] {taskinstance.py:2890} INFO - Executing <Task(PythonOperator): generate_orders_data> on 2025-03-01 01:50:00+00:00
[2025-03-01T02:07:19.257+0000] {logging_mixin.py:190} WARNING - /home/***/.local/lib/python3.12/site-packages/***/task/task_runner/standard_task_runner.py:70 DeprecationWarning: This process (pid=57167) is multi-threaded, use of fork() may lead to deadlocks in the child.
[2025-03-01T02:07:19.257+0000] {standard_task_runner.py:104} INFO - Running: ['***', 'tasks', 'run', 'dag_postgres_1', 'generate_orders_data', 'scheduled__2025-03-01T01:50:00+00:00', '--job-id', '83', '--raw', '--subdir', 'DAGS_FOLDER/dag_generate_table_info.py', '--cfg-path', '/tmp/tmp50raqjsq']
[2025-03-01T02:07:19.260+0000] {standard_task_runner.py:72} INFO - Started process 57178 to run task
[2025-03-01T02:07:19.261+0000] {standard_task_runner.py:105} INFO - Job 83: Subtask generate_orders_data
[2025-03-01T02:07:19.323+0000] {task_command.py:467} INFO - Running <TaskInstance: dag_postgres_1.generate_orders_data scheduled__2025-03-01T01:50:00+00:00 [running]> on host e6b43e607126
[2025-03-01T02:07:19.396+0000] {taskinstance.py:3134} INFO - Exporting env vars: AIRFLOW_CTX_DAG_EMAIL='kucikm23@gmail.com' AIRFLOW_CTX_DAG_OWNER='***' AIRFLOW_CTX_DAG_ID='dag_postgres_1' AIRFLOW_CTX_TASK_ID='generate_orders_data' AIRFLOW_CTX_EXECUTION_DATE='2025-03-01T01:50:00+00:00' AIRFLOW_CTX_TRY_NUMBER='1' AIRFLOW_CTX_DAG_RUN_ID='scheduled__2025-03-01T01:50:00+00:00'
[2025-03-01T02:07:19.397+0000] {logging_mixin.py:190} INFO - Task instance is in running state
[2025-03-01T02:07:19.398+0000] {logging_mixin.py:190} INFO -  Previous state of the Task instance: queued
[2025-03-01T02:07:19.398+0000] {logging_mixin.py:190} INFO - Current task name:generate_orders_data state:running start_date:2025-03-01 02:07:19.215146+00:00
[2025-03-01T02:07:19.398+0000] {logging_mixin.py:190} INFO - Dag name:dag_postgres_1 and current dag run status:running
[2025-03-01T02:07:19.399+0000] {taskinstance.py:732} INFO - ::endgroup::
[2025-03-01T02:07:19.406+0000] {taskinstance.py:3313} ERROR - Task failed with exception
Traceback (most recent call last):
  File "/home/airflow/.local/lib/python3.12/site-packages/airflow/models/taskinstance.py", line 768, in _execute_task
    result = _execute_callable(context=context, **execute_callable_kwargs)
             ^^^^^^^^^^^^^^^^^^^^^^^^^^^^^^^^^^^^^^^^^^^^^^^^^^^^^^^^^^^^^
  File "/home/airflow/.local/lib/python3.12/site-packages/airflow/models/taskinstance.py", line 734, in _execute_callable
    return ExecutionCallableRunner(
           ^^^^^^^^^^^^^^^^^^^^^^^^
  File "/home/airflow/.local/lib/python3.12/site-packages/airflow/utils/operator_helpers.py", line 252, in run
    return self.func(*args, **kwargs)
           ^^^^^^^^^^^^^^^^^^^^^^^^^^
  File "/home/airflow/.local/lib/python3.12/site-packages/airflow/models/baseoperator.py", line 424, in wrapper
    return func(self, *args, **kwargs)
           ^^^^^^^^^^^^^^^^^^^^^^^^^^^
  File "/home/airflow/.local/lib/python3.12/site-packages/airflow/operators/python.py", line 238, in execute
    return_value = self.execute_callable()
                   ^^^^^^^^^^^^^^^^^^^^^^^
  File "/home/airflow/.local/lib/python3.12/site-packages/airflow/operators/python.py", line 256, in execute_callable
    return runner.run(*self.op_args, **self.op_kwargs)
           ^^^^^^^^^^^^^^^^^^^^^^^^^^^^^^^^^^^^^^^^^^^
  File "/home/airflow/.local/lib/python3.12/site-packages/airflow/utils/operator_helpers.py", line 252, in run
    return self.func(*args, **kwargs)
           ^^^^^^^^^^^^^^^^^^^^^^^^^^
  File "/opt/airflow/dags/dag_generate_table_info.py", line 42, in generate_table_info
    two_weeks_ago = current_date - timedelta(weeks=3)
                    ^^^^^^^^^^^^
NameError: name 'current_date' is not defined
[2025-03-01T02:07:19.422+0000] {logging_mixin.py:190} INFO - Task instance in failure state
[2025-03-01T02:07:19.422+0000] {logging_mixin.py:190} INFO - Task start:2025-03-01 02:07:19.215146+00:00 end:2025-03-01 02:07:19.421725+00:00 duration:0.206579
[2025-03-01T02:07:19.422+0000] {logging_mixin.py:190} INFO - Task:<Task(PythonOperator): generate_orders_data> dag:<DAG: dag_postgres_1> dagrun:<DagRun dag_postgres_1 @ 2025-03-01 01:50:00+00:00: scheduled__2025-03-01T01:50:00+00:00, state:running, queued_at: 2025-03-01 02:07:14.141760+00:00. externally triggered: False>
[2025-03-01T02:07:19.423+0000] {logging_mixin.py:190} INFO - Failure caused by name 'current_date' is not defined
[2025-03-01T02:07:19.423+0000] {taskinstance.py:1226} INFO - Marking task as UP_FOR_RETRY. dag_id=dag_postgres_1, task_id=generate_orders_data, run_id=scheduled__2025-03-01T01:50:00+00:00, execution_date=20250301T015000, start_date=20250301T020719, end_date=20250301T020719
[2025-03-01T02:07:19.449+0000] {taskinstance.py:341} INFO - ::group::Post task execution logs
[2025-03-01T02:07:19.450+0000] {standard_task_runner.py:124} ERROR - Failed to execute job 83 for task generate_orders_data (name 'current_date' is not defined; 57178)
Traceback (most recent call last):
  File "/home/airflow/.local/lib/python3.12/site-packages/airflow/task/task_runner/standard_task_runner.py", line 117, in _start_by_fork
    ret = args.func(args, dag=self.dag)
          ^^^^^^^^^^^^^^^^^^^^^^^^^^^^^
  File "/home/airflow/.local/lib/python3.12/site-packages/airflow/cli/cli_config.py", line 49, in command
    return func(*args, **kwargs)
           ^^^^^^^^^^^^^^^^^^^^^
  File "/home/airflow/.local/lib/python3.12/site-packages/airflow/utils/cli.py", line 116, in wrapper
    return f(*args, **kwargs)
           ^^^^^^^^^^^^^^^^^^
  File "/home/airflow/.local/lib/python3.12/site-packages/airflow/cli/commands/task_command.py", line 483, in task_run
    task_return_code = _run_task_by_selected_method(args, _dag, ti)
                       ^^^^^^^^^^^^^^^^^^^^^^^^^^^^^^^^^^^^^^^^^^^^
  File "/home/airflow/.local/lib/python3.12/site-packages/airflow/cli/commands/task_command.py", line 256, in _run_task_by_selected_method
    return _run_raw_task(args, ti)
           ^^^^^^^^^^^^^^^^^^^^^^^
  File "/home/airflow/.local/lib/python3.12/site-packages/airflow/cli/commands/task_command.py", line 341, in _run_raw_task
    return ti._run_raw_task(
           ^^^^^^^^^^^^^^^^^
  File "/home/airflow/.local/lib/python3.12/site-packages/airflow/utils/session.py", line 97, in wrapper
    return func(*args, session=session, **kwargs)
           ^^^^^^^^^^^^^^^^^^^^^^^^^^^^^^^^^^^^^^
  File "/home/airflow/.local/lib/python3.12/site-packages/airflow/models/taskinstance.py", line 3006, in _run_raw_task
    return _run_raw_task(
           ^^^^^^^^^^^^^^
  File "/home/airflow/.local/lib/python3.12/site-packages/airflow/models/taskinstance.py", line 274, in _run_raw_task
    TaskInstance._execute_task_with_callbacks(
  File "/home/airflow/.local/lib/python3.12/site-packages/airflow/models/taskinstance.py", line 3161, in _execute_task_with_callbacks
    result = self._execute_task(context, task_orig)
             ^^^^^^^^^^^^^^^^^^^^^^^^^^^^^^^^^^^^^^
  File "/home/airflow/.local/lib/python3.12/site-packages/airflow/models/taskinstance.py", line 3185, in _execute_task
    return _execute_task(self, context, task_orig)
           ^^^^^^^^^^^^^^^^^^^^^^^^^^^^^^^^^^^^^^^
  File "/home/airflow/.local/lib/python3.12/site-packages/airflow/models/taskinstance.py", line 768, in _execute_task
    result = _execute_callable(context=context, **execute_callable_kwargs)
             ^^^^^^^^^^^^^^^^^^^^^^^^^^^^^^^^^^^^^^^^^^^^^^^^^^^^^^^^^^^^^
  File "/home/airflow/.local/lib/python3.12/site-packages/airflow/models/taskinstance.py", line 734, in _execute_callable
    return ExecutionCallableRunner(
           ^^^^^^^^^^^^^^^^^^^^^^^^
  File "/home/airflow/.local/lib/python3.12/site-packages/airflow/utils/operator_helpers.py", line 252, in run
    return self.func(*args, **kwargs)
           ^^^^^^^^^^^^^^^^^^^^^^^^^^
  File "/home/airflow/.local/lib/python3.12/site-packages/airflow/models/baseoperator.py", line 424, in wrapper
    return func(self, *args, **kwargs)
           ^^^^^^^^^^^^^^^^^^^^^^^^^^^
  File "/home/airflow/.local/lib/python3.12/site-packages/airflow/operators/python.py", line 238, in execute
    return_value = self.execute_callable()
                   ^^^^^^^^^^^^^^^^^^^^^^^
  File "/home/airflow/.local/lib/python3.12/site-packages/airflow/operators/python.py", line 256, in execute_callable
    return runner.run(*self.op_args, **self.op_kwargs)
           ^^^^^^^^^^^^^^^^^^^^^^^^^^^^^^^^^^^^^^^^^^^
  File "/home/airflow/.local/lib/python3.12/site-packages/airflow/utils/operator_helpers.py", line 252, in run
    return self.func(*args, **kwargs)
           ^^^^^^^^^^^^^^^^^^^^^^^^^^
  File "/opt/airflow/dags/dag_generate_table_info.py", line 42, in generate_table_info
    two_weeks_ago = current_date - timedelta(weeks=3)
                    ^^^^^^^^^^^^
NameError: name 'current_date' is not defined
[2025-03-01T02:07:19.476+0000] {local_task_job_runner.py:266} INFO - Task exited with return code 1
[2025-03-01T02:07:19.496+0000] {taskinstance.py:3901} INFO - 0 downstream tasks scheduled from follow-on schedule check
[2025-03-01T02:07:19.500+0000] {local_task_job_runner.py:245} INFO - ::endgroup::
[2025-03-01T02:11:27.221+0000] {local_task_job_runner.py:123} INFO - ::group::Pre task execution logs
[2025-03-01T02:11:27.241+0000] {taskinstance.py:2614} INFO - Dependencies all met for dep_context=non-requeueable deps ti=<TaskInstance: dag_postgres_1.generate_orders_data scheduled__2025-03-01T01:50:00+00:00 [queued]>
[2025-03-01T02:11:27.251+0000] {taskinstance.py:2614} INFO - Dependencies all met for dep_context=requeueable deps ti=<TaskInstance: dag_postgres_1.generate_orders_data scheduled__2025-03-01T01:50:00+00:00 [queued]>
[2025-03-01T02:11:27.252+0000] {taskinstance.py:2867} INFO - Starting attempt 1 of 2
[2025-03-01T02:11:27.268+0000] {taskinstance.py:2890} INFO - Executing <Task(PythonOperator): generate_orders_data> on 2025-03-01 01:50:00+00:00
[2025-03-01T02:11:27.279+0000] {logging_mixin.py:190} WARNING - /home/***/.local/lib/python3.12/site-packages/***/task/task_runner/standard_task_runner.py:70 DeprecationWarning: This process (pid=59589) is multi-threaded, use of fork() may lead to deadlocks in the child.
[2025-03-01T02:11:27.279+0000] {standard_task_runner.py:104} INFO - Running: ['***', 'tasks', 'run', 'dag_postgres_1', 'generate_orders_data', 'scheduled__2025-03-01T01:50:00+00:00', '--job-id', '92', '--raw', '--subdir', 'DAGS_FOLDER/dag_generate_table_info.py', '--cfg-path', '/tmp/tmp4x03a3ty']
[2025-03-01T02:11:27.280+0000] {standard_task_runner.py:72} INFO - Started process 59590 to run task
[2025-03-01T02:11:27.280+0000] {standard_task_runner.py:105} INFO - Job 92: Subtask generate_orders_data
[2025-03-01T02:11:27.324+0000] {task_command.py:467} INFO - Running <TaskInstance: dag_postgres_1.generate_orders_data scheduled__2025-03-01T01:50:00+00:00 [running]> on host e6b43e607126
[2025-03-01T02:11:27.426+0000] {taskinstance.py:3134} INFO - Exporting env vars: AIRFLOW_CTX_DAG_EMAIL='kucikm23@gmail.com' AIRFLOW_CTX_DAG_OWNER='***' AIRFLOW_CTX_DAG_ID='dag_postgres_1' AIRFLOW_CTX_TASK_ID='generate_orders_data' AIRFLOW_CTX_EXECUTION_DATE='2025-03-01T01:50:00+00:00' AIRFLOW_CTX_TRY_NUMBER='1' AIRFLOW_CTX_DAG_RUN_ID='scheduled__2025-03-01T01:50:00+00:00'
[2025-03-01T02:11:27.427+0000] {logging_mixin.py:190} INFO - Task instance is in running state
[2025-03-01T02:11:27.428+0000] {logging_mixin.py:190} INFO -  Previous state of the Task instance: queued
[2025-03-01T02:11:27.428+0000] {logging_mixin.py:190} INFO - Current task name:generate_orders_data state:running start_date:2025-03-01 02:11:27.242512+00:00
[2025-03-01T02:11:27.429+0000] {logging_mixin.py:190} INFO - Dag name:dag_postgres_1 and current dag run status:running
[2025-03-01T02:11:27.429+0000] {taskinstance.py:732} INFO - ::endgroup::
[2025-03-01T02:11:27.443+0000] {python.py:240} INFO - Done. Returned value was:                                order_id        customer_email  ...  amount  currency
0  fe27cf20-e777-423d-a8b2-5e25de5d1cfe  user5869@example.com  ...  430.46       CDF

[1 rows x 5 columns]
[2025-03-01T02:11:27.503+0000] {taskinstance.py:341} INFO - ::group::Post task execution logs
[2025-03-01T02:11:27.503+0000] {taskinstance.py:353} INFO - Marking task as SUCCESS. dag_id=dag_postgres_1, task_id=generate_orders_data, run_id=scheduled__2025-03-01T01:50:00+00:00, execution_date=20250301T015000, start_date=20250301T021127, end_date=20250301T021127
[2025-03-01T02:11:27.536+0000] {logging_mixin.py:190} INFO - Task instance in success state
[2025-03-01T02:11:27.537+0000] {logging_mixin.py:190} INFO -  Previous state of the Task instance: running
[2025-03-01T02:11:27.538+0000] {logging_mixin.py:190} INFO - Dag name:dag_postgres_1 queued_at:2025-03-01 02:11:22.172302+00:00
[2025-03-01T02:11:27.538+0000] {logging_mixin.py:190} INFO - Task hostname:e6b43e607126 operator:PythonOperator
[2025-03-01T02:11:27.575+0000] {local_task_job_runner.py:266} INFO - Task exited with return code 0
[2025-03-01T02:11:27.599+0000] {taskinstance.py:3901} INFO - 1 downstream tasks scheduled from follow-on schedule check
[2025-03-01T02:11:27.605+0000] {local_task_job_runner.py:245} INFO - ::endgroup::
[2025-03-01T02:11:57.417+0000] {local_task_job_runner.py:123} INFO - ::group::Pre task execution logs
[2025-03-01T02:11:57.437+0000] {taskinstance.py:2614} INFO - Dependencies all met for dep_context=non-requeueable deps ti=<TaskInstance: dag_postgres_1.generate_orders_data scheduled__2025-03-01T01:50:00+00:00 [queued]>
[2025-03-01T02:11:57.446+0000] {taskinstance.py:2614} INFO - Dependencies all met for dep_context=requeueable deps ti=<TaskInstance: dag_postgres_1.generate_orders_data scheduled__2025-03-01T01:50:00+00:00 [queued]>
[2025-03-01T02:11:57.446+0000] {taskinstance.py:2867} INFO - Starting attempt 1 of 2
[2025-03-01T02:11:57.460+0000] {taskinstance.py:2890} INFO - Executing <Task(PythonOperator): generate_orders_data> on 2025-03-01 01:50:00+00:00
[2025-03-01T02:11:57.470+0000] {logging_mixin.py:190} WARNING - /home/***/.local/lib/python3.12/site-packages/***/task/task_runner/standard_task_runner.py:70 DeprecationWarning: This process (pid=59913) is multi-threaded, use of fork() may lead to deadlocks in the child.
[2025-03-01T02:11:57.470+0000] {standard_task_runner.py:104} INFO - Running: ['***', 'tasks', 'run', 'dag_postgres_1', 'generate_orders_data', 'scheduled__2025-03-01T01:50:00+00:00', '--job-id', '99', '--raw', '--subdir', 'DAGS_FOLDER/dag_generate_table_info.py', '--cfg-path', '/tmp/tmphdzz1msk']
[2025-03-01T02:11:57.471+0000] {standard_task_runner.py:72} INFO - Started process 59914 to run task
[2025-03-01T02:11:57.472+0000] {standard_task_runner.py:105} INFO - Job 99: Subtask generate_orders_data
[2025-03-01T02:11:57.512+0000] {task_command.py:467} INFO - Running <TaskInstance: dag_postgres_1.generate_orders_data scheduled__2025-03-01T01:50:00+00:00 [running]> on host e6b43e607126
[2025-03-01T02:11:57.591+0000] {taskinstance.py:3134} INFO - Exporting env vars: AIRFLOW_CTX_DAG_EMAIL='kucikm23@gmail.com' AIRFLOW_CTX_DAG_OWNER='***' AIRFLOW_CTX_DAG_ID='dag_postgres_1' AIRFLOW_CTX_TASK_ID='generate_orders_data' AIRFLOW_CTX_EXECUTION_DATE='2025-03-01T01:50:00+00:00' AIRFLOW_CTX_TRY_NUMBER='1' AIRFLOW_CTX_DAG_RUN_ID='scheduled__2025-03-01T01:50:00+00:00'
[2025-03-01T02:11:57.593+0000] {logging_mixin.py:190} INFO - Task instance is in running state
[2025-03-01T02:11:57.594+0000] {logging_mixin.py:190} INFO -  Previous state of the Task instance: queued
[2025-03-01T02:11:57.594+0000] {logging_mixin.py:190} INFO - Current task name:generate_orders_data state:running start_date:2025-03-01 02:11:57.437974+00:00
[2025-03-01T02:11:57.595+0000] {logging_mixin.py:190} INFO - Dag name:dag_postgres_1 and current dag run status:running
[2025-03-01T02:11:57.595+0000] {taskinstance.py:732} INFO - ::endgroup::
[2025-03-01T02:11:57.606+0000] {python.py:240} INFO - Done. Returned value was:                                order_id        customer_email  ...  amount  currency
0  96a97d62-44ee-4655-880c-0b919499b5fa  user8220@example.com  ...  327.18       IRR

[1 rows x 5 columns]
[2025-03-01T02:11:57.654+0000] {taskinstance.py:341} INFO - ::group::Post task execution logs
[2025-03-01T02:11:57.655+0000] {taskinstance.py:353} INFO - Marking task as SUCCESS. dag_id=dag_postgres_1, task_id=generate_orders_data, run_id=scheduled__2025-03-01T01:50:00+00:00, execution_date=20250301T015000, start_date=20250301T021157, end_date=20250301T021157
[2025-03-01T02:11:57.679+0000] {logging_mixin.py:190} INFO - Task instance in success state
[2025-03-01T02:11:57.680+0000] {logging_mixin.py:190} INFO -  Previous state of the Task instance: running
[2025-03-01T02:11:57.680+0000] {logging_mixin.py:190} INFO - Dag name:dag_postgres_1 queued_at:2025-03-01 02:11:52.484916+00:00
[2025-03-01T02:11:57.680+0000] {logging_mixin.py:190} INFO - Task hostname:e6b43e607126 operator:PythonOperator
[2025-03-01T02:11:57.726+0000] {local_task_job_runner.py:266} INFO - Task exited with return code 0
[2025-03-01T02:11:57.745+0000] {taskinstance.py:3901} INFO - 1 downstream tasks scheduled from follow-on schedule check
[2025-03-01T02:11:57.749+0000] {local_task_job_runner.py:245} INFO - ::endgroup::
