[2025-03-01T02:18:52.632+0000] {local_task_job_runner.py:123} INFO - ::group::Pre task execution logs
[2025-03-01T02:18:52.653+0000] {taskinstance.py:2614} INFO - Dependencies all met for dep_context=non-requeueable deps ti=<TaskInstance: dag_postgres_1.generate_orders_data manual__2025-03-01T02:18:47.008307+00:00 [queued]>
[2025-03-01T02:18:52.664+0000] {taskinstance.py:2614} INFO - Dependencies all met for dep_context=requeueable deps ti=<TaskInstance: dag_postgres_1.generate_orders_data manual__2025-03-01T02:18:47.008307+00:00 [queued]>
[2025-03-01T02:18:52.664+0000] {taskinstance.py:2867} INFO - Starting attempt 1 of 2
[2025-03-01T02:18:52.681+0000] {taskinstance.py:2890} INFO - Executing <Task(PythonOperator): generate_orders_data> on 2025-03-01 02:18:47.008307+00:00
[2025-03-01T02:18:52.695+0000] {logging_mixin.py:190} WARNING - /home/***/.local/lib/python3.12/site-packages/***/task/task_runner/standard_task_runner.py:70 DeprecationWarning: This process (pid=63878) is multi-threaded, use of fork() may lead to deadlocks in the child.
[2025-03-01T02:18:52.695+0000] {standard_task_runner.py:104} INFO - Running: ['***', 'tasks', 'run', 'dag_postgres_1', 'generate_orders_data', 'manual__2025-03-01T02:18:47.008307+00:00', '--job-id', '111', '--raw', '--subdir', 'DAGS_FOLDER/dag_generate_table_info.py', '--cfg-path', '/tmp/tmp1r7f22xt']
[2025-03-01T02:18:52.697+0000] {standard_task_runner.py:72} INFO - Started process 63887 to run task
[2025-03-01T02:18:52.697+0000] {standard_task_runner.py:105} INFO - Job 111: Subtask generate_orders_data
[2025-03-01T02:18:52.743+0000] {task_command.py:467} INFO - Running <TaskInstance: dag_postgres_1.generate_orders_data manual__2025-03-01T02:18:47.008307+00:00 [running]> on host e6b43e607126
[2025-03-01T02:18:52.832+0000] {taskinstance.py:3134} INFO - Exporting env vars: AIRFLOW_CTX_DAG_EMAIL='kucikm23@gmail.com' AIRFLOW_CTX_DAG_OWNER='***' AIRFLOW_CTX_DAG_ID='dag_postgres_1' AIRFLOW_CTX_TASK_ID='generate_orders_data' AIRFLOW_CTX_EXECUTION_DATE='2025-03-01T02:18:47.008307+00:00' AIRFLOW_CTX_TRY_NUMBER='1' AIRFLOW_CTX_DAG_RUN_ID='manual__2025-03-01T02:18:47.008307+00:00'
[2025-03-01T02:18:52.834+0000] {logging_mixin.py:190} INFO - Task instance is in running state
[2025-03-01T02:18:52.835+0000] {logging_mixin.py:190} INFO -  Previous state of the Task instance: queued
[2025-03-01T02:18:52.835+0000] {logging_mixin.py:190} INFO - Current task name:generate_orders_data state:running start_date:2025-03-01 02:18:52.653685+00:00
[2025-03-01T02:18:52.836+0000] {logging_mixin.py:190} INFO - Dag name:dag_postgres_1 and current dag run status:running
[2025-03-01T02:18:52.836+0000] {taskinstance.py:732} INFO - ::endgroup::
[2025-03-01T02:18:52.850+0000] {taskinstance.py:3313} ERROR - Task failed with exception
Traceback (most recent call last):
  File "/home/airflow/.local/lib/python3.12/site-packages/airflow/models/taskinstance.py", line 768, in _execute_task
    result = _execute_callable(context=context, **execute_callable_kwargs)
             ^^^^^^^^^^^^^^^^^^^^^^^^^^^^^^^^^^^^^^^^^^^^^^^^^^^^^^^^^^^^^
  File "/home/airflow/.local/lib/python3.12/site-packages/airflow/models/taskinstance.py", line 734, in _execute_callable
    return ExecutionCallableRunner(
           ^^^^^^^^^^^^^^^^^^^^^^^^
  File "/home/airflow/.local/lib/python3.12/site-packages/airflow/utils/operator_helpers.py", line 252, in run
    return self.func(*args, **kwargs)
           ^^^^^^^^^^^^^^^^^^^^^^^^^^
  File "/home/airflow/.local/lib/python3.12/site-packages/airflow/models/baseoperator.py", line 424, in wrapper
    return func(self, *args, **kwargs)
           ^^^^^^^^^^^^^^^^^^^^^^^^^^^
  File "/home/airflow/.local/lib/python3.12/site-packages/airflow/operators/python.py", line 238, in execute
    return_value = self.execute_callable()
                   ^^^^^^^^^^^^^^^^^^^^^^^
  File "/home/airflow/.local/lib/python3.12/site-packages/airflow/operators/python.py", line 256, in execute_callable
    return runner.run(*self.op_args, **self.op_kwargs)
           ^^^^^^^^^^^^^^^^^^^^^^^^^^^^^^^^^^^^^^^^^^^
  File "/home/airflow/.local/lib/python3.12/site-packages/airflow/utils/operator_helpers.py", line 252, in run
    return self.func(*args, **kwargs)
           ^^^^^^^^^^^^^^^^^^^^^^^^^^
  File "/opt/airflow/dags/dag_generate_table_info.py", line 60, in generate_table_info
    df = df.append({'order_id': order_id, 'customer_email': customer_email,
         ^^^^^^^^^
  File "/home/airflow/.local/lib/python3.12/site-packages/pandas/core/generic.py", line 6204, in __getattr__
    return object.__getattribute__(self, name)
           ^^^^^^^^^^^^^^^^^^^^^^^^^^^^^^^^^^^
AttributeError: 'DataFrame' object has no attribute 'append'. Did you mean: '_append'?
[2025-03-01T02:18:52.878+0000] {logging_mixin.py:190} INFO - Task instance in failure state
[2025-03-01T02:18:52.879+0000] {logging_mixin.py:190} INFO - Task start:2025-03-01 02:18:52.653685+00:00 end:2025-03-01 02:18:52.877903+00:00 duration:0.224218
[2025-03-01T02:18:52.879+0000] {logging_mixin.py:190} INFO - Task:<Task(PythonOperator): generate_orders_data> dag:<DAG: dag_postgres_1> dagrun:<DagRun dag_postgres_1 @ 2025-03-01 02:18:47.008307+00:00: manual__2025-03-01T02:18:47.008307+00:00, state:running, queued_at: 2025-03-01 02:18:47.027417+00:00. externally triggered: True>
[2025-03-01T02:18:52.879+0000] {logging_mixin.py:190} INFO - Failure caused by 'DataFrame' object has no attribute 'append'
[2025-03-01T02:18:52.880+0000] {taskinstance.py:1226} INFO - Marking task as UP_FOR_RETRY. dag_id=dag_postgres_1, task_id=generate_orders_data, run_id=manual__2025-03-01T02:18:47.008307+00:00, execution_date=20250301T021847, start_date=20250301T021852, end_date=20250301T021852
[2025-03-01T02:18:52.920+0000] {taskinstance.py:341} INFO - ::group::Post task execution logs
[2025-03-01T02:18:52.921+0000] {standard_task_runner.py:124} ERROR - Failed to execute job 111 for task generate_orders_data ('DataFrame' object has no attribute 'append'; 63887)
Traceback (most recent call last):
  File "/home/airflow/.local/lib/python3.12/site-packages/airflow/task/task_runner/standard_task_runner.py", line 117, in _start_by_fork
    ret = args.func(args, dag=self.dag)
          ^^^^^^^^^^^^^^^^^^^^^^^^^^^^^
  File "/home/airflow/.local/lib/python3.12/site-packages/airflow/cli/cli_config.py", line 49, in command
    return func(*args, **kwargs)
           ^^^^^^^^^^^^^^^^^^^^^
  File "/home/airflow/.local/lib/python3.12/site-packages/airflow/utils/cli.py", line 116, in wrapper
    return f(*args, **kwargs)
           ^^^^^^^^^^^^^^^^^^
  File "/home/airflow/.local/lib/python3.12/site-packages/airflow/cli/commands/task_command.py", line 483, in task_run
    task_return_code = _run_task_by_selected_method(args, _dag, ti)
                       ^^^^^^^^^^^^^^^^^^^^^^^^^^^^^^^^^^^^^^^^^^^^
  File "/home/airflow/.local/lib/python3.12/site-packages/airflow/cli/commands/task_command.py", line 256, in _run_task_by_selected_method
    return _run_raw_task(args, ti)
           ^^^^^^^^^^^^^^^^^^^^^^^
  File "/home/airflow/.local/lib/python3.12/site-packages/airflow/cli/commands/task_command.py", line 341, in _run_raw_task
    return ti._run_raw_task(
           ^^^^^^^^^^^^^^^^^
  File "/home/airflow/.local/lib/python3.12/site-packages/airflow/utils/session.py", line 97, in wrapper
    return func(*args, session=session, **kwargs)
           ^^^^^^^^^^^^^^^^^^^^^^^^^^^^^^^^^^^^^^
  File "/home/airflow/.local/lib/python3.12/site-packages/airflow/models/taskinstance.py", line 3006, in _run_raw_task
    return _run_raw_task(
           ^^^^^^^^^^^^^^
  File "/home/airflow/.local/lib/python3.12/site-packages/airflow/models/taskinstance.py", line 274, in _run_raw_task
    TaskInstance._execute_task_with_callbacks(
  File "/home/airflow/.local/lib/python3.12/site-packages/airflow/models/taskinstance.py", line 3161, in _execute_task_with_callbacks
    result = self._execute_task(context, task_orig)
             ^^^^^^^^^^^^^^^^^^^^^^^^^^^^^^^^^^^^^^
  File "/home/airflow/.local/lib/python3.12/site-packages/airflow/models/taskinstance.py", line 3185, in _execute_task
    return _execute_task(self, context, task_orig)
           ^^^^^^^^^^^^^^^^^^^^^^^^^^^^^^^^^^^^^^^
  File "/home/airflow/.local/lib/python3.12/site-packages/airflow/models/taskinstance.py", line 768, in _execute_task
    result = _execute_callable(context=context, **execute_callable_kwargs)
             ^^^^^^^^^^^^^^^^^^^^^^^^^^^^^^^^^^^^^^^^^^^^^^^^^^^^^^^^^^^^^
  File "/home/airflow/.local/lib/python3.12/site-packages/airflow/models/taskinstance.py", line 734, in _execute_callable
    return ExecutionCallableRunner(
           ^^^^^^^^^^^^^^^^^^^^^^^^
  File "/home/airflow/.local/lib/python3.12/site-packages/airflow/utils/operator_helpers.py", line 252, in run
    return self.func(*args, **kwargs)
           ^^^^^^^^^^^^^^^^^^^^^^^^^^
  File "/home/airflow/.local/lib/python3.12/site-packages/airflow/models/baseoperator.py", line 424, in wrapper
    return func(self, *args, **kwargs)
           ^^^^^^^^^^^^^^^^^^^^^^^^^^^
  File "/home/airflow/.local/lib/python3.12/site-packages/airflow/operators/python.py", line 238, in execute
    return_value = self.execute_callable()
                   ^^^^^^^^^^^^^^^^^^^^^^^
  File "/home/airflow/.local/lib/python3.12/site-packages/airflow/operators/python.py", line 256, in execute_callable
    return runner.run(*self.op_args, **self.op_kwargs)
           ^^^^^^^^^^^^^^^^^^^^^^^^^^^^^^^^^^^^^^^^^^^
  File "/home/airflow/.local/lib/python3.12/site-packages/airflow/utils/operator_helpers.py", line 252, in run
    return self.func(*args, **kwargs)
           ^^^^^^^^^^^^^^^^^^^^^^^^^^
  File "/opt/airflow/dags/dag_generate_table_info.py", line 60, in generate_table_info
    df = df.append({'order_id': order_id, 'customer_email': customer_email,
         ^^^^^^^^^
  File "/home/airflow/.local/lib/python3.12/site-packages/pandas/core/generic.py", line 6204, in __getattr__
    return object.__getattribute__(self, name)
           ^^^^^^^^^^^^^^^^^^^^^^^^^^^^^^^^^^^
AttributeError: 'DataFrame' object has no attribute 'append'. Did you mean: '_append'?
[2025-03-01T02:18:52.951+0000] {local_task_job_runner.py:266} INFO - Task exited with return code 1
[2025-03-01T02:18:52.976+0000] {taskinstance.py:3901} INFO - 0 downstream tasks scheduled from follow-on schedule check
[2025-03-01T02:18:52.981+0000] {local_task_job_runner.py:245} INFO - ::endgroup::
