[2025-03-01T02:00:01.550+0000] {local_task_job_runner.py:123} INFO - ::group::Pre task execution logs
[2025-03-01T02:00:01.568+0000] {taskinstance.py:2614} INFO - Dependencies all met for dep_context=non-requeueable deps ti=<TaskInstance: dag_postgres_1.insert_orders scheduled__2025-03-01T01:50:00+00:00 [queued]>
[2025-03-01T02:00:01.575+0000] {taskinstance.py:2614} INFO - Dependencies all met for dep_context=requeueable deps ti=<TaskInstance: dag_postgres_1.insert_orders scheduled__2025-03-01T01:50:00+00:00 [queued]>
[2025-03-01T02:00:01.575+0000] {taskinstance.py:2867} INFO - Starting attempt 1 of 2
[2025-03-01T02:00:01.590+0000] {taskinstance.py:2890} INFO - Executing <Task(PythonOperator): insert_orders> on 2025-03-01 01:50:00+00:00
[2025-03-01T02:00:01.600+0000] {logging_mixin.py:190} WARNING - /home/***/.local/lib/python3.12/site-packages/***/task/task_runner/standard_task_runner.py:70 DeprecationWarning: This process (pid=52900) is multi-threaded, use of fork() may lead to deadlocks in the child.
[2025-03-01T02:00:01.600+0000] {standard_task_runner.py:104} INFO - Running: ['***', 'tasks', 'run', 'dag_postgres_1', 'insert_orders', 'scheduled__2025-03-01T01:50:00+00:00', '--job-id', '65', '--raw', '--subdir', 'DAGS_FOLDER/dag_generate_table_info.py', '--cfg-path', '/tmp/tmpy3_xk7f4']
[2025-03-01T02:00:01.601+0000] {standard_task_runner.py:72} INFO - Started process 52904 to run task
[2025-03-01T02:00:01.601+0000] {standard_task_runner.py:105} INFO - Job 65: Subtask insert_orders
[2025-03-01T02:00:01.651+0000] {task_command.py:467} INFO - Running <TaskInstance: dag_postgres_1.insert_orders scheduled__2025-03-01T01:50:00+00:00 [running]> on host e6b43e607126
[2025-03-01T02:00:01.740+0000] {taskinstance.py:3134} INFO - Exporting env vars: AIRFLOW_CTX_DAG_EMAIL='kucikm23@gmail.com' AIRFLOW_CTX_DAG_OWNER='***' AIRFLOW_CTX_DAG_ID='dag_postgres_1' AIRFLOW_CTX_TASK_ID='insert_orders' AIRFLOW_CTX_EXECUTION_DATE='2025-03-01T01:50:00+00:00' AIRFLOW_CTX_TRY_NUMBER='1' AIRFLOW_CTX_DAG_RUN_ID='scheduled__2025-03-01T01:50:00+00:00'
[2025-03-01T02:00:01.741+0000] {logging_mixin.py:190} INFO - Task instance is in running state
[2025-03-01T02:00:01.742+0000] {logging_mixin.py:190} INFO -  Previous state of the Task instance: queued
[2025-03-01T02:00:01.742+0000] {logging_mixin.py:190} INFO - Current task name:insert_orders state:running start_date:2025-03-01 02:00:01.568704+00:00
[2025-03-01T02:00:01.742+0000] {logging_mixin.py:190} INFO - Dag name:dag_postgres_1 and current dag run status:running
[2025-03-01T02:00:01.743+0000] {taskinstance.py:732} INFO - ::endgroup::
[2025-03-01T02:00:01.752+0000] {taskinstance.py:3313} ERROR - Task failed with exception
Traceback (most recent call last):
  File "/home/airflow/.local/lib/python3.12/site-packages/airflow/models/taskinstance.py", line 768, in _execute_task
    result = _execute_callable(context=context, **execute_callable_kwargs)
             ^^^^^^^^^^^^^^^^^^^^^^^^^^^^^^^^^^^^^^^^^^^^^^^^^^^^^^^^^^^^^
  File "/home/airflow/.local/lib/python3.12/site-packages/airflow/models/taskinstance.py", line 734, in _execute_callable
    return ExecutionCallableRunner(
           ^^^^^^^^^^^^^^^^^^^^^^^^
  File "/home/airflow/.local/lib/python3.12/site-packages/airflow/utils/operator_helpers.py", line 252, in run
    return self.func(*args, **kwargs)
           ^^^^^^^^^^^^^^^^^^^^^^^^^^
  File "/home/airflow/.local/lib/python3.12/site-packages/airflow/models/baseoperator.py", line 424, in wrapper
    return func(self, *args, **kwargs)
           ^^^^^^^^^^^^^^^^^^^^^^^^^^^
  File "/home/airflow/.local/lib/python3.12/site-packages/airflow/operators/python.py", line 238, in execute
    return_value = self.execute_callable()
                   ^^^^^^^^^^^^^^^^^^^^^^^
  File "/home/airflow/.local/lib/python3.12/site-packages/airflow/operators/python.py", line 256, in execute_callable
    return runner.run(*self.op_args, **self.op_kwargs)
           ^^^^^^^^^^^^^^^^^^^^^^^^^^^^^^^^^^^^^^^^^^^
  File "/home/airflow/.local/lib/python3.12/site-packages/airflow/utils/operator_helpers.py", line 252, in run
    return self.func(*args, **kwargs)
           ^^^^^^^^^^^^^^^^^^^^^^^^^^
  File "/opt/airflow/dags/dag_generate_table_info.py", line 42, in generate_table_info
    two_weeks_ago = current_date - timedelta(weeks=3)
                    ^^^^^^^^^^^^
NameError: name 'current_date' is not defined
[2025-03-01T02:00:01.771+0000] {logging_mixin.py:190} INFO - Task instance in failure state
[2025-03-01T02:00:01.771+0000] {logging_mixin.py:190} INFO - Task start:2025-03-01 02:00:01.568704+00:00 end:2025-03-01 02:00:01.770733+00:00 duration:0.202029
[2025-03-01T02:00:01.772+0000] {logging_mixin.py:190} INFO - Task:<Task(PythonOperator): insert_orders> dag:<DAG: dag_postgres_1> dagrun:<DagRun dag_postgres_1 @ 2025-03-01 01:50:00+00:00: scheduled__2025-03-01T01:50:00+00:00, state:running, queued_at: 2025-03-01 02:00:00.529895+00:00. externally triggered: False>
[2025-03-01T02:00:01.772+0000] {logging_mixin.py:190} INFO - Failure caused by name 'current_date' is not defined
[2025-03-01T02:00:01.772+0000] {taskinstance.py:1226} INFO - Marking task as UP_FOR_RETRY. dag_id=dag_postgres_1, task_id=insert_orders, run_id=scheduled__2025-03-01T01:50:00+00:00, execution_date=20250301T015000, start_date=20250301T020001, end_date=20250301T020001
[2025-03-01T02:00:01.803+0000] {taskinstance.py:341} INFO - ::group::Post task execution logs
[2025-03-01T02:00:01.804+0000] {standard_task_runner.py:124} ERROR - Failed to execute job 65 for task insert_orders (name 'current_date' is not defined; 52904)
Traceback (most recent call last):
  File "/home/airflow/.local/lib/python3.12/site-packages/airflow/task/task_runner/standard_task_runner.py", line 117, in _start_by_fork
    ret = args.func(args, dag=self.dag)
          ^^^^^^^^^^^^^^^^^^^^^^^^^^^^^
  File "/home/airflow/.local/lib/python3.12/site-packages/airflow/cli/cli_config.py", line 49, in command
    return func(*args, **kwargs)
           ^^^^^^^^^^^^^^^^^^^^^
  File "/home/airflow/.local/lib/python3.12/site-packages/airflow/utils/cli.py", line 116, in wrapper
    return f(*args, **kwargs)
           ^^^^^^^^^^^^^^^^^^
  File "/home/airflow/.local/lib/python3.12/site-packages/airflow/cli/commands/task_command.py", line 483, in task_run
    task_return_code = _run_task_by_selected_method(args, _dag, ti)
                       ^^^^^^^^^^^^^^^^^^^^^^^^^^^^^^^^^^^^^^^^^^^^
  File "/home/airflow/.local/lib/python3.12/site-packages/airflow/cli/commands/task_command.py", line 256, in _run_task_by_selected_method
    return _run_raw_task(args, ti)
           ^^^^^^^^^^^^^^^^^^^^^^^
  File "/home/airflow/.local/lib/python3.12/site-packages/airflow/cli/commands/task_command.py", line 341, in _run_raw_task
    return ti._run_raw_task(
           ^^^^^^^^^^^^^^^^^
  File "/home/airflow/.local/lib/python3.12/site-packages/airflow/utils/session.py", line 97, in wrapper
    return func(*args, session=session, **kwargs)
           ^^^^^^^^^^^^^^^^^^^^^^^^^^^^^^^^^^^^^^
  File "/home/airflow/.local/lib/python3.12/site-packages/airflow/models/taskinstance.py", line 3006, in _run_raw_task
    return _run_raw_task(
           ^^^^^^^^^^^^^^
  File "/home/airflow/.local/lib/python3.12/site-packages/airflow/models/taskinstance.py", line 274, in _run_raw_task
    TaskInstance._execute_task_with_callbacks(
  File "/home/airflow/.local/lib/python3.12/site-packages/airflow/models/taskinstance.py", line 3161, in _execute_task_with_callbacks
    result = self._execute_task(context, task_orig)
             ^^^^^^^^^^^^^^^^^^^^^^^^^^^^^^^^^^^^^^
  File "/home/airflow/.local/lib/python3.12/site-packages/airflow/models/taskinstance.py", line 3185, in _execute_task
    return _execute_task(self, context, task_orig)
           ^^^^^^^^^^^^^^^^^^^^^^^^^^^^^^^^^^^^^^^
  File "/home/airflow/.local/lib/python3.12/site-packages/airflow/models/taskinstance.py", line 768, in _execute_task
    result = _execute_callable(context=context, **execute_callable_kwargs)
             ^^^^^^^^^^^^^^^^^^^^^^^^^^^^^^^^^^^^^^^^^^^^^^^^^^^^^^^^^^^^^
  File "/home/airflow/.local/lib/python3.12/site-packages/airflow/models/taskinstance.py", line 734, in _execute_callable
    return ExecutionCallableRunner(
           ^^^^^^^^^^^^^^^^^^^^^^^^
  File "/home/airflow/.local/lib/python3.12/site-packages/airflow/utils/operator_helpers.py", line 252, in run
    return self.func(*args, **kwargs)
           ^^^^^^^^^^^^^^^^^^^^^^^^^^
  File "/home/airflow/.local/lib/python3.12/site-packages/airflow/models/baseoperator.py", line 424, in wrapper
    return func(self, *args, **kwargs)
           ^^^^^^^^^^^^^^^^^^^^^^^^^^^
  File "/home/airflow/.local/lib/python3.12/site-packages/airflow/operators/python.py", line 238, in execute
    return_value = self.execute_callable()
                   ^^^^^^^^^^^^^^^^^^^^^^^
  File "/home/airflow/.local/lib/python3.12/site-packages/airflow/operators/python.py", line 256, in execute_callable
    return runner.run(*self.op_args, **self.op_kwargs)
           ^^^^^^^^^^^^^^^^^^^^^^^^^^^^^^^^^^^^^^^^^^^
  File "/home/airflow/.local/lib/python3.12/site-packages/airflow/utils/operator_helpers.py", line 252, in run
    return self.func(*args, **kwargs)
           ^^^^^^^^^^^^^^^^^^^^^^^^^^
  File "/opt/airflow/dags/dag_generate_table_info.py", line 42, in generate_table_info
    two_weeks_ago = current_date - timedelta(weeks=3)
                    ^^^^^^^^^^^^
NameError: name 'current_date' is not defined
[2025-03-01T02:00:01.856+0000] {local_task_job_runner.py:266} INFO - Task exited with return code 1
[2025-03-01T02:00:01.875+0000] {taskinstance.py:3901} INFO - 0 downstream tasks scheduled from follow-on schedule check
[2025-03-01T02:00:01.879+0000] {local_task_job_runner.py:245} INFO - ::endgroup::
[2025-03-01T02:03:42.076+0000] {local_task_job_runner.py:123} INFO - ::group::Pre task execution logs
[2025-03-01T02:03:42.094+0000] {taskinstance.py:2614} INFO - Dependencies all met for dep_context=non-requeueable deps ti=<TaskInstance: dag_postgres_1.insert_orders scheduled__2025-03-01T01:50:00+00:00 [queued]>
[2025-03-01T02:03:42.103+0000] {taskinstance.py:2614} INFO - Dependencies all met for dep_context=requeueable deps ti=<TaskInstance: dag_postgres_1.insert_orders scheduled__2025-03-01T01:50:00+00:00 [queued]>
[2025-03-01T02:03:42.104+0000] {taskinstance.py:2867} INFO - Starting attempt 1 of 2
[2025-03-01T02:03:42.124+0000] {taskinstance.py:2890} INFO - Executing <Task(PythonOperator): insert_orders> on 2025-03-01 01:50:00+00:00
[2025-03-01T02:03:42.141+0000] {logging_mixin.py:190} WARNING - /home/***/.local/lib/python3.12/site-packages/***/task/task_runner/standard_task_runner.py:70 DeprecationWarning: This process (pid=55028) is multi-threaded, use of fork() may lead to deadlocks in the child.
[2025-03-01T02:03:42.142+0000] {standard_task_runner.py:72} INFO - Started process 55044 to run task
[2025-03-01T02:03:42.145+0000] {standard_task_runner.py:104} INFO - Running: ['***', 'tasks', 'run', 'dag_postgres_1', 'insert_orders', 'scheduled__2025-03-01T01:50:00+00:00', '--job-id', '71', '--raw', '--subdir', 'DAGS_FOLDER/dag_generate_table_info.py', '--cfg-path', '/tmp/tmp3oujqg6b']
[2025-03-01T02:03:42.146+0000] {standard_task_runner.py:105} INFO - Job 71: Subtask insert_orders
[2025-03-01T02:03:42.545+0000] {task_command.py:467} INFO - Running <TaskInstance: dag_postgres_1.insert_orders scheduled__2025-03-01T01:50:00+00:00 [running]> on host e6b43e607126
[2025-03-01T02:03:42.748+0000] {taskinstance.py:3134} INFO - Exporting env vars: AIRFLOW_CTX_DAG_EMAIL='kucikm23@gmail.com' AIRFLOW_CTX_DAG_OWNER='***' AIRFLOW_CTX_DAG_ID='dag_postgres_1' AIRFLOW_CTX_TASK_ID='insert_orders' AIRFLOW_CTX_EXECUTION_DATE='2025-03-01T01:50:00+00:00' AIRFLOW_CTX_TRY_NUMBER='1' AIRFLOW_CTX_DAG_RUN_ID='scheduled__2025-03-01T01:50:00+00:00'
[2025-03-01T02:03:42.750+0000] {logging_mixin.py:190} INFO - Task instance is in running state
[2025-03-01T02:03:42.750+0000] {logging_mixin.py:190} INFO -  Previous state of the Task instance: queued
[2025-03-01T02:03:42.751+0000] {logging_mixin.py:190} INFO - Current task name:insert_orders state:running start_date:2025-03-01 02:03:42.095263+00:00
[2025-03-01T02:03:42.751+0000] {logging_mixin.py:190} INFO - Dag name:dag_postgres_1 and current dag run status:running
[2025-03-01T02:03:42.752+0000] {taskinstance.py:732} INFO - ::endgroup::
[2025-03-01T02:03:42.763+0000] {taskinstance.py:3313} ERROR - Task failed with exception
Traceback (most recent call last):
  File "/home/airflow/.local/lib/python3.12/site-packages/airflow/models/taskinstance.py", line 768, in _execute_task
    result = _execute_callable(context=context, **execute_callable_kwargs)
             ^^^^^^^^^^^^^^^^^^^^^^^^^^^^^^^^^^^^^^^^^^^^^^^^^^^^^^^^^^^^^
  File "/home/airflow/.local/lib/python3.12/site-packages/airflow/models/taskinstance.py", line 734, in _execute_callable
    return ExecutionCallableRunner(
           ^^^^^^^^^^^^^^^^^^^^^^^^
  File "/home/airflow/.local/lib/python3.12/site-packages/airflow/utils/operator_helpers.py", line 252, in run
    return self.func(*args, **kwargs)
           ^^^^^^^^^^^^^^^^^^^^^^^^^^
  File "/home/airflow/.local/lib/python3.12/site-packages/airflow/models/baseoperator.py", line 424, in wrapper
    return func(self, *args, **kwargs)
           ^^^^^^^^^^^^^^^^^^^^^^^^^^^
  File "/home/airflow/.local/lib/python3.12/site-packages/airflow/operators/python.py", line 238, in execute
    return_value = self.execute_callable()
                   ^^^^^^^^^^^^^^^^^^^^^^^
  File "/home/airflow/.local/lib/python3.12/site-packages/airflow/operators/python.py", line 256, in execute_callable
    return runner.run(*self.op_args, **self.op_kwargs)
           ^^^^^^^^^^^^^^^^^^^^^^^^^^^^^^^^^^^^^^^^^^^
  File "/home/airflow/.local/lib/python3.12/site-packages/airflow/utils/operator_helpers.py", line 252, in run
    return self.func(*args, **kwargs)
           ^^^^^^^^^^^^^^^^^^^^^^^^^^
  File "/opt/airflow/dags/dag_generate_table_info.py", line 42, in generate_table_info
    two_weeks_ago = current_date - timedelta(weeks=3)
                    ^^^^^^^^^^^^
NameError: name 'current_date' is not defined
[2025-03-01T02:03:42.824+0000] {logging_mixin.py:190} INFO - Task instance in failure state
[2025-03-01T02:03:42.824+0000] {logging_mixin.py:190} INFO - Task start:2025-03-01 02:03:42.095263+00:00 end:2025-03-01 02:03:42.823596+00:00 duration:0.728333
[2025-03-01T02:03:42.825+0000] {logging_mixin.py:190} INFO - Task:<Task(PythonOperator): insert_orders> dag:<DAG: dag_postgres_1> dagrun:<DagRun dag_postgres_1 @ 2025-03-01 01:50:00+00:00: scheduled__2025-03-01T01:50:00+00:00, state:running, queued_at: 2025-03-01 02:03:40.548117+00:00. externally triggered: False>
[2025-03-01T02:03:42.826+0000] {logging_mixin.py:190} INFO - Failure caused by name 'current_date' is not defined
[2025-03-01T02:03:42.826+0000] {taskinstance.py:1226} INFO - Marking task as UP_FOR_RETRY. dag_id=dag_postgres_1, task_id=insert_orders, run_id=scheduled__2025-03-01T01:50:00+00:00, execution_date=20250301T015000, start_date=20250301T020342, end_date=20250301T020342
[2025-03-01T02:03:42.865+0000] {taskinstance.py:341} INFO - ::group::Post task execution logs
[2025-03-01T02:03:42.866+0000] {standard_task_runner.py:124} ERROR - Failed to execute job 71 for task insert_orders (name 'current_date' is not defined; 55044)
Traceback (most recent call last):
  File "/home/airflow/.local/lib/python3.12/site-packages/airflow/task/task_runner/standard_task_runner.py", line 117, in _start_by_fork
    ret = args.func(args, dag=self.dag)
          ^^^^^^^^^^^^^^^^^^^^^^^^^^^^^
  File "/home/airflow/.local/lib/python3.12/site-packages/airflow/cli/cli_config.py", line 49, in command
    return func(*args, **kwargs)
           ^^^^^^^^^^^^^^^^^^^^^
  File "/home/airflow/.local/lib/python3.12/site-packages/airflow/utils/cli.py", line 116, in wrapper
    return f(*args, **kwargs)
           ^^^^^^^^^^^^^^^^^^
  File "/home/airflow/.local/lib/python3.12/site-packages/airflow/cli/commands/task_command.py", line 483, in task_run
    task_return_code = _run_task_by_selected_method(args, _dag, ti)
                       ^^^^^^^^^^^^^^^^^^^^^^^^^^^^^^^^^^^^^^^^^^^^
  File "/home/airflow/.local/lib/python3.12/site-packages/airflow/cli/commands/task_command.py", line 256, in _run_task_by_selected_method
    return _run_raw_task(args, ti)
           ^^^^^^^^^^^^^^^^^^^^^^^
  File "/home/airflow/.local/lib/python3.12/site-packages/airflow/cli/commands/task_command.py", line 341, in _run_raw_task
    return ti._run_raw_task(
           ^^^^^^^^^^^^^^^^^
  File "/home/airflow/.local/lib/python3.12/site-packages/airflow/utils/session.py", line 97, in wrapper
    return func(*args, session=session, **kwargs)
           ^^^^^^^^^^^^^^^^^^^^^^^^^^^^^^^^^^^^^^
  File "/home/airflow/.local/lib/python3.12/site-packages/airflow/models/taskinstance.py", line 3006, in _run_raw_task
    return _run_raw_task(
           ^^^^^^^^^^^^^^
  File "/home/airflow/.local/lib/python3.12/site-packages/airflow/models/taskinstance.py", line 274, in _run_raw_task
    TaskInstance._execute_task_with_callbacks(
  File "/home/airflow/.local/lib/python3.12/site-packages/airflow/models/taskinstance.py", line 3161, in _execute_task_with_callbacks
    result = self._execute_task(context, task_orig)
             ^^^^^^^^^^^^^^^^^^^^^^^^^^^^^^^^^^^^^^
  File "/home/airflow/.local/lib/python3.12/site-packages/airflow/models/taskinstance.py", line 3185, in _execute_task
    return _execute_task(self, context, task_orig)
           ^^^^^^^^^^^^^^^^^^^^^^^^^^^^^^^^^^^^^^^
  File "/home/airflow/.local/lib/python3.12/site-packages/airflow/models/taskinstance.py", line 768, in _execute_task
    result = _execute_callable(context=context, **execute_callable_kwargs)
             ^^^^^^^^^^^^^^^^^^^^^^^^^^^^^^^^^^^^^^^^^^^^^^^^^^^^^^^^^^^^^
  File "/home/airflow/.local/lib/python3.12/site-packages/airflow/models/taskinstance.py", line 734, in _execute_callable
    return ExecutionCallableRunner(
           ^^^^^^^^^^^^^^^^^^^^^^^^
  File "/home/airflow/.local/lib/python3.12/site-packages/airflow/utils/operator_helpers.py", line 252, in run
    return self.func(*args, **kwargs)
           ^^^^^^^^^^^^^^^^^^^^^^^^^^
  File "/home/airflow/.local/lib/python3.12/site-packages/airflow/models/baseoperator.py", line 424, in wrapper
    return func(self, *args, **kwargs)
           ^^^^^^^^^^^^^^^^^^^^^^^^^^^
  File "/home/airflow/.local/lib/python3.12/site-packages/airflow/operators/python.py", line 238, in execute
    return_value = self.execute_callable()
                   ^^^^^^^^^^^^^^^^^^^^^^^
  File "/home/airflow/.local/lib/python3.12/site-packages/airflow/operators/python.py", line 256, in execute_callable
    return runner.run(*self.op_args, **self.op_kwargs)
           ^^^^^^^^^^^^^^^^^^^^^^^^^^^^^^^^^^^^^^^^^^^
  File "/home/airflow/.local/lib/python3.12/site-packages/airflow/utils/operator_helpers.py", line 252, in run
    return self.func(*args, **kwargs)
           ^^^^^^^^^^^^^^^^^^^^^^^^^^
  File "/opt/airflow/dags/dag_generate_table_info.py", line 42, in generate_table_info
    two_weeks_ago = current_date - timedelta(weeks=3)
                    ^^^^^^^^^^^^
NameError: name 'current_date' is not defined
[2025-03-01T02:03:42.919+0000] {local_task_job_runner.py:266} INFO - Task exited with return code 1
[2025-03-01T02:03:42.946+0000] {taskinstance.py:3901} INFO - 0 downstream tasks scheduled from follow-on schedule check
[2025-03-01T02:03:42.951+0000] {local_task_job_runner.py:245} INFO - ::endgroup::
[2025-03-01T02:04:12.024+0000] {local_task_job_runner.py:123} INFO - ::group::Pre task execution logs
[2025-03-01T02:04:12.038+0000] {taskinstance.py:2614} INFO - Dependencies all met for dep_context=non-requeueable deps ti=<TaskInstance: dag_postgres_1.insert_orders scheduled__2025-03-01T01:50:00+00:00 [queued]>
[2025-03-01T02:04:12.045+0000] {taskinstance.py:2614} INFO - Dependencies all met for dep_context=requeueable deps ti=<TaskInstance: dag_postgres_1.insert_orders scheduled__2025-03-01T01:50:00+00:00 [queued]>
[2025-03-01T02:04:12.045+0000] {taskinstance.py:2867} INFO - Starting attempt 1 of 2
[2025-03-01T02:04:12.060+0000] {taskinstance.py:2890} INFO - Executing <Task(PythonOperator): insert_orders> on 2025-03-01 01:50:00+00:00
[2025-03-01T02:04:12.072+0000] {logging_mixin.py:190} WARNING - /home/***/.local/lib/python3.12/site-packages/***/task/task_runner/standard_task_runner.py:70 DeprecationWarning: This process (pid=55341) is multi-threaded, use of fork() may lead to deadlocks in the child.
[2025-03-01T02:04:12.072+0000] {standard_task_runner.py:104} INFO - Running: ['***', 'tasks', 'run', 'dag_postgres_1', 'insert_orders', 'scheduled__2025-03-01T01:50:00+00:00', '--job-id', '76', '--raw', '--subdir', 'DAGS_FOLDER/dag_generate_table_info.py', '--cfg-path', '/tmp/tmpr4tl6ff9']
[2025-03-01T02:04:12.073+0000] {standard_task_runner.py:72} INFO - Started process 55342 to run task
[2025-03-01T02:04:12.073+0000] {standard_task_runner.py:105} INFO - Job 76: Subtask insert_orders
[2025-03-01T02:04:12.119+0000] {task_command.py:467} INFO - Running <TaskInstance: dag_postgres_1.insert_orders scheduled__2025-03-01T01:50:00+00:00 [running]> on host e6b43e607126
[2025-03-01T02:04:12.203+0000] {taskinstance.py:3134} INFO - Exporting env vars: AIRFLOW_CTX_DAG_EMAIL='kucikm23@gmail.com' AIRFLOW_CTX_DAG_OWNER='***' AIRFLOW_CTX_DAG_ID='dag_postgres_1' AIRFLOW_CTX_TASK_ID='insert_orders' AIRFLOW_CTX_EXECUTION_DATE='2025-03-01T01:50:00+00:00' AIRFLOW_CTX_TRY_NUMBER='1' AIRFLOW_CTX_DAG_RUN_ID='scheduled__2025-03-01T01:50:00+00:00'
[2025-03-01T02:04:12.205+0000] {logging_mixin.py:190} INFO - Task instance is in running state
[2025-03-01T02:04:12.205+0000] {logging_mixin.py:190} INFO -  Previous state of the Task instance: queued
[2025-03-01T02:04:12.205+0000] {logging_mixin.py:190} INFO - Current task name:insert_orders state:running start_date:2025-03-01 02:04:12.039258+00:00
[2025-03-01T02:04:12.206+0000] {logging_mixin.py:190} INFO - Dag name:dag_postgres_1 and current dag run status:running
[2025-03-01T02:04:12.206+0000] {taskinstance.py:732} INFO - ::endgroup::
[2025-03-01T02:04:12.215+0000] {taskinstance.py:3313} ERROR - Task failed with exception
Traceback (most recent call last):
  File "/home/airflow/.local/lib/python3.12/site-packages/airflow/models/taskinstance.py", line 768, in _execute_task
    result = _execute_callable(context=context, **execute_callable_kwargs)
             ^^^^^^^^^^^^^^^^^^^^^^^^^^^^^^^^^^^^^^^^^^^^^^^^^^^^^^^^^^^^^
  File "/home/airflow/.local/lib/python3.12/site-packages/airflow/models/taskinstance.py", line 734, in _execute_callable
    return ExecutionCallableRunner(
           ^^^^^^^^^^^^^^^^^^^^^^^^
  File "/home/airflow/.local/lib/python3.12/site-packages/airflow/utils/operator_helpers.py", line 252, in run
    return self.func(*args, **kwargs)
           ^^^^^^^^^^^^^^^^^^^^^^^^^^
  File "/home/airflow/.local/lib/python3.12/site-packages/airflow/models/baseoperator.py", line 424, in wrapper
    return func(self, *args, **kwargs)
           ^^^^^^^^^^^^^^^^^^^^^^^^^^^
  File "/home/airflow/.local/lib/python3.12/site-packages/airflow/operators/python.py", line 238, in execute
    return_value = self.execute_callable()
                   ^^^^^^^^^^^^^^^^^^^^^^^
  File "/home/airflow/.local/lib/python3.12/site-packages/airflow/operators/python.py", line 256, in execute_callable
    return runner.run(*self.op_args, **self.op_kwargs)
           ^^^^^^^^^^^^^^^^^^^^^^^^^^^^^^^^^^^^^^^^^^^
  File "/home/airflow/.local/lib/python3.12/site-packages/airflow/utils/operator_helpers.py", line 252, in run
    return self.func(*args, **kwargs)
           ^^^^^^^^^^^^^^^^^^^^^^^^^^
  File "/opt/airflow/dags/dag_generate_table_info.py", line 42, in generate_table_info
    two_weeks_ago = current_date - timedelta(weeks=3)
                    ^^^^^^^^^^^^
NameError: name 'current_date' is not defined
[2025-03-01T02:04:12.233+0000] {logging_mixin.py:190} INFO - Task instance in failure state
[2025-03-01T02:04:12.234+0000] {logging_mixin.py:190} INFO - Task start:2025-03-01 02:04:12.039258+00:00 end:2025-03-01 02:04:12.233125+00:00 duration:0.193867
[2025-03-01T02:04:12.234+0000] {logging_mixin.py:190} INFO - Task:<Task(PythonOperator): insert_orders> dag:<DAG: dag_postgres_1> dagrun:<DagRun dag_postgres_1 @ 2025-03-01 01:50:00+00:00: scheduled__2025-03-01T01:50:00+00:00, state:running, queued_at: 2025-03-01 02:04:11.017280+00:00. externally triggered: False>
[2025-03-01T02:04:12.235+0000] {logging_mixin.py:190} INFO - Failure caused by name 'current_date' is not defined
[2025-03-01T02:04:12.235+0000] {taskinstance.py:1226} INFO - Marking task as UP_FOR_RETRY. dag_id=dag_postgres_1, task_id=insert_orders, run_id=scheduled__2025-03-01T01:50:00+00:00, execution_date=20250301T015000, start_date=20250301T020412, end_date=20250301T020412
[2025-03-01T02:04:12.269+0000] {taskinstance.py:341} INFO - ::group::Post task execution logs
[2025-03-01T02:04:12.270+0000] {standard_task_runner.py:124} ERROR - Failed to execute job 76 for task insert_orders (name 'current_date' is not defined; 55342)
Traceback (most recent call last):
  File "/home/airflow/.local/lib/python3.12/site-packages/airflow/task/task_runner/standard_task_runner.py", line 117, in _start_by_fork
    ret = args.func(args, dag=self.dag)
          ^^^^^^^^^^^^^^^^^^^^^^^^^^^^^
  File "/home/airflow/.local/lib/python3.12/site-packages/airflow/cli/cli_config.py", line 49, in command
    return func(*args, **kwargs)
           ^^^^^^^^^^^^^^^^^^^^^
  File "/home/airflow/.local/lib/python3.12/site-packages/airflow/utils/cli.py", line 116, in wrapper
    return f(*args, **kwargs)
           ^^^^^^^^^^^^^^^^^^
  File "/home/airflow/.local/lib/python3.12/site-packages/airflow/cli/commands/task_command.py", line 483, in task_run
    task_return_code = _run_task_by_selected_method(args, _dag, ti)
                       ^^^^^^^^^^^^^^^^^^^^^^^^^^^^^^^^^^^^^^^^^^^^
  File "/home/airflow/.local/lib/python3.12/site-packages/airflow/cli/commands/task_command.py", line 256, in _run_task_by_selected_method
    return _run_raw_task(args, ti)
           ^^^^^^^^^^^^^^^^^^^^^^^
  File "/home/airflow/.local/lib/python3.12/site-packages/airflow/cli/commands/task_command.py", line 341, in _run_raw_task
    return ti._run_raw_task(
           ^^^^^^^^^^^^^^^^^
  File "/home/airflow/.local/lib/python3.12/site-packages/airflow/utils/session.py", line 97, in wrapper
    return func(*args, session=session, **kwargs)
           ^^^^^^^^^^^^^^^^^^^^^^^^^^^^^^^^^^^^^^
  File "/home/airflow/.local/lib/python3.12/site-packages/airflow/models/taskinstance.py", line 3006, in _run_raw_task
    return _run_raw_task(
           ^^^^^^^^^^^^^^
  File "/home/airflow/.local/lib/python3.12/site-packages/airflow/models/taskinstance.py", line 274, in _run_raw_task
    TaskInstance._execute_task_with_callbacks(
  File "/home/airflow/.local/lib/python3.12/site-packages/airflow/models/taskinstance.py", line 3161, in _execute_task_with_callbacks
    result = self._execute_task(context, task_orig)
             ^^^^^^^^^^^^^^^^^^^^^^^^^^^^^^^^^^^^^^
  File "/home/airflow/.local/lib/python3.12/site-packages/airflow/models/taskinstance.py", line 3185, in _execute_task
    return _execute_task(self, context, task_orig)
           ^^^^^^^^^^^^^^^^^^^^^^^^^^^^^^^^^^^^^^^
  File "/home/airflow/.local/lib/python3.12/site-packages/airflow/models/taskinstance.py", line 768, in _execute_task
    result = _execute_callable(context=context, **execute_callable_kwargs)
             ^^^^^^^^^^^^^^^^^^^^^^^^^^^^^^^^^^^^^^^^^^^^^^^^^^^^^^^^^^^^^
  File "/home/airflow/.local/lib/python3.12/site-packages/airflow/models/taskinstance.py", line 734, in _execute_callable
    return ExecutionCallableRunner(
           ^^^^^^^^^^^^^^^^^^^^^^^^
  File "/home/airflow/.local/lib/python3.12/site-packages/airflow/utils/operator_helpers.py", line 252, in run
    return self.func(*args, **kwargs)
           ^^^^^^^^^^^^^^^^^^^^^^^^^^
  File "/home/airflow/.local/lib/python3.12/site-packages/airflow/models/baseoperator.py", line 424, in wrapper
    return func(self, *args, **kwargs)
           ^^^^^^^^^^^^^^^^^^^^^^^^^^^
  File "/home/airflow/.local/lib/python3.12/site-packages/airflow/operators/python.py", line 238, in execute
    return_value = self.execute_callable()
                   ^^^^^^^^^^^^^^^^^^^^^^^
  File "/home/airflow/.local/lib/python3.12/site-packages/airflow/operators/python.py", line 256, in execute_callable
    return runner.run(*self.op_args, **self.op_kwargs)
           ^^^^^^^^^^^^^^^^^^^^^^^^^^^^^^^^^^^^^^^^^^^
  File "/home/airflow/.local/lib/python3.12/site-packages/airflow/utils/operator_helpers.py", line 252, in run
    return self.func(*args, **kwargs)
           ^^^^^^^^^^^^^^^^^^^^^^^^^^
  File "/opt/airflow/dags/dag_generate_table_info.py", line 42, in generate_table_info
    two_weeks_ago = current_date - timedelta(weeks=3)
                    ^^^^^^^^^^^^
NameError: name 'current_date' is not defined
[2025-03-01T02:04:12.287+0000] {local_task_job_runner.py:266} INFO - Task exited with return code 1
[2025-03-01T02:04:12.311+0000] {taskinstance.py:3901} INFO - 0 downstream tasks scheduled from follow-on schedule check
[2025-03-01T02:04:12.316+0000] {local_task_job_runner.py:245} INFO - ::endgroup::
[2025-03-01T02:07:15.390+0000] {local_task_job_runner.py:123} INFO - ::group::Pre task execution logs
[2025-03-01T02:07:15.404+0000] {taskinstance.py:2614} INFO - Dependencies all met for dep_context=non-requeueable deps ti=<TaskInstance: dag_postgres_1.insert_orders scheduled__2025-03-01T01:50:00+00:00 [queued]>
[2025-03-01T02:07:15.411+0000] {taskinstance.py:2614} INFO - Dependencies all met for dep_context=requeueable deps ti=<TaskInstance: dag_postgres_1.insert_orders scheduled__2025-03-01T01:50:00+00:00 [queued]>
[2025-03-01T02:07:15.411+0000] {taskinstance.py:2867} INFO - Starting attempt 1 of 2
[2025-03-01T02:07:15.424+0000] {taskinstance.py:2890} INFO - Executing <Task(PythonOperator): insert_orders> on 2025-03-01 01:50:00+00:00
[2025-03-01T02:07:15.435+0000] {logging_mixin.py:190} WARNING - /home/***/.local/lib/python3.12/site-packages/***/task/task_runner/standard_task_runner.py:70 DeprecationWarning: This process (pid=57129) is multi-threaded, use of fork() may lead to deadlocks in the child.
[2025-03-01T02:07:15.435+0000] {standard_task_runner.py:104} INFO - Running: ['***', 'tasks', 'run', 'dag_postgres_1', 'insert_orders', 'scheduled__2025-03-01T01:50:00+00:00', '--job-id', '81', '--raw', '--subdir', 'DAGS_FOLDER/dag_generate_table_info.py', '--cfg-path', '/tmp/tmp4v48gt1p']
[2025-03-01T02:07:15.437+0000] {standard_task_runner.py:72} INFO - Started process 57132 to run task
[2025-03-01T02:07:15.437+0000] {standard_task_runner.py:105} INFO - Job 81: Subtask insert_orders
[2025-03-01T02:07:15.499+0000] {task_command.py:467} INFO - Running <TaskInstance: dag_postgres_1.insert_orders scheduled__2025-03-01T01:50:00+00:00 [running]> on host e6b43e607126
[2025-03-01T02:07:15.604+0000] {taskinstance.py:3134} INFO - Exporting env vars: AIRFLOW_CTX_DAG_EMAIL='kucikm23@gmail.com' AIRFLOW_CTX_DAG_OWNER='***' AIRFLOW_CTX_DAG_ID='dag_postgres_1' AIRFLOW_CTX_TASK_ID='insert_orders' AIRFLOW_CTX_EXECUTION_DATE='2025-03-01T01:50:00+00:00' AIRFLOW_CTX_TRY_NUMBER='1' AIRFLOW_CTX_DAG_RUN_ID='scheduled__2025-03-01T01:50:00+00:00'
[2025-03-01T02:07:15.606+0000] {logging_mixin.py:190} INFO - Task instance is in running state
[2025-03-01T02:07:15.606+0000] {logging_mixin.py:190} INFO -  Previous state of the Task instance: queued
[2025-03-01T02:07:15.607+0000] {logging_mixin.py:190} INFO - Current task name:insert_orders state:running start_date:2025-03-01 02:07:15.404531+00:00
[2025-03-01T02:07:15.607+0000] {logging_mixin.py:190} INFO - Dag name:dag_postgres_1 and current dag run status:running
[2025-03-01T02:07:15.608+0000] {taskinstance.py:732} INFO - ::endgroup::
[2025-03-01T02:07:15.617+0000] {taskinstance.py:3313} ERROR - Task failed with exception
Traceback (most recent call last):
  File "/home/airflow/.local/lib/python3.12/site-packages/airflow/models/taskinstance.py", line 768, in _execute_task
    result = _execute_callable(context=context, **execute_callable_kwargs)
             ^^^^^^^^^^^^^^^^^^^^^^^^^^^^^^^^^^^^^^^^^^^^^^^^^^^^^^^^^^^^^
  File "/home/airflow/.local/lib/python3.12/site-packages/airflow/models/taskinstance.py", line 734, in _execute_callable
    return ExecutionCallableRunner(
           ^^^^^^^^^^^^^^^^^^^^^^^^
  File "/home/airflow/.local/lib/python3.12/site-packages/airflow/utils/operator_helpers.py", line 252, in run
    return self.func(*args, **kwargs)
           ^^^^^^^^^^^^^^^^^^^^^^^^^^
  File "/home/airflow/.local/lib/python3.12/site-packages/airflow/models/baseoperator.py", line 424, in wrapper
    return func(self, *args, **kwargs)
           ^^^^^^^^^^^^^^^^^^^^^^^^^^^
  File "/home/airflow/.local/lib/python3.12/site-packages/airflow/operators/python.py", line 238, in execute
    return_value = self.execute_callable()
                   ^^^^^^^^^^^^^^^^^^^^^^^
  File "/home/airflow/.local/lib/python3.12/site-packages/airflow/operators/python.py", line 256, in execute_callable
    return runner.run(*self.op_args, **self.op_kwargs)
           ^^^^^^^^^^^^^^^^^^^^^^^^^^^^^^^^^^^^^^^^^^^
  File "/home/airflow/.local/lib/python3.12/site-packages/airflow/utils/operator_helpers.py", line 252, in run
    return self.func(*args, **kwargs)
           ^^^^^^^^^^^^^^^^^^^^^^^^^^
  File "/opt/airflow/dags/dag_generate_table_info.py", line 42, in generate_table_info
    two_weeks_ago = current_date - timedelta(weeks=3)
                    ^^^^^^^^^^^^
NameError: name 'current_date' is not defined
[2025-03-01T02:07:15.639+0000] {logging_mixin.py:190} INFO - Task instance in failure state
[2025-03-01T02:07:15.640+0000] {logging_mixin.py:190} INFO - Task start:2025-03-01 02:07:15.404531+00:00 end:2025-03-01 02:07:15.638445+00:00 duration:0.233914
[2025-03-01T02:07:15.640+0000] {logging_mixin.py:190} INFO - Task:<Task(PythonOperator): insert_orders> dag:<DAG: dag_postgres_1> dagrun:<DagRun dag_postgres_1 @ 2025-03-01 01:50:00+00:00: scheduled__2025-03-01T01:50:00+00:00, state:running, queued_at: 2025-03-01 02:07:14.141760+00:00. externally triggered: False>
[2025-03-01T02:07:15.640+0000] {logging_mixin.py:190} INFO - Failure caused by name 'current_date' is not defined
[2025-03-01T02:07:15.641+0000] {taskinstance.py:1226} INFO - Marking task as UP_FOR_RETRY. dag_id=dag_postgres_1, task_id=insert_orders, run_id=scheduled__2025-03-01T01:50:00+00:00, execution_date=20250301T015000, start_date=20250301T020715, end_date=20250301T020715
[2025-03-01T02:07:15.691+0000] {taskinstance.py:341} INFO - ::group::Post task execution logs
[2025-03-01T02:07:15.693+0000] {standard_task_runner.py:124} ERROR - Failed to execute job 81 for task insert_orders (name 'current_date' is not defined; 57132)
Traceback (most recent call last):
  File "/home/airflow/.local/lib/python3.12/site-packages/airflow/task/task_runner/standard_task_runner.py", line 117, in _start_by_fork
    ret = args.func(args, dag=self.dag)
          ^^^^^^^^^^^^^^^^^^^^^^^^^^^^^
  File "/home/airflow/.local/lib/python3.12/site-packages/airflow/cli/cli_config.py", line 49, in command
    return func(*args, **kwargs)
           ^^^^^^^^^^^^^^^^^^^^^
  File "/home/airflow/.local/lib/python3.12/site-packages/airflow/utils/cli.py", line 116, in wrapper
    return f(*args, **kwargs)
           ^^^^^^^^^^^^^^^^^^
  File "/home/airflow/.local/lib/python3.12/site-packages/airflow/cli/commands/task_command.py", line 483, in task_run
    task_return_code = _run_task_by_selected_method(args, _dag, ti)
                       ^^^^^^^^^^^^^^^^^^^^^^^^^^^^^^^^^^^^^^^^^^^^
  File "/home/airflow/.local/lib/python3.12/site-packages/airflow/cli/commands/task_command.py", line 256, in _run_task_by_selected_method
    return _run_raw_task(args, ti)
           ^^^^^^^^^^^^^^^^^^^^^^^
  File "/home/airflow/.local/lib/python3.12/site-packages/airflow/cli/commands/task_command.py", line 341, in _run_raw_task
    return ti._run_raw_task(
           ^^^^^^^^^^^^^^^^^
  File "/home/airflow/.local/lib/python3.12/site-packages/airflow/utils/session.py", line 97, in wrapper
    return func(*args, session=session, **kwargs)
           ^^^^^^^^^^^^^^^^^^^^^^^^^^^^^^^^^^^^^^
  File "/home/airflow/.local/lib/python3.12/site-packages/airflow/models/taskinstance.py", line 3006, in _run_raw_task
    return _run_raw_task(
           ^^^^^^^^^^^^^^
  File "/home/airflow/.local/lib/python3.12/site-packages/airflow/models/taskinstance.py", line 274, in _run_raw_task
    TaskInstance._execute_task_with_callbacks(
  File "/home/airflow/.local/lib/python3.12/site-packages/airflow/models/taskinstance.py", line 3161, in _execute_task_with_callbacks
    result = self._execute_task(context, task_orig)
             ^^^^^^^^^^^^^^^^^^^^^^^^^^^^^^^^^^^^^^
  File "/home/airflow/.local/lib/python3.12/site-packages/airflow/models/taskinstance.py", line 3185, in _execute_task
    return _execute_task(self, context, task_orig)
           ^^^^^^^^^^^^^^^^^^^^^^^^^^^^^^^^^^^^^^^
  File "/home/airflow/.local/lib/python3.12/site-packages/airflow/models/taskinstance.py", line 768, in _execute_task
    result = _execute_callable(context=context, **execute_callable_kwargs)
             ^^^^^^^^^^^^^^^^^^^^^^^^^^^^^^^^^^^^^^^^^^^^^^^^^^^^^^^^^^^^^
  File "/home/airflow/.local/lib/python3.12/site-packages/airflow/models/taskinstance.py", line 734, in _execute_callable
    return ExecutionCallableRunner(
           ^^^^^^^^^^^^^^^^^^^^^^^^
  File "/home/airflow/.local/lib/python3.12/site-packages/airflow/utils/operator_helpers.py", line 252, in run
    return self.func(*args, **kwargs)
           ^^^^^^^^^^^^^^^^^^^^^^^^^^
  File "/home/airflow/.local/lib/python3.12/site-packages/airflow/models/baseoperator.py", line 424, in wrapper
    return func(self, *args, **kwargs)
           ^^^^^^^^^^^^^^^^^^^^^^^^^^^
  File "/home/airflow/.local/lib/python3.12/site-packages/airflow/operators/python.py", line 238, in execute
    return_value = self.execute_callable()
                   ^^^^^^^^^^^^^^^^^^^^^^^
  File "/home/airflow/.local/lib/python3.12/site-packages/airflow/operators/python.py", line 256, in execute_callable
    return runner.run(*self.op_args, **self.op_kwargs)
           ^^^^^^^^^^^^^^^^^^^^^^^^^^^^^^^^^^^^^^^^^^^
  File "/home/airflow/.local/lib/python3.12/site-packages/airflow/utils/operator_helpers.py", line 252, in run
    return self.func(*args, **kwargs)
           ^^^^^^^^^^^^^^^^^^^^^^^^^^
  File "/opt/airflow/dags/dag_generate_table_info.py", line 42, in generate_table_info
    two_weeks_ago = current_date - timedelta(weeks=3)
                    ^^^^^^^^^^^^
NameError: name 'current_date' is not defined
[2025-03-01T02:07:15.731+0000] {local_task_job_runner.py:266} INFO - Task exited with return code 1
[2025-03-01T02:07:15.740+0000] {local_task_job_runner.py:245} INFO - ::endgroup::
[2025-03-01T02:09:48.662+0000] {local_task_job_runner.py:123} INFO - ::group::Pre task execution logs
[2025-03-01T02:09:48.679+0000] {taskinstance.py:2614} INFO - Dependencies all met for dep_context=non-requeueable deps ti=<TaskInstance: dag_postgres_1.insert_orders scheduled__2025-03-01T01:50:00+00:00 [queued]>
[2025-03-01T02:09:48.687+0000] {taskinstance.py:2614} INFO - Dependencies all met for dep_context=requeueable deps ti=<TaskInstance: dag_postgres_1.insert_orders scheduled__2025-03-01T01:50:00+00:00 [queued]>
[2025-03-01T02:09:48.688+0000] {taskinstance.py:2867} INFO - Starting attempt 1 of 2
[2025-03-01T02:09:48.704+0000] {taskinstance.py:2890} INFO - Executing <Task(PythonOperator): insert_orders> on 2025-03-01 01:50:00+00:00
[2025-03-01T02:09:48.714+0000] {logging_mixin.py:190} WARNING - /home/***/.local/lib/python3.12/site-packages/***/task/task_runner/standard_task_runner.py:70 DeprecationWarning: This process (pid=58637) is multi-threaded, use of fork() may lead to deadlocks in the child.
[2025-03-01T02:09:48.714+0000] {standard_task_runner.py:104} INFO - Running: ['***', 'tasks', 'run', 'dag_postgres_1', 'insert_orders', 'scheduled__2025-03-01T01:50:00+00:00', '--job-id', '89', '--raw', '--subdir', 'DAGS_FOLDER/dag_generate_table_info.py', '--cfg-path', '/tmp/tmpcubcxmkf']
[2025-03-01T02:09:48.716+0000] {standard_task_runner.py:72} INFO - Started process 58660 to run task
[2025-03-01T02:09:48.716+0000] {standard_task_runner.py:105} INFO - Job 89: Subtask insert_orders
[2025-03-01T02:09:48.766+0000] {task_command.py:467} INFO - Running <TaskInstance: dag_postgres_1.insert_orders scheduled__2025-03-01T01:50:00+00:00 [running]> on host e6b43e607126
[2025-03-01T02:09:48.861+0000] {taskinstance.py:3134} INFO - Exporting env vars: AIRFLOW_CTX_DAG_EMAIL='kucikm23@gmail.com' AIRFLOW_CTX_DAG_OWNER='***' AIRFLOW_CTX_DAG_ID='dag_postgres_1' AIRFLOW_CTX_TASK_ID='insert_orders' AIRFLOW_CTX_EXECUTION_DATE='2025-03-01T01:50:00+00:00' AIRFLOW_CTX_TRY_NUMBER='1' AIRFLOW_CTX_DAG_RUN_ID='scheduled__2025-03-01T01:50:00+00:00'
[2025-03-01T02:09:48.863+0000] {logging_mixin.py:190} INFO - Task instance is in running state
[2025-03-01T02:09:48.864+0000] {logging_mixin.py:190} INFO -  Previous state of the Task instance: queued
[2025-03-01T02:09:48.865+0000] {logging_mixin.py:190} INFO - Current task name:insert_orders state:running start_date:2025-03-01 02:09:48.680369+00:00
[2025-03-01T02:09:48.865+0000] {logging_mixin.py:190} INFO - Dag name:dag_postgres_1 and current dag run status:running
[2025-03-01T02:09:48.866+0000] {taskinstance.py:732} INFO - ::endgroup::
[2025-03-01T02:09:48.876+0000] {taskinstance.py:3313} ERROR - Task failed with exception
Traceback (most recent call last):
  File "/home/airflow/.local/lib/python3.12/site-packages/airflow/models/taskinstance.py", line 768, in _execute_task
    result = _execute_callable(context=context, **execute_callable_kwargs)
             ^^^^^^^^^^^^^^^^^^^^^^^^^^^^^^^^^^^^^^^^^^^^^^^^^^^^^^^^^^^^^
  File "/home/airflow/.local/lib/python3.12/site-packages/airflow/models/taskinstance.py", line 734, in _execute_callable
    return ExecutionCallableRunner(
           ^^^^^^^^^^^^^^^^^^^^^^^^
  File "/home/airflow/.local/lib/python3.12/site-packages/airflow/utils/operator_helpers.py", line 252, in run
    return self.func(*args, **kwargs)
           ^^^^^^^^^^^^^^^^^^^^^^^^^^
  File "/home/airflow/.local/lib/python3.12/site-packages/airflow/models/baseoperator.py", line 424, in wrapper
    return func(self, *args, **kwargs)
           ^^^^^^^^^^^^^^^^^^^^^^^^^^^
  File "/home/airflow/.local/lib/python3.12/site-packages/airflow/operators/python.py", line 238, in execute
    return_value = self.execute_callable()
                   ^^^^^^^^^^^^^^^^^^^^^^^
  File "/home/airflow/.local/lib/python3.12/site-packages/airflow/operators/python.py", line 256, in execute_callable
    return runner.run(*self.op_args, **self.op_kwargs)
           ^^^^^^^^^^^^^^^^^^^^^^^^^^^^^^^^^^^^^^^^^^^
  File "/home/airflow/.local/lib/python3.12/site-packages/airflow/utils/operator_helpers.py", line 252, in run
    return self.func(*args, **kwargs)
           ^^^^^^^^^^^^^^^^^^^^^^^^^^
  File "/opt/airflow/dags/dag_generate_table_info.py", line 47, in generate_table_info
    currency = random.choice(currencies)
               ^^^^^^^^^^^^^^^^^^^^^^^^^
  File "/usr/local/lib/python3.12/random.py", line 346, in choice
    if not len(seq):
           ^^^^^^^^
TypeError: object of type 'NoneType' has no len()
[2025-03-01T02:09:48.892+0000] {logging_mixin.py:190} INFO - Task instance in failure state
[2025-03-01T02:09:48.893+0000] {logging_mixin.py:190} INFO - Task start:2025-03-01 02:09:48.680369+00:00 end:2025-03-01 02:09:48.891646+00:00 duration:0.211277
[2025-03-01T02:09:48.893+0000] {logging_mixin.py:190} INFO - Task:<Task(PythonOperator): insert_orders> dag:<DAG: dag_postgres_1> dagrun:<DagRun dag_postgres_1 @ 2025-03-01 01:50:00+00:00: scheduled__2025-03-01T01:50:00+00:00, state:running, queued_at: 2025-03-01 02:09:47.342430+00:00. externally triggered: False>
[2025-03-01T02:09:48.894+0000] {logging_mixin.py:190} INFO - Failure caused by object of type 'NoneType' has no len()
[2025-03-01T02:09:48.894+0000] {taskinstance.py:1226} INFO - Marking task as UP_FOR_RETRY. dag_id=dag_postgres_1, task_id=insert_orders, run_id=scheduled__2025-03-01T01:50:00+00:00, execution_date=20250301T015000, start_date=20250301T020948, end_date=20250301T020948
[2025-03-01T02:09:48.933+0000] {taskinstance.py:341} INFO - ::group::Post task execution logs
[2025-03-01T02:09:48.933+0000] {standard_task_runner.py:124} ERROR - Failed to execute job 89 for task insert_orders (object of type 'NoneType' has no len(); 58660)
Traceback (most recent call last):
  File "/home/airflow/.local/lib/python3.12/site-packages/airflow/task/task_runner/standard_task_runner.py", line 117, in _start_by_fork
    ret = args.func(args, dag=self.dag)
          ^^^^^^^^^^^^^^^^^^^^^^^^^^^^^
  File "/home/airflow/.local/lib/python3.12/site-packages/airflow/cli/cli_config.py", line 49, in command
    return func(*args, **kwargs)
           ^^^^^^^^^^^^^^^^^^^^^
  File "/home/airflow/.local/lib/python3.12/site-packages/airflow/utils/cli.py", line 116, in wrapper
    return f(*args, **kwargs)
           ^^^^^^^^^^^^^^^^^^
  File "/home/airflow/.local/lib/python3.12/site-packages/airflow/cli/commands/task_command.py", line 483, in task_run
    task_return_code = _run_task_by_selected_method(args, _dag, ti)
                       ^^^^^^^^^^^^^^^^^^^^^^^^^^^^^^^^^^^^^^^^^^^^
  File "/home/airflow/.local/lib/python3.12/site-packages/airflow/cli/commands/task_command.py", line 256, in _run_task_by_selected_method
    return _run_raw_task(args, ti)
           ^^^^^^^^^^^^^^^^^^^^^^^
  File "/home/airflow/.local/lib/python3.12/site-packages/airflow/cli/commands/task_command.py", line 341, in _run_raw_task
    return ti._run_raw_task(
           ^^^^^^^^^^^^^^^^^
  File "/home/airflow/.local/lib/python3.12/site-packages/airflow/utils/session.py", line 97, in wrapper
    return func(*args, session=session, **kwargs)
           ^^^^^^^^^^^^^^^^^^^^^^^^^^^^^^^^^^^^^^
  File "/home/airflow/.local/lib/python3.12/site-packages/airflow/models/taskinstance.py", line 3006, in _run_raw_task
    return _run_raw_task(
           ^^^^^^^^^^^^^^
  File "/home/airflow/.local/lib/python3.12/site-packages/airflow/models/taskinstance.py", line 274, in _run_raw_task
    TaskInstance._execute_task_with_callbacks(
  File "/home/airflow/.local/lib/python3.12/site-packages/airflow/models/taskinstance.py", line 3161, in _execute_task_with_callbacks
    result = self._execute_task(context, task_orig)
             ^^^^^^^^^^^^^^^^^^^^^^^^^^^^^^^^^^^^^^
  File "/home/airflow/.local/lib/python3.12/site-packages/airflow/models/taskinstance.py", line 3185, in _execute_task
    return _execute_task(self, context, task_orig)
           ^^^^^^^^^^^^^^^^^^^^^^^^^^^^^^^^^^^^^^^
  File "/home/airflow/.local/lib/python3.12/site-packages/airflow/models/taskinstance.py", line 768, in _execute_task
    result = _execute_callable(context=context, **execute_callable_kwargs)
             ^^^^^^^^^^^^^^^^^^^^^^^^^^^^^^^^^^^^^^^^^^^^^^^^^^^^^^^^^^^^^
  File "/home/airflow/.local/lib/python3.12/site-packages/airflow/models/taskinstance.py", line 734, in _execute_callable
    return ExecutionCallableRunner(
           ^^^^^^^^^^^^^^^^^^^^^^^^
  File "/home/airflow/.local/lib/python3.12/site-packages/airflow/utils/operator_helpers.py", line 252, in run
    return self.func(*args, **kwargs)
           ^^^^^^^^^^^^^^^^^^^^^^^^^^
  File "/home/airflow/.local/lib/python3.12/site-packages/airflow/models/baseoperator.py", line 424, in wrapper
    return func(self, *args, **kwargs)
           ^^^^^^^^^^^^^^^^^^^^^^^^^^^
  File "/home/airflow/.local/lib/python3.12/site-packages/airflow/operators/python.py", line 238, in execute
    return_value = self.execute_callable()
                   ^^^^^^^^^^^^^^^^^^^^^^^
  File "/home/airflow/.local/lib/python3.12/site-packages/airflow/operators/python.py", line 256, in execute_callable
    return runner.run(*self.op_args, **self.op_kwargs)
           ^^^^^^^^^^^^^^^^^^^^^^^^^^^^^^^^^^^^^^^^^^^
  File "/home/airflow/.local/lib/python3.12/site-packages/airflow/utils/operator_helpers.py", line 252, in run
    return self.func(*args, **kwargs)
           ^^^^^^^^^^^^^^^^^^^^^^^^^^
  File "/opt/airflow/dags/dag_generate_table_info.py", line 47, in generate_table_info
    currency = random.choice(currencies)
               ^^^^^^^^^^^^^^^^^^^^^^^^^
  File "/usr/local/lib/python3.12/random.py", line 346, in choice
    if not len(seq):
           ^^^^^^^^
TypeError: object of type 'NoneType' has no len()
[2025-03-01T02:09:48.970+0000] {local_task_job_runner.py:266} INFO - Task exited with return code 1
[2025-03-01T02:09:48.979+0000] {local_task_job_runner.py:245} INFO - ::endgroup::
[2025-03-01T02:11:59.484+0000] {local_task_job_runner.py:123} INFO - ::group::Pre task execution logs
[2025-03-01T02:11:59.500+0000] {taskinstance.py:2614} INFO - Dependencies all met for dep_context=non-requeueable deps ti=<TaskInstance: dag_postgres_1.insert_orders scheduled__2025-03-01T01:50:00+00:00 [queued]>
[2025-03-01T02:11:59.509+0000] {taskinstance.py:2614} INFO - Dependencies all met for dep_context=requeueable deps ti=<TaskInstance: dag_postgres_1.insert_orders scheduled__2025-03-01T01:50:00+00:00 [queued]>
[2025-03-01T02:11:59.510+0000] {taskinstance.py:2867} INFO - Starting attempt 1 of 2
[2025-03-01T02:11:59.522+0000] {taskinstance.py:2890} INFO - Executing <Task(PythonOperator): insert_orders> on 2025-03-01 01:50:00+00:00
[2025-03-01T02:11:59.532+0000] {logging_mixin.py:190} WARNING - /home/***/.local/lib/python3.12/site-packages/***/task/task_runner/standard_task_runner.py:70 DeprecationWarning: This process (pid=59936) is multi-threaded, use of fork() may lead to deadlocks in the child.
[2025-03-01T02:11:59.532+0000] {standard_task_runner.py:104} INFO - Running: ['***', 'tasks', 'run', 'dag_postgres_1', 'insert_orders', 'scheduled__2025-03-01T01:50:00+00:00', '--job-id', '100', '--raw', '--subdir', 'DAGS_FOLDER/dag_generate_table_info.py', '--cfg-path', '/tmp/tmpfg2ejl7z']
[2025-03-01T02:11:59.533+0000] {standard_task_runner.py:72} INFO - Started process 59937 to run task
[2025-03-01T02:11:59.533+0000] {standard_task_runner.py:105} INFO - Job 100: Subtask insert_orders
[2025-03-01T02:11:59.570+0000] {task_command.py:467} INFO - Running <TaskInstance: dag_postgres_1.insert_orders scheduled__2025-03-01T01:50:00+00:00 [running]> on host e6b43e607126
[2025-03-01T02:11:59.638+0000] {taskinstance.py:3134} INFO - Exporting env vars: AIRFLOW_CTX_DAG_EMAIL='kucikm23@gmail.com' AIRFLOW_CTX_DAG_OWNER='***' AIRFLOW_CTX_DAG_ID='dag_postgres_1' AIRFLOW_CTX_TASK_ID='insert_orders' AIRFLOW_CTX_EXECUTION_DATE='2025-03-01T01:50:00+00:00' AIRFLOW_CTX_TRY_NUMBER='1' AIRFLOW_CTX_DAG_RUN_ID='scheduled__2025-03-01T01:50:00+00:00'
[2025-03-01T02:11:59.639+0000] {logging_mixin.py:190} INFO - Task instance is in running state
[2025-03-01T02:11:59.640+0000] {logging_mixin.py:190} INFO -  Previous state of the Task instance: queued
[2025-03-01T02:11:59.640+0000] {logging_mixin.py:190} INFO - Current task name:insert_orders state:running start_date:2025-03-01 02:11:59.501579+00:00
[2025-03-01T02:11:59.640+0000] {logging_mixin.py:190} INFO - Dag name:dag_postgres_1 and current dag run status:running
[2025-03-01T02:11:59.641+0000] {taskinstance.py:732} INFO - ::endgroup::
[2025-03-01T02:11:59.681+0000] {logging_mixin.py:190} INFO - order_id          1
customer_email    1
order_date        1
amount            1
currency          1
dtype: int64
[2025-03-01T02:11:59.689+0000] {base.py:84} INFO - Retrieving connection 'postgres_conn'
[2025-03-01T02:11:59.722+0000] {python.py:240} INFO - Done. Returned value was: None
[2025-03-01T02:11:59.731+0000] {taskinstance.py:341} INFO - ::group::Post task execution logs
[2025-03-01T02:11:59.732+0000] {taskinstance.py:353} INFO - Marking task as SUCCESS. dag_id=dag_postgres_1, task_id=insert_orders, run_id=scheduled__2025-03-01T01:50:00+00:00, execution_date=20250301T015000, start_date=20250301T021159, end_date=20250301T021159
[2025-03-01T02:11:59.755+0000] {logging_mixin.py:190} INFO - Task instance in success state
[2025-03-01T02:11:59.755+0000] {logging_mixin.py:190} INFO -  Previous state of the Task instance: running
[2025-03-01T02:11:59.756+0000] {logging_mixin.py:190} INFO - Dag name:dag_postgres_1 queued_at:2025-03-01 02:11:52.484916+00:00
[2025-03-01T02:11:59.756+0000] {logging_mixin.py:190} INFO - Task hostname:e6b43e607126 operator:PythonOperator
[2025-03-01T02:11:59.787+0000] {local_task_job_runner.py:266} INFO - Task exited with return code 0
[2025-03-01T02:11:59.801+0000] {taskinstance.py:3901} INFO - 0 downstream tasks scheduled from follow-on schedule check
[2025-03-01T02:11:59.806+0000] {local_task_job_runner.py:245} INFO - ::endgroup::
