[2025-03-01T00:30:23.487+0000] {local_task_job_runner.py:123} INFO - ::group::Pre task execution logs
[2025-03-01T00:30:23.503+0000] {taskinstance.py:2614} INFO - Dependencies all met for dep_context=non-requeueable deps ti=<TaskInstance: dag_create_orders_table.create_table_orders manual__2025-03-01T00:30:21.664119+00:00 [queued]>
[2025-03-01T00:30:23.510+0000] {taskinstance.py:2614} INFO - Dependencies all met for dep_context=requeueable deps ti=<TaskInstance: dag_create_orders_table.create_table_orders manual__2025-03-01T00:30:21.664119+00:00 [queued]>
[2025-03-01T00:30:23.511+0000] {taskinstance.py:2867} INFO - Starting attempt 1 of 2
[2025-03-01T00:30:23.528+0000] {taskinstance.py:2890} INFO - Executing <Task(PostgresOperator): create_table_orders> on 2025-03-01 00:30:21.664119+00:00
[2025-03-01T00:30:23.540+0000] {standard_task_runner.py:104} INFO - Running: ['***', 'tasks', 'run', 'dag_create_orders_table', 'create_table_orders', 'manual__2025-03-01T00:30:21.664119+00:00', '--job-id', '13', '--raw', '--subdir', 'DAGS_FOLDER/dag_generate_table_info.py', '--cfg-path', '/tmp/tmps70hzge_']
[2025-03-01T00:30:23.543+0000] {standard_task_runner.py:105} INFO - Job 13: Subtask create_table_orders
[2025-03-01T00:30:23.545+0000] {logging_mixin.py:190} WARNING - /home/***/.local/lib/python3.12/site-packages/***/task/task_runner/standard_task_runner.py:70 DeprecationWarning: This process (pid=1078) is multi-threaded, use of fork() may lead to deadlocks in the child.
[2025-03-01T00:30:23.546+0000] {standard_task_runner.py:72} INFO - Started process 1079 to run task
[2025-03-01T00:30:23.604+0000] {task_command.py:467} INFO - Running <TaskInstance: dag_create_orders_table.create_table_orders manual__2025-03-01T00:30:21.664119+00:00 [running]> on host e6b43e607126
[2025-03-01T00:30:23.683+0000] {taskinstance.py:3134} INFO - Exporting env vars: AIRFLOW_CTX_DAG_EMAIL='kucikm23@gmail.com' AIRFLOW_CTX_DAG_OWNER='***' AIRFLOW_CTX_DAG_ID='dag_create_orders_table' AIRFLOW_CTX_TASK_ID='create_table_orders' AIRFLOW_CTX_EXECUTION_DATE='2025-03-01T00:30:21.664119+00:00' AIRFLOW_CTX_TRY_NUMBER='1' AIRFLOW_CTX_DAG_RUN_ID='manual__2025-03-01T00:30:21.664119+00:00'
[2025-03-01T00:30:23.685+0000] {logging_mixin.py:190} INFO - Task instance is in running state
[2025-03-01T00:30:23.685+0000] {logging_mixin.py:190} INFO -  Previous state of the Task instance: queued
[2025-03-01T00:30:23.685+0000] {logging_mixin.py:190} INFO - Current task name:create_table_orders state:running start_date:2025-03-01 00:30:23.503627+00:00
[2025-03-01T00:30:23.686+0000] {logging_mixin.py:190} INFO - Dag name:dag_create_orders_table and current dag run status:running
[2025-03-01T00:30:23.686+0000] {taskinstance.py:732} INFO - ::endgroup::
[2025-03-01T00:30:23.686+0000] {sql.py:295} INFO - Executing: CREATE TABLE IF NOT EXISTS orders (
            order_id UUID PRIMARY KEY DEFAULT gen_random_uuid(),
            customer_email VARCHAR(255) NOT NULL,
            order_date TIMESTAMP NOT NULL DEFAULT NOW(),
            amount NUMERIC(10,2) NOT NULL,
            currency VARCHAR(10) NOT NULL
        );
[2025-03-01T00:30:23.701+0000] {taskinstance.py:3313} ERROR - Task failed with exception
Traceback (most recent call last):
  File "/home/airflow/.local/lib/python3.12/site-packages/airflow/models/taskinstance.py", line 768, in _execute_task
    result = _execute_callable(context=context, **execute_callable_kwargs)
             ^^^^^^^^^^^^^^^^^^^^^^^^^^^^^^^^^^^^^^^^^^^^^^^^^^^^^^^^^^^^^
  File "/home/airflow/.local/lib/python3.12/site-packages/airflow/models/taskinstance.py", line 734, in _execute_callable
    return ExecutionCallableRunner(
           ^^^^^^^^^^^^^^^^^^^^^^^^
  File "/home/airflow/.local/lib/python3.12/site-packages/airflow/utils/operator_helpers.py", line 252, in run
    return self.func(*args, **kwargs)
           ^^^^^^^^^^^^^^^^^^^^^^^^^^
  File "/home/airflow/.local/lib/python3.12/site-packages/airflow/models/baseoperator.py", line 424, in wrapper
    return func(self, *args, **kwargs)
           ^^^^^^^^^^^^^^^^^^^^^^^^^^^
  File "/home/airflow/.local/lib/python3.12/site-packages/airflow/providers/common/sql/operators/sql.py", line 296, in execute
    hook = self.get_db_hook()
           ^^^^^^^^^^^^^^^^^^
  File "/home/airflow/.local/lib/python3.12/site-packages/airflow/providers/common/sql/operators/sql.py", line 195, in get_db_hook
    return self._hook
           ^^^^^^^^^^
  File "/usr/local/lib/python3.12/functools.py", line 998, in __get__
    val = self.func(instance)
          ^^^^^^^^^^^^^^^^^^^
  File "/home/airflow/.local/lib/python3.12/site-packages/airflow/providers/common/sql/operators/sql.py", line 171, in _hook
    hook = self.get_hook(conn_id=conn_id, hook_params=self.hook_params)
           ^^^^^^^^^^^^^^^^^^^^^^^^^^^^^^^^^^^^^^^^^^^^^^^^^^^^^^^^^^^^
  File "/home/airflow/.local/lib/python3.12/site-packages/airflow/providers/common/sql/operators/sql.py", line 163, in get_hook
    connection = BaseHook.get_connection(conn_id)
                 ^^^^^^^^^^^^^^^^^^^^^^^^^^^^^^^^
  File "/home/airflow/.local/lib/python3.12/site-packages/airflow/hooks/base.py", line 83, in get_connection
    conn = Connection.get_connection_from_secrets(conn_id)
           ^^^^^^^^^^^^^^^^^^^^^^^^^^^^^^^^^^^^^^^^^^^^^^^
  File "/home/airflow/.local/lib/python3.12/site-packages/airflow/models/connection.py", line 537, in get_connection_from_secrets
    raise AirflowNotFoundException(f"The conn_id `{conn_id}` isn't defined")
airflow.exceptions.AirflowNotFoundException: The conn_id `postgres_conn` isn't defined
[2025-03-01T00:30:23.707+0000] {logging_mixin.py:190} INFO - Task instance in failure state
[2025-03-01T00:30:23.708+0000] {logging_mixin.py:190} INFO - Task start:2025-03-01 00:30:23.503627+00:00 end:2025-03-01 00:30:23.707497+00:00 duration:0.20387
[2025-03-01T00:30:23.708+0000] {logging_mixin.py:190} INFO - Task:<Task(PostgresOperator): create_table_orders> dag:<DAG: dag_create_orders_table> dagrun:<DagRun dag_create_orders_table @ 2025-03-01 00:30:21.664119+00:00: manual__2025-03-01T00:30:21.664119+00:00, state:running, queued_at: 2025-03-01 00:30:21.687222+00:00. externally triggered: True>
[2025-03-01T00:30:23.709+0000] {logging_mixin.py:190} INFO - Failure caused by The conn_id `postgres_conn` isn't defined
[2025-03-01T00:30:23.709+0000] {taskinstance.py:1226} INFO - Marking task as UP_FOR_RETRY. dag_id=dag_create_orders_table, task_id=create_table_orders, run_id=manual__2025-03-01T00:30:21.664119+00:00, execution_date=20250301T003021, start_date=20250301T003023, end_date=20250301T003023
[2025-03-01T00:30:23.744+0000] {taskinstance.py:341} INFO - ::group::Post task execution logs
[2025-03-01T00:30:23.744+0000] {standard_task_runner.py:124} ERROR - Failed to execute job 13 for task create_table_orders (The conn_id `postgres_conn` isn't defined; 1079)
Traceback (most recent call last):
  File "/home/airflow/.local/lib/python3.12/site-packages/airflow/task/task_runner/standard_task_runner.py", line 117, in _start_by_fork
    ret = args.func(args, dag=self.dag)
          ^^^^^^^^^^^^^^^^^^^^^^^^^^^^^
  File "/home/airflow/.local/lib/python3.12/site-packages/airflow/cli/cli_config.py", line 49, in command
    return func(*args, **kwargs)
           ^^^^^^^^^^^^^^^^^^^^^
  File "/home/airflow/.local/lib/python3.12/site-packages/airflow/utils/cli.py", line 116, in wrapper
    return f(*args, **kwargs)
           ^^^^^^^^^^^^^^^^^^
  File "/home/airflow/.local/lib/python3.12/site-packages/airflow/cli/commands/task_command.py", line 483, in task_run
    task_return_code = _run_task_by_selected_method(args, _dag, ti)
                       ^^^^^^^^^^^^^^^^^^^^^^^^^^^^^^^^^^^^^^^^^^^^
  File "/home/airflow/.local/lib/python3.12/site-packages/airflow/cli/commands/task_command.py", line 256, in _run_task_by_selected_method
    return _run_raw_task(args, ti)
           ^^^^^^^^^^^^^^^^^^^^^^^
  File "/home/airflow/.local/lib/python3.12/site-packages/airflow/cli/commands/task_command.py", line 341, in _run_raw_task
    return ti._run_raw_task(
           ^^^^^^^^^^^^^^^^^
  File "/home/airflow/.local/lib/python3.12/site-packages/airflow/utils/session.py", line 97, in wrapper
    return func(*args, session=session, **kwargs)
           ^^^^^^^^^^^^^^^^^^^^^^^^^^^^^^^^^^^^^^
  File "/home/airflow/.local/lib/python3.12/site-packages/airflow/models/taskinstance.py", line 3006, in _run_raw_task
    return _run_raw_task(
           ^^^^^^^^^^^^^^
  File "/home/airflow/.local/lib/python3.12/site-packages/airflow/models/taskinstance.py", line 274, in _run_raw_task
    TaskInstance._execute_task_with_callbacks(
  File "/home/airflow/.local/lib/python3.12/site-packages/airflow/models/taskinstance.py", line 3161, in _execute_task_with_callbacks
    result = self._execute_task(context, task_orig)
             ^^^^^^^^^^^^^^^^^^^^^^^^^^^^^^^^^^^^^^
  File "/home/airflow/.local/lib/python3.12/site-packages/airflow/models/taskinstance.py", line 3185, in _execute_task
    return _execute_task(self, context, task_orig)
           ^^^^^^^^^^^^^^^^^^^^^^^^^^^^^^^^^^^^^^^
  File "/home/airflow/.local/lib/python3.12/site-packages/airflow/models/taskinstance.py", line 768, in _execute_task
    result = _execute_callable(context=context, **execute_callable_kwargs)
             ^^^^^^^^^^^^^^^^^^^^^^^^^^^^^^^^^^^^^^^^^^^^^^^^^^^^^^^^^^^^^
  File "/home/airflow/.local/lib/python3.12/site-packages/airflow/models/taskinstance.py", line 734, in _execute_callable
    return ExecutionCallableRunner(
           ^^^^^^^^^^^^^^^^^^^^^^^^
  File "/home/airflow/.local/lib/python3.12/site-packages/airflow/utils/operator_helpers.py", line 252, in run
    return self.func(*args, **kwargs)
           ^^^^^^^^^^^^^^^^^^^^^^^^^^
  File "/home/airflow/.local/lib/python3.12/site-packages/airflow/models/baseoperator.py", line 424, in wrapper
    return func(self, *args, **kwargs)
           ^^^^^^^^^^^^^^^^^^^^^^^^^^^
  File "/home/airflow/.local/lib/python3.12/site-packages/airflow/providers/common/sql/operators/sql.py", line 296, in execute
    hook = self.get_db_hook()
           ^^^^^^^^^^^^^^^^^^
  File "/home/airflow/.local/lib/python3.12/site-packages/airflow/providers/common/sql/operators/sql.py", line 195, in get_db_hook
    return self._hook
           ^^^^^^^^^^
  File "/usr/local/lib/python3.12/functools.py", line 998, in __get__
    val = self.func(instance)
          ^^^^^^^^^^^^^^^^^^^
  File "/home/airflow/.local/lib/python3.12/site-packages/airflow/providers/common/sql/operators/sql.py", line 171, in _hook
    hook = self.get_hook(conn_id=conn_id, hook_params=self.hook_params)
           ^^^^^^^^^^^^^^^^^^^^^^^^^^^^^^^^^^^^^^^^^^^^^^^^^^^^^^^^^^^^
  File "/home/airflow/.local/lib/python3.12/site-packages/airflow/providers/common/sql/operators/sql.py", line 163, in get_hook
    connection = BaseHook.get_connection(conn_id)
                 ^^^^^^^^^^^^^^^^^^^^^^^^^^^^^^^^
  File "/home/airflow/.local/lib/python3.12/site-packages/airflow/hooks/base.py", line 83, in get_connection
    conn = Connection.get_connection_from_secrets(conn_id)
           ^^^^^^^^^^^^^^^^^^^^^^^^^^^^^^^^^^^^^^^^^^^^^^^
  File "/home/airflow/.local/lib/python3.12/site-packages/airflow/models/connection.py", line 537, in get_connection_from_secrets
    raise AirflowNotFoundException(f"The conn_id `{conn_id}` isn't defined")
airflow.exceptions.AirflowNotFoundException: The conn_id `postgres_conn` isn't defined
[2025-03-01T00:30:23.761+0000] {local_task_job_runner.py:266} INFO - Task exited with return code 1
[2025-03-01T00:30:23.780+0000] {taskinstance.py:3901} INFO - 0 downstream tasks scheduled from follow-on schedule check
[2025-03-01T00:30:23.787+0000] {local_task_job_runner.py:245} INFO - ::endgroup::
