[2025-03-01T01:58:34.785+0000] {local_task_job_runner.py:123} INFO - ::group::Pre task execution logs
[2025-03-01T01:58:34.805+0000] {taskinstance.py:2614} INFO - Dependencies all met for dep_context=non-requeueable deps ti=<TaskInstance: dag_postgres_1.generate_orders_data scheduled__2025-03-01T01:40:00+00:00 [queued]>
[2025-03-01T01:58:34.815+0000] {taskinstance.py:2614} INFO - Dependencies all met for dep_context=requeueable deps ti=<TaskInstance: dag_postgres_1.generate_orders_data scheduled__2025-03-01T01:40:00+00:00 [queued]>
[2025-03-01T01:58:34.815+0000] {taskinstance.py:2867} INFO - Starting attempt 1 of 2
[2025-03-01T01:58:34.829+0000] {taskinstance.py:2890} INFO - Executing <Task(PythonOperator): generate_orders_data> on 2025-03-01 01:40:00+00:00
[2025-03-01T01:58:34.839+0000] {logging_mixin.py:190} WARNING - /home/***/.local/lib/python3.12/site-packages/***/task/task_runner/standard_task_runner.py:70 DeprecationWarning: This process (pid=52018) is multi-threaded, use of fork() may lead to deadlocks in the child.
[2025-03-01T01:58:34.839+0000] {standard_task_runner.py:104} INFO - Running: ['***', 'tasks', 'run', 'dag_postgres_1', 'generate_orders_data', 'scheduled__2025-03-01T01:40:00+00:00', '--job-id', '59', '--raw', '--subdir', 'DAGS_FOLDER/dag_generate_table_info.py', '--cfg-path', '/tmp/tmp6zfngqxl']
[2025-03-01T01:58:34.840+0000] {standard_task_runner.py:72} INFO - Started process 52024 to run task
[2025-03-01T01:58:34.840+0000] {standard_task_runner.py:105} INFO - Job 59: Subtask generate_orders_data
[2025-03-01T01:58:34.881+0000] {task_command.py:467} INFO - Running <TaskInstance: dag_postgres_1.generate_orders_data scheduled__2025-03-01T01:40:00+00:00 [running]> on host e6b43e607126
[2025-03-01T01:58:34.955+0000] {taskinstance.py:3134} INFO - Exporting env vars: AIRFLOW_CTX_DAG_EMAIL='kucikm23@gmail.com' AIRFLOW_CTX_DAG_OWNER='***' AIRFLOW_CTX_DAG_ID='dag_postgres_1' AIRFLOW_CTX_TASK_ID='generate_orders_data' AIRFLOW_CTX_EXECUTION_DATE='2025-03-01T01:40:00+00:00' AIRFLOW_CTX_TRY_NUMBER='1' AIRFLOW_CTX_DAG_RUN_ID='scheduled__2025-03-01T01:40:00+00:00'
[2025-03-01T01:58:34.956+0000] {logging_mixin.py:190} INFO - Task instance is in running state
[2025-03-01T01:58:34.956+0000] {logging_mixin.py:190} INFO -  Previous state of the Task instance: queued
[2025-03-01T01:58:34.957+0000] {logging_mixin.py:190} INFO - Current task name:generate_orders_data state:running start_date:2025-03-01 01:58:34.806243+00:00
[2025-03-01T01:58:34.957+0000] {logging_mixin.py:190} INFO - Dag name:dag_postgres_1 and current dag run status:running
[2025-03-01T01:58:34.957+0000] {taskinstance.py:732} INFO - ::endgroup::
[2025-03-01T01:58:34.965+0000] {taskinstance.py:3313} ERROR - Task failed with exception
Traceback (most recent call last):
  File "/home/airflow/.local/lib/python3.12/site-packages/airflow/models/taskinstance.py", line 768, in _execute_task
    result = _execute_callable(context=context, **execute_callable_kwargs)
             ^^^^^^^^^^^^^^^^^^^^^^^^^^^^^^^^^^^^^^^^^^^^^^^^^^^^^^^^^^^^^
  File "/home/airflow/.local/lib/python3.12/site-packages/airflow/models/taskinstance.py", line 734, in _execute_callable
    return ExecutionCallableRunner(
           ^^^^^^^^^^^^^^^^^^^^^^^^
  File "/home/airflow/.local/lib/python3.12/site-packages/airflow/utils/operator_helpers.py", line 252, in run
    return self.func(*args, **kwargs)
           ^^^^^^^^^^^^^^^^^^^^^^^^^^
  File "/home/airflow/.local/lib/python3.12/site-packages/airflow/models/baseoperator.py", line 424, in wrapper
    return func(self, *args, **kwargs)
           ^^^^^^^^^^^^^^^^^^^^^^^^^^^
  File "/home/airflow/.local/lib/python3.12/site-packages/airflow/operators/python.py", line 238, in execute
    return_value = self.execute_callable()
                   ^^^^^^^^^^^^^^^^^^^^^^^
  File "/home/airflow/.local/lib/python3.12/site-packages/airflow/operators/python.py", line 256, in execute_callable
    return runner.run(*self.op_args, **self.op_kwargs)
           ^^^^^^^^^^^^^^^^^^^^^^^^^^^^^^^^^^^^^^^^^^^
  File "/home/airflow/.local/lib/python3.12/site-packages/airflow/utils/operator_helpers.py", line 252, in run
    return self.func(*args, **kwargs)
           ^^^^^^^^^^^^^^^^^^^^^^^^^^
  File "/opt/airflow/dags/dag_generate_table_info.py", line 41, in generate_table_info
    two_weeks_ago = current_date - timedelta(weeks=3)
                    ^^^^^^^^^^^^
NameError: name 'current_date' is not defined
[2025-03-01T01:58:34.981+0000] {logging_mixin.py:190} INFO - Task instance in failure state
[2025-03-01T01:58:34.982+0000] {logging_mixin.py:190} INFO - Task start:2025-03-01 01:58:34.806243+00:00 end:2025-03-01 01:58:34.981238+00:00 duration:0.174995
[2025-03-01T01:58:34.982+0000] {logging_mixin.py:190} INFO - Task:<Task(PythonOperator): generate_orders_data> dag:<DAG: dag_postgres_1> dagrun:<DagRun dag_postgres_1 @ 2025-03-01 01:40:00+00:00: scheduled__2025-03-01T01:40:00+00:00, state:running, queued_at: 2025-03-01 01:58:29.688825+00:00. externally triggered: False>
[2025-03-01T01:58:34.982+0000] {logging_mixin.py:190} INFO - Failure caused by name 'current_date' is not defined
[2025-03-01T01:58:34.983+0000] {taskinstance.py:1226} INFO - Marking task as UP_FOR_RETRY. dag_id=dag_postgres_1, task_id=generate_orders_data, run_id=scheduled__2025-03-01T01:40:00+00:00, execution_date=20250301T014000, start_date=20250301T015834, end_date=20250301T015834
[2025-03-01T01:58:35.011+0000] {taskinstance.py:341} INFO - ::group::Post task execution logs
[2025-03-01T01:58:35.012+0000] {standard_task_runner.py:124} ERROR - Failed to execute job 59 for task generate_orders_data (name 'current_date' is not defined; 52024)
Traceback (most recent call last):
  File "/home/airflow/.local/lib/python3.12/site-packages/airflow/task/task_runner/standard_task_runner.py", line 117, in _start_by_fork
    ret = args.func(args, dag=self.dag)
          ^^^^^^^^^^^^^^^^^^^^^^^^^^^^^
  File "/home/airflow/.local/lib/python3.12/site-packages/airflow/cli/cli_config.py", line 49, in command
    return func(*args, **kwargs)
           ^^^^^^^^^^^^^^^^^^^^^
  File "/home/airflow/.local/lib/python3.12/site-packages/airflow/utils/cli.py", line 116, in wrapper
    return f(*args, **kwargs)
           ^^^^^^^^^^^^^^^^^^
  File "/home/airflow/.local/lib/python3.12/site-packages/airflow/cli/commands/task_command.py", line 483, in task_run
    task_return_code = _run_task_by_selected_method(args, _dag, ti)
                       ^^^^^^^^^^^^^^^^^^^^^^^^^^^^^^^^^^^^^^^^^^^^
  File "/home/airflow/.local/lib/python3.12/site-packages/airflow/cli/commands/task_command.py", line 256, in _run_task_by_selected_method
    return _run_raw_task(args, ti)
           ^^^^^^^^^^^^^^^^^^^^^^^
  File "/home/airflow/.local/lib/python3.12/site-packages/airflow/cli/commands/task_command.py", line 341, in _run_raw_task
    return ti._run_raw_task(
           ^^^^^^^^^^^^^^^^^
  File "/home/airflow/.local/lib/python3.12/site-packages/airflow/utils/session.py", line 97, in wrapper
    return func(*args, session=session, **kwargs)
           ^^^^^^^^^^^^^^^^^^^^^^^^^^^^^^^^^^^^^^
  File "/home/airflow/.local/lib/python3.12/site-packages/airflow/models/taskinstance.py", line 3006, in _run_raw_task
    return _run_raw_task(
           ^^^^^^^^^^^^^^
  File "/home/airflow/.local/lib/python3.12/site-packages/airflow/models/taskinstance.py", line 274, in _run_raw_task
    TaskInstance._execute_task_with_callbacks(
  File "/home/airflow/.local/lib/python3.12/site-packages/airflow/models/taskinstance.py", line 3161, in _execute_task_with_callbacks
    result = self._execute_task(context, task_orig)
             ^^^^^^^^^^^^^^^^^^^^^^^^^^^^^^^^^^^^^^
  File "/home/airflow/.local/lib/python3.12/site-packages/airflow/models/taskinstance.py", line 3185, in _execute_task
    return _execute_task(self, context, task_orig)
           ^^^^^^^^^^^^^^^^^^^^^^^^^^^^^^^^^^^^^^^
  File "/home/airflow/.local/lib/python3.12/site-packages/airflow/models/taskinstance.py", line 768, in _execute_task
    result = _execute_callable(context=context, **execute_callable_kwargs)
             ^^^^^^^^^^^^^^^^^^^^^^^^^^^^^^^^^^^^^^^^^^^^^^^^^^^^^^^^^^^^^
  File "/home/airflow/.local/lib/python3.12/site-packages/airflow/models/taskinstance.py", line 734, in _execute_callable
    return ExecutionCallableRunner(
           ^^^^^^^^^^^^^^^^^^^^^^^^
  File "/home/airflow/.local/lib/python3.12/site-packages/airflow/utils/operator_helpers.py", line 252, in run
    return self.func(*args, **kwargs)
           ^^^^^^^^^^^^^^^^^^^^^^^^^^
  File "/home/airflow/.local/lib/python3.12/site-packages/airflow/models/baseoperator.py", line 424, in wrapper
    return func(self, *args, **kwargs)
           ^^^^^^^^^^^^^^^^^^^^^^^^^^^
  File "/home/airflow/.local/lib/python3.12/site-packages/airflow/operators/python.py", line 238, in execute
    return_value = self.execute_callable()
                   ^^^^^^^^^^^^^^^^^^^^^^^
  File "/home/airflow/.local/lib/python3.12/site-packages/airflow/operators/python.py", line 256, in execute_callable
    return runner.run(*self.op_args, **self.op_kwargs)
           ^^^^^^^^^^^^^^^^^^^^^^^^^^^^^^^^^^^^^^^^^^^
  File "/home/airflow/.local/lib/python3.12/site-packages/airflow/utils/operator_helpers.py", line 252, in run
    return self.func(*args, **kwargs)
           ^^^^^^^^^^^^^^^^^^^^^^^^^^
  File "/opt/airflow/dags/dag_generate_table_info.py", line 41, in generate_table_info
    two_weeks_ago = current_date - timedelta(weeks=3)
                    ^^^^^^^^^^^^
NameError: name 'current_date' is not defined
[2025-03-01T01:58:35.054+0000] {local_task_job_runner.py:266} INFO - Task exited with return code 1
[2025-03-01T01:58:35.076+0000] {taskinstance.py:3901} INFO - 0 downstream tasks scheduled from follow-on schedule check
[2025-03-01T01:58:35.079+0000] {local_task_job_runner.py:245} INFO - ::endgroup::
[2025-03-01T01:59:16.091+0000] {local_task_job_runner.py:123} INFO - ::group::Pre task execution logs
[2025-03-01T01:59:16.109+0000] {taskinstance.py:2614} INFO - Dependencies all met for dep_context=non-requeueable deps ti=<TaskInstance: dag_postgres_1.generate_orders_data scheduled__2025-03-01T01:40:00+00:00 [queued]>
[2025-03-01T01:59:16.117+0000] {taskinstance.py:2614} INFO - Dependencies all met for dep_context=requeueable deps ti=<TaskInstance: dag_postgres_1.generate_orders_data scheduled__2025-03-01T01:40:00+00:00 [queued]>
[2025-03-01T01:59:16.117+0000] {taskinstance.py:2867} INFO - Starting attempt 1 of 2
[2025-03-01T01:59:16.132+0000] {taskinstance.py:2890} INFO - Executing <Task(PythonOperator): generate_orders_data> on 2025-03-01 01:40:00+00:00
[2025-03-01T01:59:16.142+0000] {logging_mixin.py:190} WARNING - /home/***/.local/lib/python3.12/site-packages/***/task/task_runner/standard_task_runner.py:70 DeprecationWarning: This process (pid=52566) is multi-threaded, use of fork() may lead to deadlocks in the child.
[2025-03-01T01:59:16.142+0000] {standard_task_runner.py:104} INFO - Running: ['***', 'tasks', 'run', 'dag_postgres_1', 'generate_orders_data', 'scheduled__2025-03-01T01:40:00+00:00', '--job-id', '63', '--raw', '--subdir', 'DAGS_FOLDER/dag_generate_table_info.py', '--cfg-path', '/tmp/tmpbf5tjsl6']
[2025-03-01T01:59:16.143+0000] {standard_task_runner.py:72} INFO - Started process 52567 to run task
[2025-03-01T01:59:16.143+0000] {standard_task_runner.py:105} INFO - Job 63: Subtask generate_orders_data
[2025-03-01T01:59:16.186+0000] {task_command.py:467} INFO - Running <TaskInstance: dag_postgres_1.generate_orders_data scheduled__2025-03-01T01:40:00+00:00 [running]> on host e6b43e607126
[2025-03-01T01:59:16.272+0000] {taskinstance.py:3134} INFO - Exporting env vars: AIRFLOW_CTX_DAG_EMAIL='kucikm23@gmail.com' AIRFLOW_CTX_DAG_OWNER='***' AIRFLOW_CTX_DAG_ID='dag_postgres_1' AIRFLOW_CTX_TASK_ID='generate_orders_data' AIRFLOW_CTX_EXECUTION_DATE='2025-03-01T01:40:00+00:00' AIRFLOW_CTX_TRY_NUMBER='1' AIRFLOW_CTX_DAG_RUN_ID='scheduled__2025-03-01T01:40:00+00:00'
[2025-03-01T01:59:16.274+0000] {logging_mixin.py:190} INFO - Task instance is in running state
[2025-03-01T01:59:16.274+0000] {logging_mixin.py:190} INFO -  Previous state of the Task instance: queued
[2025-03-01T01:59:16.274+0000] {logging_mixin.py:190} INFO - Current task name:generate_orders_data state:running start_date:2025-03-01 01:59:16.110141+00:00
[2025-03-01T01:59:16.275+0000] {logging_mixin.py:190} INFO - Dag name:dag_postgres_1 and current dag run status:running
[2025-03-01T01:59:16.275+0000] {taskinstance.py:732} INFO - ::endgroup::
[2025-03-01T01:59:16.284+0000] {taskinstance.py:3313} ERROR - Task failed with exception
Traceback (most recent call last):
  File "/home/airflow/.local/lib/python3.12/site-packages/airflow/models/taskinstance.py", line 768, in _execute_task
    result = _execute_callable(context=context, **execute_callable_kwargs)
             ^^^^^^^^^^^^^^^^^^^^^^^^^^^^^^^^^^^^^^^^^^^^^^^^^^^^^^^^^^^^^
  File "/home/airflow/.local/lib/python3.12/site-packages/airflow/models/taskinstance.py", line 734, in _execute_callable
    return ExecutionCallableRunner(
           ^^^^^^^^^^^^^^^^^^^^^^^^
  File "/home/airflow/.local/lib/python3.12/site-packages/airflow/utils/operator_helpers.py", line 252, in run
    return self.func(*args, **kwargs)
           ^^^^^^^^^^^^^^^^^^^^^^^^^^
  File "/home/airflow/.local/lib/python3.12/site-packages/airflow/models/baseoperator.py", line 424, in wrapper
    return func(self, *args, **kwargs)
           ^^^^^^^^^^^^^^^^^^^^^^^^^^^
  File "/home/airflow/.local/lib/python3.12/site-packages/airflow/operators/python.py", line 238, in execute
    return_value = self.execute_callable()
                   ^^^^^^^^^^^^^^^^^^^^^^^
  File "/home/airflow/.local/lib/python3.12/site-packages/airflow/operators/python.py", line 256, in execute_callable
    return runner.run(*self.op_args, **self.op_kwargs)
           ^^^^^^^^^^^^^^^^^^^^^^^^^^^^^^^^^^^^^^^^^^^
  File "/home/airflow/.local/lib/python3.12/site-packages/airflow/utils/operator_helpers.py", line 252, in run
    return self.func(*args, **kwargs)
           ^^^^^^^^^^^^^^^^^^^^^^^^^^
  File "/opt/airflow/dags/dag_generate_table_info.py", line 42, in generate_table_info
    two_weeks_ago = current_date - timedelta(weeks=3)
                    ^^^^^^^^^^^^
NameError: name 'current_date' is not defined
[2025-03-01T01:59:16.304+0000] {logging_mixin.py:190} INFO - Task instance in failure state
[2025-03-01T01:59:16.304+0000] {logging_mixin.py:190} INFO - Task start:2025-03-01 01:59:16.110141+00:00 end:2025-03-01 01:59:16.303848+00:00 duration:0.193707
[2025-03-01T01:59:16.305+0000] {logging_mixin.py:190} INFO - Task:<Task(PythonOperator): generate_orders_data> dag:<DAG: dag_postgres_1> dagrun:<DagRun dag_postgres_1 @ 2025-03-01 01:40:00+00:00: scheduled__2025-03-01T01:40:00+00:00, state:running, queued_at: 2025-03-01 01:59:11.056301+00:00. externally triggered: False>
[2025-03-01T01:59:16.305+0000] {logging_mixin.py:190} INFO - Failure caused by name 'current_date' is not defined
[2025-03-01T01:59:16.306+0000] {taskinstance.py:1226} INFO - Marking task as UP_FOR_RETRY. dag_id=dag_postgres_1, task_id=generate_orders_data, run_id=scheduled__2025-03-01T01:40:00+00:00, execution_date=20250301T014000, start_date=20250301T015916, end_date=20250301T015916
[2025-03-01T01:59:16.349+0000] {taskinstance.py:341} INFO - ::group::Post task execution logs
[2025-03-01T01:59:16.350+0000] {standard_task_runner.py:124} ERROR - Failed to execute job 63 for task generate_orders_data (name 'current_date' is not defined; 52567)
Traceback (most recent call last):
  File "/home/airflow/.local/lib/python3.12/site-packages/airflow/task/task_runner/standard_task_runner.py", line 117, in _start_by_fork
    ret = args.func(args, dag=self.dag)
          ^^^^^^^^^^^^^^^^^^^^^^^^^^^^^
  File "/home/airflow/.local/lib/python3.12/site-packages/airflow/cli/cli_config.py", line 49, in command
    return func(*args, **kwargs)
           ^^^^^^^^^^^^^^^^^^^^^
  File "/home/airflow/.local/lib/python3.12/site-packages/airflow/utils/cli.py", line 116, in wrapper
    return f(*args, **kwargs)
           ^^^^^^^^^^^^^^^^^^
  File "/home/airflow/.local/lib/python3.12/site-packages/airflow/cli/commands/task_command.py", line 483, in task_run
    task_return_code = _run_task_by_selected_method(args, _dag, ti)
                       ^^^^^^^^^^^^^^^^^^^^^^^^^^^^^^^^^^^^^^^^^^^^
  File "/home/airflow/.local/lib/python3.12/site-packages/airflow/cli/commands/task_command.py", line 256, in _run_task_by_selected_method
    return _run_raw_task(args, ti)
           ^^^^^^^^^^^^^^^^^^^^^^^
  File "/home/airflow/.local/lib/python3.12/site-packages/airflow/cli/commands/task_command.py", line 341, in _run_raw_task
    return ti._run_raw_task(
           ^^^^^^^^^^^^^^^^^
  File "/home/airflow/.local/lib/python3.12/site-packages/airflow/utils/session.py", line 97, in wrapper
    return func(*args, session=session, **kwargs)
           ^^^^^^^^^^^^^^^^^^^^^^^^^^^^^^^^^^^^^^
  File "/home/airflow/.local/lib/python3.12/site-packages/airflow/models/taskinstance.py", line 3006, in _run_raw_task
    return _run_raw_task(
           ^^^^^^^^^^^^^^
  File "/home/airflow/.local/lib/python3.12/site-packages/airflow/models/taskinstance.py", line 274, in _run_raw_task
    TaskInstance._execute_task_with_callbacks(
  File "/home/airflow/.local/lib/python3.12/site-packages/airflow/models/taskinstance.py", line 3161, in _execute_task_with_callbacks
    result = self._execute_task(context, task_orig)
             ^^^^^^^^^^^^^^^^^^^^^^^^^^^^^^^^^^^^^^
  File "/home/airflow/.local/lib/python3.12/site-packages/airflow/models/taskinstance.py", line 3185, in _execute_task
    return _execute_task(self, context, task_orig)
           ^^^^^^^^^^^^^^^^^^^^^^^^^^^^^^^^^^^^^^^
  File "/home/airflow/.local/lib/python3.12/site-packages/airflow/models/taskinstance.py", line 768, in _execute_task
    result = _execute_callable(context=context, **execute_callable_kwargs)
             ^^^^^^^^^^^^^^^^^^^^^^^^^^^^^^^^^^^^^^^^^^^^^^^^^^^^^^^^^^^^^
  File "/home/airflow/.local/lib/python3.12/site-packages/airflow/models/taskinstance.py", line 734, in _execute_callable
    return ExecutionCallableRunner(
           ^^^^^^^^^^^^^^^^^^^^^^^^
  File "/home/airflow/.local/lib/python3.12/site-packages/airflow/utils/operator_helpers.py", line 252, in run
    return self.func(*args, **kwargs)
           ^^^^^^^^^^^^^^^^^^^^^^^^^^
  File "/home/airflow/.local/lib/python3.12/site-packages/airflow/models/baseoperator.py", line 424, in wrapper
    return func(self, *args, **kwargs)
           ^^^^^^^^^^^^^^^^^^^^^^^^^^^
  File "/home/airflow/.local/lib/python3.12/site-packages/airflow/operators/python.py", line 238, in execute
    return_value = self.execute_callable()
                   ^^^^^^^^^^^^^^^^^^^^^^^
  File "/home/airflow/.local/lib/python3.12/site-packages/airflow/operators/python.py", line 256, in execute_callable
    return runner.run(*self.op_args, **self.op_kwargs)
           ^^^^^^^^^^^^^^^^^^^^^^^^^^^^^^^^^^^^^^^^^^^
  File "/home/airflow/.local/lib/python3.12/site-packages/airflow/utils/operator_helpers.py", line 252, in run
    return self.func(*args, **kwargs)
           ^^^^^^^^^^^^^^^^^^^^^^^^^^
  File "/opt/airflow/dags/dag_generate_table_info.py", line 42, in generate_table_info
    two_weeks_ago = current_date - timedelta(weeks=3)
                    ^^^^^^^^^^^^
NameError: name 'current_date' is not defined
[2025-03-01T01:59:16.397+0000] {local_task_job_runner.py:266} INFO - Task exited with return code 1
[2025-03-01T01:59:16.425+0000] {taskinstance.py:3901} INFO - 0 downstream tasks scheduled from follow-on schedule check
[2025-03-01T01:59:16.430+0000] {local_task_job_runner.py:245} INFO - ::endgroup::
